{
 "cells": [
  {
   "cell_type": "code",
   "execution_count": 58,
   "id": "b962262a-106e-4f9f-82b8-3161913e658e",
   "metadata": {},
   "outputs": [],
   "source": [
    "fighter_1 = {\n",
    "    'RedOdds': -150,\n",
    "    'BlueOdds': 120,\n",
    "    'RedExpectedValue': 0.6,\n",
    "    'BlueExpectedValue': 0.4,\n",
    "    'Date': '2024-10-26',\n",
    "    'Location': 'Abu Dhabi',\n",
    "    'Country': 'Spain',\n",
    "    'TitleBout': True,\n",
    "    'WeightClass': 'Featherweight',\n",
    "    'Gender': 'MALE',\n",
    "    'NumberOfRounds': 5,\n",
    "    'BlueCurrentLoseStreak': 0,\n",
    "    'BlueCurrentWinStreak': 1,\n",
    "    'BlueDraws': 0,\n",
    "    'BlueAvgSigStrLanded': 7.16,\n",
    "    'BlueAvgSigStrPct': 49.0,\n",
    "    'BlueAvgSubAtt': 0.4,\n",
    "    'BlueAvgTDLanded': 0.5,\n",
    "    'BlueAvgTDPct': 83.0,\n",
    "    'BlueLongestWinStreak': 14,\n",
    "    'BlueLosses': 7,\n",
    "    'BlueTotalRoundsFought': 113,\n",
    "    'BlueTotalTitleBouts': 11,\n",
    "    'BlueWinsByDecisionMajority': 0,\n",
    "    'BlueWinsByDecisionSplit': 0,\n",
    "    'BlueWinsByDecisionUnanimous': 10,\n",
    "    'BlueWinsByKO': 11,\n",
    "    'BlueWinsBySubmission': 2,\n",
    "    'BlueWinsByTKODoctorStoppage': 1,\n",
    "    'BlueWins': 24,\n",
    "    'BlueStance': 'Orthodox',\n",
    "    'BlueHeightCms': 180,\n",
    "    'BlueReachCms': 175,\n",
    "    'BlueWeightLbs': 145,\n",
    "    'RedCurrentLoseStreak': 0,\n",
    "    'RedCurrentWinStreak': 5,\n",
    "    'RedDraws': 0,\n",
    "    'RedAvgSigStrLanded': 4.40,\n",
    "    'RedAvgSigStrPct': 46.0,\n",
    "    'RedAvgSubAtt': 1.28,\n",
    "    'RedAvgTDLanded': 1.92,\n",
    "    'RedAvgTDPct': 56.0,\n",
    "    'RedLongestWinStreak': 5,\n",
    "    'RedLosses': 0,\n",
    "    'RedTotalRoundsFought': 25,\n",
    "    'RedTotalTitleBouts': 1,\n",
    "    'RedWinsByDecisionMajority': 2,\n",
    "    'RedWinsByDecisionSplit': 1,\n",
    "    'RedWinsByDecisionUnanimous': 2,\n",
    "    'RedWinsByKO': 5,\n",
    "    'RedWinsBySubmission': 8,\n",
    "    'RedWinsByTKODoctorStoppage': 0,\n",
    "    'RedWins': 15,\n",
    "    'RedStance': 'Orthodox',\n",
    "    'RedHeightCms': 170,\n",
    "    'RedReachCms': 175,\n",
    "    'RedWeightLbs': 145,\n",
    "    'RedAge': 27,\n",
    "    'BlueAge': 32,\n",
    "    'LoseStreakDif': 0,\n",
    "    'WinStreakDif': 4,\n",
    "    'LongestWinStreakDif': -9,\n",
    "    'WinDif': -9,\n",
    "    'LossDif': 7,\n",
    "    'TotalRoundDif': -88,\n",
    "    'TotalTitleBoutDif': -10,\n",
    "    'KODif': 6,\n",
    "    'SubDif': 6,\n",
    "    'HeightDif': -5,\n",
    "    'ReachDif': 0,\n",
    "    'AgeDif': -5,\n",
    "    'SigStrDif': -2.76,\n",
    "    'AvgSubAttDif': 0.88,\n",
    "    'AvgTDDif': 1.42,\n",
    "    'EmptyArena': False,\n",
    "    'BMatchWCRank': 1,\n",
    "    'RMatchWCRank': 1,\n",
    "    'RWFlyweightRank': 0,\n",
    "    'RWFeatherweightRank': 1,\n",
    "    'RWStrawweightRank': 0,\n",
    "    'RWBantamweightRank': 0,\n",
    "    'RHeavyweightRank': 0,\n",
    "    'RLightHeavyweightRank': 0,\n",
    "    'RMiddleweightRank': 3,\n",
    "    'RWelterweightRank': 0,\n",
    "    'RLightweightRank': 0,\n",
    "    'RFeatherweightRank': 1,\n",
    "    'RBantamweightRank': 0,\n",
    "    'RFlyweightRank': 0,\n",
    "    'RPFPRank': 1,\n",
    "    'BWFlyweightRank': 0,\n",
    "    'BWFeatherweightRank': 0,\n",
    "    'BWStrawweightRank': 0,\n",
    "    'BWBantamweightRank': 0,\n",
    "    'BHeavyweightRank': 0,\n",
    "    'BLightHeavyweightRank': 0,\n",
    "    'BMiddleweightRank': 0,\n",
    "    'BWelterweightRank': 0,\n",
    "    'BLightweightRank': 0,\n",
    "    'BFeatherweightRank': 0,\n",
    "    'BBantamweightRank': 0,\n",
    "    'BFlyweightRank': 0,\n",
    "    'BPFPRank': 2,\n",
    "    'BetterRank': 0,\n",
    "    'Finish': 'KO',\n",
    "    'FinishDetails': 'Punches',\n",
    "    'FinishRound': 2,\n",
    "    'FinishRoundTime': '3:32',\n",
    "    'TotalFightTimeSecs': 600,\n",
    "    'RedDecOdds': 150,\n",
    "    'BlueDecOdds': -150,\n",
    "    'RSubOdds': 300,\n",
    "    'BSubOdds': -100,\n",
    "    'RKOOdds': 120,\n",
    "    'BKOOdds': -150\n",
    "}"
   ]
  },
  {
   "cell_type": "code",
   "execution_count": null,
   "id": "f60a311b-b112-4468-93ac-a1238883e2f8",
   "metadata": {},
   "outputs": [],
   "source": []
  },
  {
   "cell_type": "code",
   "execution_count": 59,
   "id": "5e443f3c-064c-405c-a46f-dd1321f7e485",
   "metadata": {
    "scrolled": true
   },
   "outputs": [
    {
     "name": "stdout",
     "output_type": "stream",
     "text": [
      "Fitting 3 folds for each of 18 candidates, totalling 54 fits\n",
      "Fitting 3 folds for each of 36 candidates, totalling 108 fits\n"
     ]
    },
    {
     "name": "stderr",
     "output_type": "stream",
     "text": [
      "E:\\anaconda3\\envs\\segmentation\\lib\\site-packages\\sklearn\\feature_selection\\_univariate_selection.py:112: UserWarning: Features [78 91] are constant.\n",
      "  warnings.warn(\"Features %s are constant.\" % constant_features_idx, UserWarning)\n",
      "E:\\anaconda3\\envs\\segmentation\\lib\\site-packages\\sklearn\\feature_selection\\_univariate_selection.py:113: RuntimeWarning: invalid value encountered in divide\n",
      "  f = msb / msw\n"
     ]
    },
    {
     "name": "stdout",
     "output_type": "stream",
     "text": [
      "Fitting 3 folds for each of 54 candidates, totalling 162 fits\n"
     ]
    },
    {
     "name": "stderr",
     "output_type": "stream",
     "text": [
      "E:\\anaconda3\\envs\\segmentation\\lib\\site-packages\\sklearn\\feature_selection\\_univariate_selection.py:112: UserWarning: Features [78 91] are constant.\n",
      "  warnings.warn(\"Features %s are constant.\" % constant_features_idx, UserWarning)\n",
      "E:\\anaconda3\\envs\\segmentation\\lib\\site-packages\\sklearn\\feature_selection\\_univariate_selection.py:113: RuntimeWarning: invalid value encountered in divide\n",
      "  f = msb / msw\n"
     ]
    },
    {
     "name": "stdout",
     "output_type": "stream",
     "text": [
      "Fitting 3 folds for each of 12 candidates, totalling 36 fits\n"
     ]
    },
    {
     "name": "stderr",
     "output_type": "stream",
     "text": [
      "E:\\anaconda3\\envs\\segmentation\\lib\\site-packages\\sklearn\\model_selection\\_validation.py:425: FitFailedWarning: \n",
      "24 fits failed out of a total of 36.\n",
      "The score on these train-test partitions for these parameters will be set to nan.\n",
      "If these failures are not expected, you can try to debug them by setting error_score='raise'.\n",
      "\n",
      "Below are more details about the failures:\n",
      "--------------------------------------------------------------------------------\n",
      "1 fits failed with the following error:\n",
      "Traceback (most recent call last):\n",
      "  File \"E:\\anaconda3\\envs\\segmentation\\lib\\site-packages\\sklearn\\model_selection\\_validation.py\", line 729, in _fit_and_score\n",
      "    estimator.fit(X_train, y_train, **fit_params)\n",
      "  File \"E:\\anaconda3\\envs\\segmentation\\lib\\site-packages\\sklearn\\base.py\", line 1152, in wrapper\n",
      "    return fit_method(estimator, *args, **kwargs)\n",
      "  File \"E:\\anaconda3\\envs\\segmentation\\lib\\site-packages\\sklearn\\pipeline.py\", line 427, in fit\n",
      "    self._final_estimator.fit(Xt, y, **fit_params_last_step)\n",
      "  File \"C:\\Users\\marcb\\AppData\\Local\\Temp\\ipykernel_24688\\2277059315.py\", line 30, in fit\n",
      "  File \"E:\\anaconda3\\envs\\segmentation\\lib\\site-packages\\keras\\src\\utils\\traceback_utils.py\", line 70, in error_handler\n",
      "    raise e.with_traceback(filtered_tb) from None\n",
      "  File \"C:\\Users\\marcb\\AppData\\Local\\Temp\\__autograph_generated_fileq_dwuwll.py\", line 15, in tf__train_function\n",
      "    retval_ = ag__.converted_call(ag__.ld(step_function), (ag__.ld(self), ag__.ld(iterator)), None, fscope)\n",
      "ValueError: in user code:\n",
      "\n",
      "    File \"E:\\anaconda3\\envs\\segmentation\\lib\\site-packages\\keras\\src\\engine\\training.py\", line 1338, in train_function  *\n",
      "        return step_function(self, iterator)\n",
      "    File \"E:\\anaconda3\\envs\\segmentation\\lib\\site-packages\\keras\\src\\engine\\training.py\", line 1322, in step_function  **\n",
      "        outputs = model.distribute_strategy.run(run_step, args=(data,))\n",
      "    File \"E:\\anaconda3\\envs\\segmentation\\lib\\site-packages\\keras\\src\\engine\\training.py\", line 1303, in run_step  **\n",
      "        outputs = model.train_step(data)\n",
      "    File \"E:\\anaconda3\\envs\\segmentation\\lib\\site-packages\\keras\\src\\engine\\training.py\", line 1080, in train_step\n",
      "        y_pred = self(x, training=True)\n",
      "    File \"E:\\anaconda3\\envs\\segmentation\\lib\\site-packages\\keras\\src\\utils\\traceback_utils.py\", line 70, in error_handler\n",
      "        raise e.with_traceback(filtered_tb) from None\n",
      "    File \"E:\\anaconda3\\envs\\segmentation\\lib\\site-packages\\keras\\src\\engine\\input_spec.py\", line 298, in assert_input_compatibility\n",
      "        raise ValueError(\n",
      "\n",
      "    ValueError: Input 0 of layer \"sequential_2\" is incompatible with the layer: expected shape=(None, 10), found shape=(None, 5)\n",
      "\n",
      "\n",
      "--------------------------------------------------------------------------------\n",
      "1 fits failed with the following error:\n",
      "Traceback (most recent call last):\n",
      "  File \"E:\\anaconda3\\envs\\segmentation\\lib\\site-packages\\sklearn\\model_selection\\_validation.py\", line 729, in _fit_and_score\n",
      "    estimator.fit(X_train, y_train, **fit_params)\n",
      "  File \"E:\\anaconda3\\envs\\segmentation\\lib\\site-packages\\sklearn\\base.py\", line 1152, in wrapper\n",
      "    return fit_method(estimator, *args, **kwargs)\n",
      "  File \"E:\\anaconda3\\envs\\segmentation\\lib\\site-packages\\sklearn\\pipeline.py\", line 427, in fit\n",
      "    self._final_estimator.fit(Xt, y, **fit_params_last_step)\n",
      "  File \"C:\\Users\\marcb\\AppData\\Local\\Temp\\ipykernel_24688\\2277059315.py\", line 30, in fit\n",
      "  File \"E:\\anaconda3\\envs\\segmentation\\lib\\site-packages\\keras\\src\\utils\\traceback_utils.py\", line 70, in error_handler\n",
      "    raise e.with_traceback(filtered_tb) from None\n",
      "  File \"C:\\Users\\marcb\\AppData\\Local\\Temp\\__autograph_generated_file25f38dna.py\", line 15, in tf__train_function\n",
      "    retval_ = ag__.converted_call(ag__.ld(step_function), (ag__.ld(self), ag__.ld(iterator)), None, fscope)\n",
      "ValueError: in user code:\n",
      "\n",
      "    File \"E:\\anaconda3\\envs\\segmentation\\lib\\site-packages\\keras\\src\\engine\\training.py\", line 1338, in train_function  *\n",
      "        return step_function(self, iterator)\n",
      "    File \"E:\\anaconda3\\envs\\segmentation\\lib\\site-packages\\keras\\src\\engine\\training.py\", line 1322, in step_function  **\n",
      "        outputs = model.distribute_strategy.run(run_step, args=(data,))\n",
      "    File \"E:\\anaconda3\\envs\\segmentation\\lib\\site-packages\\keras\\src\\engine\\training.py\", line 1303, in run_step  **\n",
      "        outputs = model.train_step(data)\n",
      "    File \"E:\\anaconda3\\envs\\segmentation\\lib\\site-packages\\keras\\src\\engine\\training.py\", line 1080, in train_step\n",
      "        y_pred = self(x, training=True)\n",
      "    File \"E:\\anaconda3\\envs\\segmentation\\lib\\site-packages\\keras\\src\\utils\\traceback_utils.py\", line 70, in error_handler\n",
      "        raise e.with_traceback(filtered_tb) from None\n",
      "    File \"E:\\anaconda3\\envs\\segmentation\\lib\\site-packages\\keras\\src\\engine\\input_spec.py\", line 298, in assert_input_compatibility\n",
      "        raise ValueError(\n",
      "\n",
      "    ValueError: Input 0 of layer \"sequential_3\" is incompatible with the layer: expected shape=(None, 10), found shape=(None, 5)\n",
      "\n",
      "\n",
      "--------------------------------------------------------------------------------\n",
      "1 fits failed with the following error:\n",
      "Traceback (most recent call last):\n",
      "  File \"E:\\anaconda3\\envs\\segmentation\\lib\\site-packages\\sklearn\\model_selection\\_validation.py\", line 729, in _fit_and_score\n",
      "    estimator.fit(X_train, y_train, **fit_params)\n",
      "  File \"E:\\anaconda3\\envs\\segmentation\\lib\\site-packages\\sklearn\\base.py\", line 1152, in wrapper\n",
      "    return fit_method(estimator, *args, **kwargs)\n",
      "  File \"E:\\anaconda3\\envs\\segmentation\\lib\\site-packages\\sklearn\\pipeline.py\", line 427, in fit\n",
      "    self._final_estimator.fit(Xt, y, **fit_params_last_step)\n",
      "  File \"C:\\Users\\marcb\\AppData\\Local\\Temp\\ipykernel_24688\\2277059315.py\", line 30, in fit\n",
      "  File \"E:\\anaconda3\\envs\\segmentation\\lib\\site-packages\\keras\\src\\utils\\traceback_utils.py\", line 70, in error_handler\n",
      "    raise e.with_traceback(filtered_tb) from None\n",
      "  File \"C:\\Users\\marcb\\AppData\\Local\\Temp\\__autograph_generated_fileq5no0svl.py\", line 15, in tf__train_function\n",
      "    retval_ = ag__.converted_call(ag__.ld(step_function), (ag__.ld(self), ag__.ld(iterator)), None, fscope)\n",
      "ValueError: in user code:\n",
      "\n",
      "    File \"E:\\anaconda3\\envs\\segmentation\\lib\\site-packages\\keras\\src\\engine\\training.py\", line 1338, in train_function  *\n",
      "        return step_function(self, iterator)\n",
      "    File \"E:\\anaconda3\\envs\\segmentation\\lib\\site-packages\\keras\\src\\engine\\training.py\", line 1322, in step_function  **\n",
      "        outputs = model.distribute_strategy.run(run_step, args=(data,))\n",
      "    File \"E:\\anaconda3\\envs\\segmentation\\lib\\site-packages\\keras\\src\\engine\\training.py\", line 1303, in run_step  **\n",
      "        outputs = model.train_step(data)\n",
      "    File \"E:\\anaconda3\\envs\\segmentation\\lib\\site-packages\\keras\\src\\engine\\training.py\", line 1080, in train_step\n",
      "        y_pred = self(x, training=True)\n",
      "    File \"E:\\anaconda3\\envs\\segmentation\\lib\\site-packages\\keras\\src\\utils\\traceback_utils.py\", line 70, in error_handler\n",
      "        raise e.with_traceback(filtered_tb) from None\n",
      "    File \"E:\\anaconda3\\envs\\segmentation\\lib\\site-packages\\keras\\src\\engine\\input_spec.py\", line 298, in assert_input_compatibility\n",
      "        raise ValueError(\n",
      "\n",
      "    ValueError: Input 0 of layer \"sequential_4\" is incompatible with the layer: expected shape=(None, 10), found shape=(16, 5)\n",
      "\n",
      "\n",
      "--------------------------------------------------------------------------------\n",
      "1 fits failed with the following error:\n",
      "Traceback (most recent call last):\n",
      "  File \"E:\\anaconda3\\envs\\segmentation\\lib\\site-packages\\sklearn\\model_selection\\_validation.py\", line 729, in _fit_and_score\n",
      "    estimator.fit(X_train, y_train, **fit_params)\n",
      "  File \"E:\\anaconda3\\envs\\segmentation\\lib\\site-packages\\sklearn\\base.py\", line 1152, in wrapper\n",
      "    return fit_method(estimator, *args, **kwargs)\n",
      "  File \"E:\\anaconda3\\envs\\segmentation\\lib\\site-packages\\sklearn\\pipeline.py\", line 427, in fit\n",
      "    self._final_estimator.fit(Xt, y, **fit_params_last_step)\n",
      "  File \"C:\\Users\\marcb\\AppData\\Local\\Temp\\ipykernel_24688\\2277059315.py\", line 30, in fit\n",
      "  File \"E:\\anaconda3\\envs\\segmentation\\lib\\site-packages\\keras\\src\\utils\\traceback_utils.py\", line 70, in error_handler\n",
      "    raise e.with_traceback(filtered_tb) from None\n",
      "  File \"C:\\Users\\marcb\\AppData\\Local\\Temp\\__autograph_generated_filendcf10be.py\", line 15, in tf__train_function\n",
      "    retval_ = ag__.converted_call(ag__.ld(step_function), (ag__.ld(self), ag__.ld(iterator)), None, fscope)\n",
      "ValueError: in user code:\n",
      "\n",
      "    File \"E:\\anaconda3\\envs\\segmentation\\lib\\site-packages\\keras\\src\\engine\\training.py\", line 1338, in train_function  *\n",
      "        return step_function(self, iterator)\n",
      "    File \"E:\\anaconda3\\envs\\segmentation\\lib\\site-packages\\keras\\src\\engine\\training.py\", line 1322, in step_function  **\n",
      "        outputs = model.distribute_strategy.run(run_step, args=(data,))\n",
      "    File \"E:\\anaconda3\\envs\\segmentation\\lib\\site-packages\\keras\\src\\engine\\training.py\", line 1303, in run_step  **\n",
      "        outputs = model.train_step(data)\n",
      "    File \"E:\\anaconda3\\envs\\segmentation\\lib\\site-packages\\keras\\src\\engine\\training.py\", line 1080, in train_step\n",
      "        y_pred = self(x, training=True)\n",
      "    File \"E:\\anaconda3\\envs\\segmentation\\lib\\site-packages\\keras\\src\\utils\\traceback_utils.py\", line 70, in error_handler\n",
      "        raise e.with_traceback(filtered_tb) from None\n",
      "    File \"E:\\anaconda3\\envs\\segmentation\\lib\\site-packages\\keras\\src\\engine\\input_spec.py\", line 298, in assert_input_compatibility\n",
      "        raise ValueError(\n",
      "\n",
      "    ValueError: Input 0 of layer \"sequential\" is incompatible with the layer: expected shape=(None, 10), found shape=(None, 15)\n",
      "\n",
      "\n",
      "--------------------------------------------------------------------------------\n",
      "1 fits failed with the following error:\n",
      "Traceback (most recent call last):\n",
      "  File \"E:\\anaconda3\\envs\\segmentation\\lib\\site-packages\\sklearn\\model_selection\\_validation.py\", line 729, in _fit_and_score\n",
      "    estimator.fit(X_train, y_train, **fit_params)\n",
      "  File \"E:\\anaconda3\\envs\\segmentation\\lib\\site-packages\\sklearn\\base.py\", line 1152, in wrapper\n",
      "    return fit_method(estimator, *args, **kwargs)\n",
      "  File \"E:\\anaconda3\\envs\\segmentation\\lib\\site-packages\\sklearn\\pipeline.py\", line 427, in fit\n",
      "    self._final_estimator.fit(Xt, y, **fit_params_last_step)\n",
      "  File \"C:\\Users\\marcb\\AppData\\Local\\Temp\\ipykernel_24688\\2277059315.py\", line 30, in fit\n",
      "  File \"E:\\anaconda3\\envs\\segmentation\\lib\\site-packages\\keras\\src\\utils\\traceback_utils.py\", line 70, in error_handler\n",
      "    raise e.with_traceback(filtered_tb) from None\n",
      "  File \"C:\\Users\\marcb\\AppData\\Local\\Temp\\__autograph_generated_filekgl0d56o.py\", line 15, in tf__train_function\n",
      "    retval_ = ag__.converted_call(ag__.ld(step_function), (ag__.ld(self), ag__.ld(iterator)), None, fscope)\n",
      "ValueError: in user code:\n",
      "\n",
      "    File \"E:\\anaconda3\\envs\\segmentation\\lib\\site-packages\\keras\\src\\engine\\training.py\", line 1338, in train_function  *\n",
      "        return step_function(self, iterator)\n",
      "    File \"E:\\anaconda3\\envs\\segmentation\\lib\\site-packages\\keras\\src\\engine\\training.py\", line 1322, in step_function  **\n",
      "        outputs = model.distribute_strategy.run(run_step, args=(data,))\n",
      "    File \"E:\\anaconda3\\envs\\segmentation\\lib\\site-packages\\keras\\src\\engine\\training.py\", line 1303, in run_step  **\n",
      "        outputs = model.train_step(data)\n",
      "    File \"E:\\anaconda3\\envs\\segmentation\\lib\\site-packages\\keras\\src\\engine\\training.py\", line 1080, in train_step\n",
      "        y_pred = self(x, training=True)\n",
      "    File \"E:\\anaconda3\\envs\\segmentation\\lib\\site-packages\\keras\\src\\utils\\traceback_utils.py\", line 70, in error_handler\n",
      "        raise e.with_traceback(filtered_tb) from None\n",
      "    File \"E:\\anaconda3\\envs\\segmentation\\lib\\site-packages\\keras\\src\\engine\\input_spec.py\", line 298, in assert_input_compatibility\n",
      "        raise ValueError(\n",
      "\n",
      "    ValueError: Input 0 of layer \"sequential\" is incompatible with the layer: expected shape=(None, 10), found shape=(None, 15)\n",
      "\n",
      "\n",
      "--------------------------------------------------------------------------------\n",
      "1 fits failed with the following error:\n",
      "Traceback (most recent call last):\n",
      "  File \"E:\\anaconda3\\envs\\segmentation\\lib\\site-packages\\sklearn\\model_selection\\_validation.py\", line 729, in _fit_and_score\n",
      "    estimator.fit(X_train, y_train, **fit_params)\n",
      "  File \"E:\\anaconda3\\envs\\segmentation\\lib\\site-packages\\sklearn\\base.py\", line 1152, in wrapper\n",
      "    return fit_method(estimator, *args, **kwargs)\n",
      "  File \"E:\\anaconda3\\envs\\segmentation\\lib\\site-packages\\sklearn\\pipeline.py\", line 427, in fit\n",
      "    self._final_estimator.fit(Xt, y, **fit_params_last_step)\n",
      "  File \"C:\\Users\\marcb\\AppData\\Local\\Temp\\ipykernel_24688\\2277059315.py\", line 30, in fit\n",
      "  File \"E:\\anaconda3\\envs\\segmentation\\lib\\site-packages\\keras\\src\\utils\\traceback_utils.py\", line 70, in error_handler\n",
      "    raise e.with_traceback(filtered_tb) from None\n",
      "  File \"C:\\Users\\marcb\\AppData\\Local\\Temp\\__autograph_generated_fileaylk41jz.py\", line 15, in tf__train_function\n",
      "    retval_ = ag__.converted_call(ag__.ld(step_function), (ag__.ld(self), ag__.ld(iterator)), None, fscope)\n",
      "ValueError: in user code:\n",
      "\n",
      "    File \"E:\\anaconda3\\envs\\segmentation\\lib\\site-packages\\keras\\src\\engine\\training.py\", line 1338, in train_function  *\n",
      "        return step_function(self, iterator)\n",
      "    File \"E:\\anaconda3\\envs\\segmentation\\lib\\site-packages\\keras\\src\\engine\\training.py\", line 1322, in step_function  **\n",
      "        outputs = model.distribute_strategy.run(run_step, args=(data,))\n",
      "    File \"E:\\anaconda3\\envs\\segmentation\\lib\\site-packages\\keras\\src\\engine\\training.py\", line 1303, in run_step  **\n",
      "        outputs = model.train_step(data)\n",
      "    File \"E:\\anaconda3\\envs\\segmentation\\lib\\site-packages\\keras\\src\\engine\\training.py\", line 1080, in train_step\n",
      "        y_pred = self(x, training=True)\n",
      "    File \"E:\\anaconda3\\envs\\segmentation\\lib\\site-packages\\keras\\src\\utils\\traceback_utils.py\", line 70, in error_handler\n",
      "        raise e.with_traceback(filtered_tb) from None\n",
      "    File \"E:\\anaconda3\\envs\\segmentation\\lib\\site-packages\\keras\\src\\engine\\input_spec.py\", line 298, in assert_input_compatibility\n",
      "        raise ValueError(\n",
      "\n",
      "    ValueError: Input 0 of layer \"sequential_3\" is incompatible with the layer: expected shape=(None, 10), found shape=(16, 15)\n",
      "\n",
      "\n",
      "--------------------------------------------------------------------------------\n",
      "1 fits failed with the following error:\n",
      "Traceback (most recent call last):\n",
      "  File \"E:\\anaconda3\\envs\\segmentation\\lib\\site-packages\\sklearn\\model_selection\\_validation.py\", line 729, in _fit_and_score\n",
      "    estimator.fit(X_train, y_train, **fit_params)\n",
      "  File \"E:\\anaconda3\\envs\\segmentation\\lib\\site-packages\\sklearn\\base.py\", line 1152, in wrapper\n",
      "    return fit_method(estimator, *args, **kwargs)\n",
      "  File \"E:\\anaconda3\\envs\\segmentation\\lib\\site-packages\\sklearn\\pipeline.py\", line 427, in fit\n",
      "    self._final_estimator.fit(Xt, y, **fit_params_last_step)\n",
      "  File \"C:\\Users\\marcb\\AppData\\Local\\Temp\\ipykernel_24688\\2277059315.py\", line 30, in fit\n",
      "  File \"E:\\anaconda3\\envs\\segmentation\\lib\\site-packages\\keras\\src\\utils\\traceback_utils.py\", line 70, in error_handler\n",
      "    raise e.with_traceback(filtered_tb) from None\n",
      "  File \"C:\\Users\\marcb\\AppData\\Local\\Temp\\__autograph_generated_file3at0n400.py\", line 15, in tf__train_function\n",
      "    retval_ = ag__.converted_call(ag__.ld(step_function), (ag__.ld(self), ag__.ld(iterator)), None, fscope)\n",
      "ValueError: in user code:\n",
      "\n",
      "    File \"E:\\anaconda3\\envs\\segmentation\\lib\\site-packages\\keras\\src\\engine\\training.py\", line 1338, in train_function  *\n",
      "        return step_function(self, iterator)\n",
      "    File \"E:\\anaconda3\\envs\\segmentation\\lib\\site-packages\\keras\\src\\engine\\training.py\", line 1322, in step_function  **\n",
      "        outputs = model.distribute_strategy.run(run_step, args=(data,))\n",
      "    File \"E:\\anaconda3\\envs\\segmentation\\lib\\site-packages\\keras\\src\\engine\\training.py\", line 1303, in run_step  **\n",
      "        outputs = model.train_step(data)\n",
      "    File \"E:\\anaconda3\\envs\\segmentation\\lib\\site-packages\\keras\\src\\engine\\training.py\", line 1080, in train_step\n",
      "        y_pred = self(x, training=True)\n",
      "    File \"E:\\anaconda3\\envs\\segmentation\\lib\\site-packages\\keras\\src\\utils\\traceback_utils.py\", line 70, in error_handler\n",
      "        raise e.with_traceback(filtered_tb) from None\n",
      "    File \"E:\\anaconda3\\envs\\segmentation\\lib\\site-packages\\keras\\src\\engine\\input_spec.py\", line 298, in assert_input_compatibility\n",
      "        raise ValueError(\n",
      "\n",
      "    ValueError: Input 0 of layer \"sequential_2\" is incompatible with the layer: expected shape=(None, 10), found shape=(None, 5)\n",
      "\n",
      "\n",
      "--------------------------------------------------------------------------------\n",
      "1 fits failed with the following error:\n",
      "Traceback (most recent call last):\n",
      "  File \"E:\\anaconda3\\envs\\segmentation\\lib\\site-packages\\sklearn\\model_selection\\_validation.py\", line 729, in _fit_and_score\n",
      "    estimator.fit(X_train, y_train, **fit_params)\n",
      "  File \"E:\\anaconda3\\envs\\segmentation\\lib\\site-packages\\sklearn\\base.py\", line 1152, in wrapper\n",
      "    return fit_method(estimator, *args, **kwargs)\n",
      "  File \"E:\\anaconda3\\envs\\segmentation\\lib\\site-packages\\sklearn\\pipeline.py\", line 427, in fit\n",
      "    self._final_estimator.fit(Xt, y, **fit_params_last_step)\n",
      "  File \"C:\\Users\\marcb\\AppData\\Local\\Temp\\ipykernel_24688\\2277059315.py\", line 30, in fit\n",
      "  File \"E:\\anaconda3\\envs\\segmentation\\lib\\site-packages\\keras\\src\\utils\\traceback_utils.py\", line 70, in error_handler\n",
      "    raise e.with_traceback(filtered_tb) from None\n",
      "  File \"C:\\Users\\marcb\\AppData\\Local\\Temp\\__autograph_generated_filenqsvt53_.py\", line 15, in tf__train_function\n",
      "    retval_ = ag__.converted_call(ag__.ld(step_function), (ag__.ld(self), ag__.ld(iterator)), None, fscope)\n",
      "ValueError: in user code:\n",
      "\n",
      "    File \"E:\\anaconda3\\envs\\segmentation\\lib\\site-packages\\keras\\src\\engine\\training.py\", line 1338, in train_function  *\n",
      "        return step_function(self, iterator)\n",
      "    File \"E:\\anaconda3\\envs\\segmentation\\lib\\site-packages\\keras\\src\\engine\\training.py\", line 1322, in step_function  **\n",
      "        outputs = model.distribute_strategy.run(run_step, args=(data,))\n",
      "    File \"E:\\anaconda3\\envs\\segmentation\\lib\\site-packages\\keras\\src\\engine\\training.py\", line 1303, in run_step  **\n",
      "        outputs = model.train_step(data)\n",
      "    File \"E:\\anaconda3\\envs\\segmentation\\lib\\site-packages\\keras\\src\\engine\\training.py\", line 1080, in train_step\n",
      "        y_pred = self(x, training=True)\n",
      "    File \"E:\\anaconda3\\envs\\segmentation\\lib\\site-packages\\keras\\src\\utils\\traceback_utils.py\", line 70, in error_handler\n",
      "        raise e.with_traceback(filtered_tb) from None\n",
      "    File \"E:\\anaconda3\\envs\\segmentation\\lib\\site-packages\\keras\\src\\engine\\input_spec.py\", line 298, in assert_input_compatibility\n",
      "        raise ValueError(\n",
      "\n",
      "    ValueError: Input 0 of layer \"sequential_3\" is incompatible with the layer: expected shape=(None, 10), found shape=(None, 5)\n",
      "\n",
      "\n",
      "--------------------------------------------------------------------------------\n",
      "1 fits failed with the following error:\n",
      "Traceback (most recent call last):\n",
      "  File \"E:\\anaconda3\\envs\\segmentation\\lib\\site-packages\\sklearn\\model_selection\\_validation.py\", line 729, in _fit_and_score\n",
      "    estimator.fit(X_train, y_train, **fit_params)\n",
      "  File \"E:\\anaconda3\\envs\\segmentation\\lib\\site-packages\\sklearn\\base.py\", line 1152, in wrapper\n",
      "    return fit_method(estimator, *args, **kwargs)\n",
      "  File \"E:\\anaconda3\\envs\\segmentation\\lib\\site-packages\\sklearn\\pipeline.py\", line 427, in fit\n",
      "    self._final_estimator.fit(Xt, y, **fit_params_last_step)\n",
      "  File \"C:\\Users\\marcb\\AppData\\Local\\Temp\\ipykernel_24688\\2277059315.py\", line 30, in fit\n",
      "  File \"E:\\anaconda3\\envs\\segmentation\\lib\\site-packages\\keras\\src\\utils\\traceback_utils.py\", line 70, in error_handler\n",
      "    raise e.with_traceback(filtered_tb) from None\n",
      "  File \"C:\\Users\\marcb\\AppData\\Local\\Temp\\__autograph_generated_filepjids2ym.py\", line 15, in tf__train_function\n",
      "    retval_ = ag__.converted_call(ag__.ld(step_function), (ag__.ld(self), ag__.ld(iterator)), None, fscope)\n",
      "ValueError: in user code:\n",
      "\n",
      "    File \"E:\\anaconda3\\envs\\segmentation\\lib\\site-packages\\keras\\src\\engine\\training.py\", line 1338, in train_function  *\n",
      "        return step_function(self, iterator)\n",
      "    File \"E:\\anaconda3\\envs\\segmentation\\lib\\site-packages\\keras\\src\\engine\\training.py\", line 1322, in step_function  **\n",
      "        outputs = model.distribute_strategy.run(run_step, args=(data,))\n",
      "    File \"E:\\anaconda3\\envs\\segmentation\\lib\\site-packages\\keras\\src\\engine\\training.py\", line 1303, in run_step  **\n",
      "        outputs = model.train_step(data)\n",
      "    File \"E:\\anaconda3\\envs\\segmentation\\lib\\site-packages\\keras\\src\\engine\\training.py\", line 1080, in train_step\n",
      "        y_pred = self(x, training=True)\n",
      "    File \"E:\\anaconda3\\envs\\segmentation\\lib\\site-packages\\keras\\src\\utils\\traceback_utils.py\", line 70, in error_handler\n",
      "        raise e.with_traceback(filtered_tb) from None\n",
      "    File \"E:\\anaconda3\\envs\\segmentation\\lib\\site-packages\\keras\\src\\engine\\input_spec.py\", line 298, in assert_input_compatibility\n",
      "        raise ValueError(\n",
      "\n",
      "    ValueError: Input 0 of layer \"sequential_3\" is incompatible with the layer: expected shape=(None, 10), found shape=(16, 5)\n",
      "\n",
      "\n",
      "--------------------------------------------------------------------------------\n",
      "1 fits failed with the following error:\n",
      "Traceback (most recent call last):\n",
      "  File \"E:\\anaconda3\\envs\\segmentation\\lib\\site-packages\\sklearn\\model_selection\\_validation.py\", line 729, in _fit_and_score\n",
      "    estimator.fit(X_train, y_train, **fit_params)\n",
      "  File \"E:\\anaconda3\\envs\\segmentation\\lib\\site-packages\\sklearn\\base.py\", line 1152, in wrapper\n",
      "    return fit_method(estimator, *args, **kwargs)\n",
      "  File \"E:\\anaconda3\\envs\\segmentation\\lib\\site-packages\\sklearn\\pipeline.py\", line 427, in fit\n",
      "    self._final_estimator.fit(Xt, y, **fit_params_last_step)\n",
      "  File \"C:\\Users\\marcb\\AppData\\Local\\Temp\\ipykernel_24688\\2277059315.py\", line 30, in fit\n",
      "  File \"E:\\anaconda3\\envs\\segmentation\\lib\\site-packages\\keras\\src\\utils\\traceback_utils.py\", line 70, in error_handler\n",
      "    raise e.with_traceback(filtered_tb) from None\n",
      "  File \"C:\\Users\\marcb\\AppData\\Local\\Temp\\__autograph_generated_filefi70_8nr.py\", line 15, in tf__train_function\n",
      "    retval_ = ag__.converted_call(ag__.ld(step_function), (ag__.ld(self), ag__.ld(iterator)), None, fscope)\n",
      "ValueError: in user code:\n",
      "\n",
      "    File \"E:\\anaconda3\\envs\\segmentation\\lib\\site-packages\\keras\\src\\engine\\training.py\", line 1338, in train_function  *\n",
      "        return step_function(self, iterator)\n",
      "    File \"E:\\anaconda3\\envs\\segmentation\\lib\\site-packages\\keras\\src\\engine\\training.py\", line 1322, in step_function  **\n",
      "        outputs = model.distribute_strategy.run(run_step, args=(data,))\n",
      "    File \"E:\\anaconda3\\envs\\segmentation\\lib\\site-packages\\keras\\src\\engine\\training.py\", line 1303, in run_step  **\n",
      "        outputs = model.train_step(data)\n",
      "    File \"E:\\anaconda3\\envs\\segmentation\\lib\\site-packages\\keras\\src\\engine\\training.py\", line 1080, in train_step\n",
      "        y_pred = self(x, training=True)\n",
      "    File \"E:\\anaconda3\\envs\\segmentation\\lib\\site-packages\\keras\\src\\utils\\traceback_utils.py\", line 70, in error_handler\n",
      "        raise e.with_traceback(filtered_tb) from None\n",
      "    File \"E:\\anaconda3\\envs\\segmentation\\lib\\site-packages\\keras\\src\\engine\\input_spec.py\", line 298, in assert_input_compatibility\n",
      "        raise ValueError(\n",
      "\n",
      "    ValueError: Input 0 of layer \"sequential\" is incompatible with the layer: expected shape=(None, 10), found shape=(None, 15)\n",
      "\n",
      "\n",
      "--------------------------------------------------------------------------------\n",
      "1 fits failed with the following error:\n",
      "Traceback (most recent call last):\n",
      "  File \"E:\\anaconda3\\envs\\segmentation\\lib\\site-packages\\sklearn\\model_selection\\_validation.py\", line 729, in _fit_and_score\n",
      "    estimator.fit(X_train, y_train, **fit_params)\n",
      "  File \"E:\\anaconda3\\envs\\segmentation\\lib\\site-packages\\sklearn\\base.py\", line 1152, in wrapper\n",
      "    return fit_method(estimator, *args, **kwargs)\n",
      "  File \"E:\\anaconda3\\envs\\segmentation\\lib\\site-packages\\sklearn\\pipeline.py\", line 427, in fit\n",
      "    self._final_estimator.fit(Xt, y, **fit_params_last_step)\n",
      "  File \"C:\\Users\\marcb\\AppData\\Local\\Temp\\ipykernel_24688\\2277059315.py\", line 30, in fit\n",
      "  File \"E:\\anaconda3\\envs\\segmentation\\lib\\site-packages\\keras\\src\\utils\\traceback_utils.py\", line 70, in error_handler\n",
      "    raise e.with_traceback(filtered_tb) from None\n",
      "  File \"C:\\Users\\marcb\\AppData\\Local\\Temp\\__autograph_generated_file7txwl163.py\", line 15, in tf__train_function\n",
      "    retval_ = ag__.converted_call(ag__.ld(step_function), (ag__.ld(self), ag__.ld(iterator)), None, fscope)\n",
      "ValueError: in user code:\n",
      "\n",
      "    File \"E:\\anaconda3\\envs\\segmentation\\lib\\site-packages\\keras\\src\\engine\\training.py\", line 1338, in train_function  *\n",
      "        return step_function(self, iterator)\n",
      "    File \"E:\\anaconda3\\envs\\segmentation\\lib\\site-packages\\keras\\src\\engine\\training.py\", line 1322, in step_function  **\n",
      "        outputs = model.distribute_strategy.run(run_step, args=(data,))\n",
      "    File \"E:\\anaconda3\\envs\\segmentation\\lib\\site-packages\\keras\\src\\engine\\training.py\", line 1303, in run_step  **\n",
      "        outputs = model.train_step(data)\n",
      "    File \"E:\\anaconda3\\envs\\segmentation\\lib\\site-packages\\keras\\src\\engine\\training.py\", line 1080, in train_step\n",
      "        y_pred = self(x, training=True)\n",
      "    File \"E:\\anaconda3\\envs\\segmentation\\lib\\site-packages\\keras\\src\\utils\\traceback_utils.py\", line 70, in error_handler\n",
      "        raise e.with_traceback(filtered_tb) from None\n",
      "    File \"E:\\anaconda3\\envs\\segmentation\\lib\\site-packages\\keras\\src\\engine\\input_spec.py\", line 298, in assert_input_compatibility\n",
      "        raise ValueError(\n",
      "\n",
      "    ValueError: Input 0 of layer \"sequential_3\" is incompatible with the layer: expected shape=(None, 10), found shape=(None, 15)\n",
      "\n",
      "\n",
      "--------------------------------------------------------------------------------\n",
      "1 fits failed with the following error:\n",
      "Traceback (most recent call last):\n",
      "  File \"E:\\anaconda3\\envs\\segmentation\\lib\\site-packages\\sklearn\\model_selection\\_validation.py\", line 729, in _fit_and_score\n",
      "    estimator.fit(X_train, y_train, **fit_params)\n",
      "  File \"E:\\anaconda3\\envs\\segmentation\\lib\\site-packages\\sklearn\\base.py\", line 1152, in wrapper\n",
      "    return fit_method(estimator, *args, **kwargs)\n",
      "  File \"E:\\anaconda3\\envs\\segmentation\\lib\\site-packages\\sklearn\\pipeline.py\", line 427, in fit\n",
      "    self._final_estimator.fit(Xt, y, **fit_params_last_step)\n",
      "  File \"C:\\Users\\marcb\\AppData\\Local\\Temp\\ipykernel_24688\\2277059315.py\", line 30, in fit\n",
      "  File \"E:\\anaconda3\\envs\\segmentation\\lib\\site-packages\\keras\\src\\utils\\traceback_utils.py\", line 70, in error_handler\n",
      "    raise e.with_traceback(filtered_tb) from None\n",
      "  File \"C:\\Users\\marcb\\AppData\\Local\\Temp\\__autograph_generated_filezpu79s1e.py\", line 15, in tf__train_function\n",
      "    retval_ = ag__.converted_call(ag__.ld(step_function), (ag__.ld(self), ag__.ld(iterator)), None, fscope)\n",
      "ValueError: in user code:\n",
      "\n",
      "    File \"E:\\anaconda3\\envs\\segmentation\\lib\\site-packages\\keras\\src\\engine\\training.py\", line 1338, in train_function  *\n",
      "        return step_function(self, iterator)\n",
      "    File \"E:\\anaconda3\\envs\\segmentation\\lib\\site-packages\\keras\\src\\engine\\training.py\", line 1322, in step_function  **\n",
      "        outputs = model.distribute_strategy.run(run_step, args=(data,))\n",
      "    File \"E:\\anaconda3\\envs\\segmentation\\lib\\site-packages\\keras\\src\\engine\\training.py\", line 1303, in run_step  **\n",
      "        outputs = model.train_step(data)\n",
      "    File \"E:\\anaconda3\\envs\\segmentation\\lib\\site-packages\\keras\\src\\engine\\training.py\", line 1080, in train_step\n",
      "        y_pred = self(x, training=True)\n",
      "    File \"E:\\anaconda3\\envs\\segmentation\\lib\\site-packages\\keras\\src\\utils\\traceback_utils.py\", line 70, in error_handler\n",
      "        raise e.with_traceback(filtered_tb) from None\n",
      "    File \"E:\\anaconda3\\envs\\segmentation\\lib\\site-packages\\keras\\src\\engine\\input_spec.py\", line 298, in assert_input_compatibility\n",
      "        raise ValueError(\n",
      "\n",
      "    ValueError: Input 0 of layer \"sequential_2\" is incompatible with the layer: expected shape=(None, 10), found shape=(16, 15)\n",
      "\n",
      "\n",
      "--------------------------------------------------------------------------------\n",
      "1 fits failed with the following error:\n",
      "Traceback (most recent call last):\n",
      "  File \"E:\\anaconda3\\envs\\segmentation\\lib\\site-packages\\sklearn\\model_selection\\_validation.py\", line 729, in _fit_and_score\n",
      "    estimator.fit(X_train, y_train, **fit_params)\n",
      "  File \"E:\\anaconda3\\envs\\segmentation\\lib\\site-packages\\sklearn\\base.py\", line 1152, in wrapper\n",
      "    return fit_method(estimator, *args, **kwargs)\n",
      "  File \"E:\\anaconda3\\envs\\segmentation\\lib\\site-packages\\sklearn\\pipeline.py\", line 427, in fit\n",
      "    self._final_estimator.fit(Xt, y, **fit_params_last_step)\n",
      "  File \"C:\\Users\\marcb\\AppData\\Local\\Temp\\ipykernel_24688\\2277059315.py\", line 30, in fit\n",
      "  File \"E:\\anaconda3\\envs\\segmentation\\lib\\site-packages\\keras\\src\\utils\\traceback_utils.py\", line 70, in error_handler\n",
      "    raise e.with_traceback(filtered_tb) from None\n",
      "  File \"C:\\Users\\marcb\\AppData\\Local\\Temp\\__autograph_generated_fileibodyggy.py\", line 15, in tf__train_function\n",
      "    retval_ = ag__.converted_call(ag__.ld(step_function), (ag__.ld(self), ag__.ld(iterator)), None, fscope)\n",
      "ValueError: in user code:\n",
      "\n",
      "    File \"E:\\anaconda3\\envs\\segmentation\\lib\\site-packages\\keras\\src\\engine\\training.py\", line 1338, in train_function  *\n",
      "        return step_function(self, iterator)\n",
      "    File \"E:\\anaconda3\\envs\\segmentation\\lib\\site-packages\\keras\\src\\engine\\training.py\", line 1322, in step_function  **\n",
      "        outputs = model.distribute_strategy.run(run_step, args=(data,))\n",
      "    File \"E:\\anaconda3\\envs\\segmentation\\lib\\site-packages\\keras\\src\\engine\\training.py\", line 1303, in run_step  **\n",
      "        outputs = model.train_step(data)\n",
      "    File \"E:\\anaconda3\\envs\\segmentation\\lib\\site-packages\\keras\\src\\engine\\training.py\", line 1080, in train_step\n",
      "        y_pred = self(x, training=True)\n",
      "    File \"E:\\anaconda3\\envs\\segmentation\\lib\\site-packages\\keras\\src\\utils\\traceback_utils.py\", line 70, in error_handler\n",
      "        raise e.with_traceback(filtered_tb) from None\n",
      "    File \"E:\\anaconda3\\envs\\segmentation\\lib\\site-packages\\keras\\src\\engine\\input_spec.py\", line 298, in assert_input_compatibility\n",
      "        raise ValueError(\n",
      "\n",
      "    ValueError: Input 0 of layer \"sequential_3\" is incompatible with the layer: expected shape=(None, 10), found shape=(None, 5)\n",
      "\n",
      "\n",
      "--------------------------------------------------------------------------------\n",
      "1 fits failed with the following error:\n",
      "Traceback (most recent call last):\n",
      "  File \"E:\\anaconda3\\envs\\segmentation\\lib\\site-packages\\sklearn\\model_selection\\_validation.py\", line 729, in _fit_and_score\n",
      "    estimator.fit(X_train, y_train, **fit_params)\n",
      "  File \"E:\\anaconda3\\envs\\segmentation\\lib\\site-packages\\sklearn\\base.py\", line 1152, in wrapper\n",
      "    return fit_method(estimator, *args, **kwargs)\n",
      "  File \"E:\\anaconda3\\envs\\segmentation\\lib\\site-packages\\sklearn\\pipeline.py\", line 427, in fit\n",
      "    self._final_estimator.fit(Xt, y, **fit_params_last_step)\n",
      "  File \"C:\\Users\\marcb\\AppData\\Local\\Temp\\ipykernel_24688\\2277059315.py\", line 30, in fit\n",
      "  File \"E:\\anaconda3\\envs\\segmentation\\lib\\site-packages\\keras\\src\\utils\\traceback_utils.py\", line 70, in error_handler\n",
      "    raise e.with_traceback(filtered_tb) from None\n",
      "  File \"C:\\Users\\marcb\\AppData\\Local\\Temp\\__autograph_generated_fileavthegh3.py\", line 15, in tf__train_function\n",
      "    retval_ = ag__.converted_call(ag__.ld(step_function), (ag__.ld(self), ag__.ld(iterator)), None, fscope)\n",
      "ValueError: in user code:\n",
      "\n",
      "    File \"E:\\anaconda3\\envs\\segmentation\\lib\\site-packages\\keras\\src\\engine\\training.py\", line 1338, in train_function  *\n",
      "        return step_function(self, iterator)\n",
      "    File \"E:\\anaconda3\\envs\\segmentation\\lib\\site-packages\\keras\\src\\engine\\training.py\", line 1322, in step_function  **\n",
      "        outputs = model.distribute_strategy.run(run_step, args=(data,))\n",
      "    File \"E:\\anaconda3\\envs\\segmentation\\lib\\site-packages\\keras\\src\\engine\\training.py\", line 1303, in run_step  **\n",
      "        outputs = model.train_step(data)\n",
      "    File \"E:\\anaconda3\\envs\\segmentation\\lib\\site-packages\\keras\\src\\engine\\training.py\", line 1080, in train_step\n",
      "        y_pred = self(x, training=True)\n",
      "    File \"E:\\anaconda3\\envs\\segmentation\\lib\\site-packages\\keras\\src\\utils\\traceback_utils.py\", line 70, in error_handler\n",
      "        raise e.with_traceback(filtered_tb) from None\n",
      "    File \"E:\\anaconda3\\envs\\segmentation\\lib\\site-packages\\keras\\src\\engine\\input_spec.py\", line 298, in assert_input_compatibility\n",
      "        raise ValueError(\n",
      "\n",
      "    ValueError: Input 0 of layer \"sequential_4\" is incompatible with the layer: expected shape=(None, 10), found shape=(None, 5)\n",
      "\n",
      "\n",
      "--------------------------------------------------------------------------------\n",
      "1 fits failed with the following error:\n",
      "Traceback (most recent call last):\n",
      "  File \"E:\\anaconda3\\envs\\segmentation\\lib\\site-packages\\sklearn\\model_selection\\_validation.py\", line 729, in _fit_and_score\n",
      "    estimator.fit(X_train, y_train, **fit_params)\n",
      "  File \"E:\\anaconda3\\envs\\segmentation\\lib\\site-packages\\sklearn\\base.py\", line 1152, in wrapper\n",
      "    return fit_method(estimator, *args, **kwargs)\n",
      "  File \"E:\\anaconda3\\envs\\segmentation\\lib\\site-packages\\sklearn\\pipeline.py\", line 427, in fit\n",
      "    self._final_estimator.fit(Xt, y, **fit_params_last_step)\n",
      "  File \"C:\\Users\\marcb\\AppData\\Local\\Temp\\ipykernel_24688\\2277059315.py\", line 30, in fit\n",
      "  File \"E:\\anaconda3\\envs\\segmentation\\lib\\site-packages\\keras\\src\\utils\\traceback_utils.py\", line 70, in error_handler\n",
      "    raise e.with_traceback(filtered_tb) from None\n",
      "  File \"C:\\Users\\marcb\\AppData\\Local\\Temp\\__autograph_generated_fileq_dwuwll.py\", line 15, in tf__train_function\n",
      "    retval_ = ag__.converted_call(ag__.ld(step_function), (ag__.ld(self), ag__.ld(iterator)), None, fscope)\n",
      "ValueError: in user code:\n",
      "\n",
      "    File \"E:\\anaconda3\\envs\\segmentation\\lib\\site-packages\\keras\\src\\engine\\training.py\", line 1338, in train_function  *\n",
      "        return step_function(self, iterator)\n",
      "    File \"E:\\anaconda3\\envs\\segmentation\\lib\\site-packages\\keras\\src\\engine\\training.py\", line 1322, in step_function  **\n",
      "        outputs = model.distribute_strategy.run(run_step, args=(data,))\n",
      "    File \"E:\\anaconda3\\envs\\segmentation\\lib\\site-packages\\keras\\src\\engine\\training.py\", line 1303, in run_step  **\n",
      "        outputs = model.train_step(data)\n",
      "    File \"E:\\anaconda3\\envs\\segmentation\\lib\\site-packages\\keras\\src\\engine\\training.py\", line 1080, in train_step\n",
      "        y_pred = self(x, training=True)\n",
      "    File \"E:\\anaconda3\\envs\\segmentation\\lib\\site-packages\\keras\\src\\utils\\traceback_utils.py\", line 70, in error_handler\n",
      "        raise e.with_traceback(filtered_tb) from None\n",
      "    File \"E:\\anaconda3\\envs\\segmentation\\lib\\site-packages\\keras\\src\\engine\\input_spec.py\", line 298, in assert_input_compatibility\n",
      "        raise ValueError(\n",
      "\n",
      "    ValueError: Input 0 of layer \"sequential_3\" is incompatible with the layer: expected shape=(None, 10), found shape=(None, 5)\n",
      "\n",
      "\n",
      "--------------------------------------------------------------------------------\n",
      "1 fits failed with the following error:\n",
      "Traceback (most recent call last):\n",
      "  File \"E:\\anaconda3\\envs\\segmentation\\lib\\site-packages\\sklearn\\model_selection\\_validation.py\", line 729, in _fit_and_score\n",
      "    estimator.fit(X_train, y_train, **fit_params)\n",
      "  File \"E:\\anaconda3\\envs\\segmentation\\lib\\site-packages\\sklearn\\base.py\", line 1152, in wrapper\n",
      "    return fit_method(estimator, *args, **kwargs)\n",
      "  File \"E:\\anaconda3\\envs\\segmentation\\lib\\site-packages\\sklearn\\pipeline.py\", line 427, in fit\n",
      "    self._final_estimator.fit(Xt, y, **fit_params_last_step)\n",
      "  File \"C:\\Users\\marcb\\AppData\\Local\\Temp\\ipykernel_24688\\2277059315.py\", line 30, in fit\n",
      "  File \"E:\\anaconda3\\envs\\segmentation\\lib\\site-packages\\keras\\src\\utils\\traceback_utils.py\", line 70, in error_handler\n",
      "    raise e.with_traceback(filtered_tb) from None\n",
      "  File \"C:\\Users\\marcb\\AppData\\Local\\Temp\\__autograph_generated_fileq5no0svl.py\", line 15, in tf__train_function\n",
      "    retval_ = ag__.converted_call(ag__.ld(step_function), (ag__.ld(self), ag__.ld(iterator)), None, fscope)\n",
      "ValueError: in user code:\n",
      "\n",
      "    File \"E:\\anaconda3\\envs\\segmentation\\lib\\site-packages\\keras\\src\\engine\\training.py\", line 1338, in train_function  *\n",
      "        return step_function(self, iterator)\n",
      "    File \"E:\\anaconda3\\envs\\segmentation\\lib\\site-packages\\keras\\src\\engine\\training.py\", line 1322, in step_function  **\n",
      "        outputs = model.distribute_strategy.run(run_step, args=(data,))\n",
      "    File \"E:\\anaconda3\\envs\\segmentation\\lib\\site-packages\\keras\\src\\engine\\training.py\", line 1303, in run_step  **\n",
      "        outputs = model.train_step(data)\n",
      "    File \"E:\\anaconda3\\envs\\segmentation\\lib\\site-packages\\keras\\src\\engine\\training.py\", line 1080, in train_step\n",
      "        y_pred = self(x, training=True)\n",
      "    File \"E:\\anaconda3\\envs\\segmentation\\lib\\site-packages\\keras\\src\\utils\\traceback_utils.py\", line 70, in error_handler\n",
      "        raise e.with_traceback(filtered_tb) from None\n",
      "    File \"E:\\anaconda3\\envs\\segmentation\\lib\\site-packages\\keras\\src\\engine\\input_spec.py\", line 298, in assert_input_compatibility\n",
      "        raise ValueError(\n",
      "\n",
      "    ValueError: Input 0 of layer \"sequential_5\" is incompatible with the layer: expected shape=(None, 10), found shape=(None, 15)\n",
      "\n",
      "\n",
      "--------------------------------------------------------------------------------\n",
      "1 fits failed with the following error:\n",
      "Traceback (most recent call last):\n",
      "  File \"E:\\anaconda3\\envs\\segmentation\\lib\\site-packages\\sklearn\\model_selection\\_validation.py\", line 729, in _fit_and_score\n",
      "    estimator.fit(X_train, y_train, **fit_params)\n",
      "  File \"E:\\anaconda3\\envs\\segmentation\\lib\\site-packages\\sklearn\\base.py\", line 1152, in wrapper\n",
      "    return fit_method(estimator, *args, **kwargs)\n",
      "  File \"E:\\anaconda3\\envs\\segmentation\\lib\\site-packages\\sklearn\\pipeline.py\", line 427, in fit\n",
      "    self._final_estimator.fit(Xt, y, **fit_params_last_step)\n",
      "  File \"C:\\Users\\marcb\\AppData\\Local\\Temp\\ipykernel_24688\\2277059315.py\", line 30, in fit\n",
      "  File \"E:\\anaconda3\\envs\\segmentation\\lib\\site-packages\\keras\\src\\utils\\traceback_utils.py\", line 70, in error_handler\n",
      "    raise e.with_traceback(filtered_tb) from None\n",
      "  File \"C:\\Users\\marcb\\AppData\\Local\\Temp\\__autograph_generated_fileaylk41jz.py\", line 15, in tf__train_function\n",
      "    retval_ = ag__.converted_call(ag__.ld(step_function), (ag__.ld(self), ag__.ld(iterator)), None, fscope)\n",
      "ValueError: in user code:\n",
      "\n",
      "    File \"E:\\anaconda3\\envs\\segmentation\\lib\\site-packages\\keras\\src\\engine\\training.py\", line 1338, in train_function  *\n",
      "        return step_function(self, iterator)\n",
      "    File \"E:\\anaconda3\\envs\\segmentation\\lib\\site-packages\\keras\\src\\engine\\training.py\", line 1322, in step_function  **\n",
      "        outputs = model.distribute_strategy.run(run_step, args=(data,))\n",
      "    File \"E:\\anaconda3\\envs\\segmentation\\lib\\site-packages\\keras\\src\\engine\\training.py\", line 1303, in run_step  **\n",
      "        outputs = model.train_step(data)\n",
      "    File \"E:\\anaconda3\\envs\\segmentation\\lib\\site-packages\\keras\\src\\engine\\training.py\", line 1080, in train_step\n",
      "        y_pred = self(x, training=True)\n",
      "    File \"E:\\anaconda3\\envs\\segmentation\\lib\\site-packages\\keras\\src\\utils\\traceback_utils.py\", line 70, in error_handler\n",
      "        raise e.with_traceback(filtered_tb) from None\n",
      "    File \"E:\\anaconda3\\envs\\segmentation\\lib\\site-packages\\keras\\src\\engine\\input_spec.py\", line 298, in assert_input_compatibility\n",
      "        raise ValueError(\n",
      "\n",
      "    ValueError: Input 0 of layer \"sequential_4\" is incompatible with the layer: expected shape=(None, 10), found shape=(None, 15)\n",
      "\n",
      "\n",
      "--------------------------------------------------------------------------------\n",
      "1 fits failed with the following error:\n",
      "Traceback (most recent call last):\n",
      "  File \"E:\\anaconda3\\envs\\segmentation\\lib\\site-packages\\sklearn\\model_selection\\_validation.py\", line 729, in _fit_and_score\n",
      "    estimator.fit(X_train, y_train, **fit_params)\n",
      "  File \"E:\\anaconda3\\envs\\segmentation\\lib\\site-packages\\sklearn\\base.py\", line 1152, in wrapper\n",
      "    return fit_method(estimator, *args, **kwargs)\n",
      "  File \"E:\\anaconda3\\envs\\segmentation\\lib\\site-packages\\sklearn\\pipeline.py\", line 427, in fit\n",
      "    self._final_estimator.fit(Xt, y, **fit_params_last_step)\n",
      "  File \"C:\\Users\\marcb\\AppData\\Local\\Temp\\ipykernel_24688\\2277059315.py\", line 30, in fit\n",
      "  File \"E:\\anaconda3\\envs\\segmentation\\lib\\site-packages\\keras\\src\\utils\\traceback_utils.py\", line 70, in error_handler\n",
      "    raise e.with_traceback(filtered_tb) from None\n",
      "  File \"C:\\Users\\marcb\\AppData\\Local\\Temp\\__autograph_generated_filezpu79s1e.py\", line 15, in tf__train_function\n",
      "    retval_ = ag__.converted_call(ag__.ld(step_function), (ag__.ld(self), ag__.ld(iterator)), None, fscope)\n",
      "ValueError: in user code:\n",
      "\n",
      "    File \"E:\\anaconda3\\envs\\segmentation\\lib\\site-packages\\keras\\src\\engine\\training.py\", line 1338, in train_function  *\n",
      "        return step_function(self, iterator)\n",
      "    File \"E:\\anaconda3\\envs\\segmentation\\lib\\site-packages\\keras\\src\\engine\\training.py\", line 1322, in step_function  **\n",
      "        outputs = model.distribute_strategy.run(run_step, args=(data,))\n",
      "    File \"E:\\anaconda3\\envs\\segmentation\\lib\\site-packages\\keras\\src\\engine\\training.py\", line 1303, in run_step  **\n",
      "        outputs = model.train_step(data)\n",
      "    File \"E:\\anaconda3\\envs\\segmentation\\lib\\site-packages\\keras\\src\\engine\\training.py\", line 1080, in train_step\n",
      "        y_pred = self(x, training=True)\n",
      "    File \"E:\\anaconda3\\envs\\segmentation\\lib\\site-packages\\keras\\src\\utils\\traceback_utils.py\", line 70, in error_handler\n",
      "        raise e.with_traceback(filtered_tb) from None\n",
      "    File \"E:\\anaconda3\\envs\\segmentation\\lib\\site-packages\\keras\\src\\engine\\input_spec.py\", line 298, in assert_input_compatibility\n",
      "        raise ValueError(\n",
      "\n",
      "    ValueError: Input 0 of layer \"sequential_3\" is incompatible with the layer: expected shape=(None, 10), found shape=(None, 15)\n",
      "\n",
      "\n",
      "--------------------------------------------------------------------------------\n",
      "1 fits failed with the following error:\n",
      "Traceback (most recent call last):\n",
      "  File \"E:\\anaconda3\\envs\\segmentation\\lib\\site-packages\\sklearn\\model_selection\\_validation.py\", line 729, in _fit_and_score\n",
      "    estimator.fit(X_train, y_train, **fit_params)\n",
      "  File \"E:\\anaconda3\\envs\\segmentation\\lib\\site-packages\\sklearn\\base.py\", line 1152, in wrapper\n",
      "    return fit_method(estimator, *args, **kwargs)\n",
      "  File \"E:\\anaconda3\\envs\\segmentation\\lib\\site-packages\\sklearn\\pipeline.py\", line 427, in fit\n",
      "    self._final_estimator.fit(Xt, y, **fit_params_last_step)\n",
      "  File \"C:\\Users\\marcb\\AppData\\Local\\Temp\\ipykernel_24688\\2277059315.py\", line 30, in fit\n",
      "  File \"E:\\anaconda3\\envs\\segmentation\\lib\\site-packages\\keras\\src\\utils\\traceback_utils.py\", line 70, in error_handler\n",
      "    raise e.with_traceback(filtered_tb) from None\n",
      "  File \"C:\\Users\\marcb\\AppData\\Local\\Temp\\__autograph_generated_filepjids2ym.py\", line 15, in tf__train_function\n",
      "    retval_ = ag__.converted_call(ag__.ld(step_function), (ag__.ld(self), ag__.ld(iterator)), None, fscope)\n",
      "ValueError: in user code:\n",
      "\n",
      "    File \"E:\\anaconda3\\envs\\segmentation\\lib\\site-packages\\keras\\src\\engine\\training.py\", line 1338, in train_function  *\n",
      "        return step_function(self, iterator)\n",
      "    File \"E:\\anaconda3\\envs\\segmentation\\lib\\site-packages\\keras\\src\\engine\\training.py\", line 1322, in step_function  **\n",
      "        outputs = model.distribute_strategy.run(run_step, args=(data,))\n",
      "    File \"E:\\anaconda3\\envs\\segmentation\\lib\\site-packages\\keras\\src\\engine\\training.py\", line 1303, in run_step  **\n",
      "        outputs = model.train_step(data)\n",
      "    File \"E:\\anaconda3\\envs\\segmentation\\lib\\site-packages\\keras\\src\\engine\\training.py\", line 1080, in train_step\n",
      "        y_pred = self(x, training=True)\n",
      "    File \"E:\\anaconda3\\envs\\segmentation\\lib\\site-packages\\keras\\src\\utils\\traceback_utils.py\", line 70, in error_handler\n",
      "        raise e.with_traceback(filtered_tb) from None\n",
      "    File \"E:\\anaconda3\\envs\\segmentation\\lib\\site-packages\\keras\\src\\engine\\input_spec.py\", line 298, in assert_input_compatibility\n",
      "        raise ValueError(\n",
      "\n",
      "    ValueError: Input 0 of layer \"sequential_4\" is incompatible with the layer: expected shape=(None, 10), found shape=(None, 5)\n",
      "\n",
      "\n",
      "--------------------------------------------------------------------------------\n",
      "1 fits failed with the following error:\n",
      "Traceback (most recent call last):\n",
      "  File \"E:\\anaconda3\\envs\\segmentation\\lib\\site-packages\\sklearn\\model_selection\\_validation.py\", line 729, in _fit_and_score\n",
      "    estimator.fit(X_train, y_train, **fit_params)\n",
      "  File \"E:\\anaconda3\\envs\\segmentation\\lib\\site-packages\\sklearn\\base.py\", line 1152, in wrapper\n",
      "    return fit_method(estimator, *args, **kwargs)\n",
      "  File \"E:\\anaconda3\\envs\\segmentation\\lib\\site-packages\\sklearn\\pipeline.py\", line 427, in fit\n",
      "    self._final_estimator.fit(Xt, y, **fit_params_last_step)\n",
      "  File \"C:\\Users\\marcb\\AppData\\Local\\Temp\\ipykernel_24688\\2277059315.py\", line 30, in fit\n",
      "  File \"E:\\anaconda3\\envs\\segmentation\\lib\\site-packages\\keras\\src\\utils\\traceback_utils.py\", line 70, in error_handler\n",
      "    raise e.with_traceback(filtered_tb) from None\n",
      "  File \"C:\\Users\\marcb\\AppData\\Local\\Temp\\__autograph_generated_file7txwl163.py\", line 15, in tf__train_function\n",
      "    retval_ = ag__.converted_call(ag__.ld(step_function), (ag__.ld(self), ag__.ld(iterator)), None, fscope)\n",
      "ValueError: in user code:\n",
      "\n",
      "    File \"E:\\anaconda3\\envs\\segmentation\\lib\\site-packages\\keras\\src\\engine\\training.py\", line 1338, in train_function  *\n",
      "        return step_function(self, iterator)\n",
      "    File \"E:\\anaconda3\\envs\\segmentation\\lib\\site-packages\\keras\\src\\engine\\training.py\", line 1322, in step_function  **\n",
      "        outputs = model.distribute_strategy.run(run_step, args=(data,))\n",
      "    File \"E:\\anaconda3\\envs\\segmentation\\lib\\site-packages\\keras\\src\\engine\\training.py\", line 1303, in run_step  **\n",
      "        outputs = model.train_step(data)\n",
      "    File \"E:\\anaconda3\\envs\\segmentation\\lib\\site-packages\\keras\\src\\engine\\training.py\", line 1080, in train_step\n",
      "        y_pred = self(x, training=True)\n",
      "    File \"E:\\anaconda3\\envs\\segmentation\\lib\\site-packages\\keras\\src\\utils\\traceback_utils.py\", line 70, in error_handler\n",
      "        raise e.with_traceback(filtered_tb) from None\n",
      "    File \"E:\\anaconda3\\envs\\segmentation\\lib\\site-packages\\keras\\src\\engine\\input_spec.py\", line 298, in assert_input_compatibility\n",
      "        raise ValueError(\n",
      "\n",
      "    ValueError: Input 0 of layer \"sequential_4\" is incompatible with the layer: expected shape=(None, 10), found shape=(None, 5)\n",
      "\n",
      "\n",
      "--------------------------------------------------------------------------------\n",
      "1 fits failed with the following error:\n",
      "Traceback (most recent call last):\n",
      "  File \"E:\\anaconda3\\envs\\segmentation\\lib\\site-packages\\sklearn\\model_selection\\_validation.py\", line 729, in _fit_and_score\n",
      "    estimator.fit(X_train, y_train, **fit_params)\n",
      "  File \"E:\\anaconda3\\envs\\segmentation\\lib\\site-packages\\sklearn\\base.py\", line 1152, in wrapper\n",
      "    return fit_method(estimator, *args, **kwargs)\n",
      "  File \"E:\\anaconda3\\envs\\segmentation\\lib\\site-packages\\sklearn\\pipeline.py\", line 427, in fit\n",
      "    self._final_estimator.fit(Xt, y, **fit_params_last_step)\n",
      "  File \"C:\\Users\\marcb\\AppData\\Local\\Temp\\ipykernel_24688\\2277059315.py\", line 30, in fit\n",
      "  File \"E:\\anaconda3\\envs\\segmentation\\lib\\site-packages\\keras\\src\\utils\\traceback_utils.py\", line 70, in error_handler\n",
      "    raise e.with_traceback(filtered_tb) from None\n",
      "  File \"C:\\Users\\marcb\\AppData\\Local\\Temp\\__autograph_generated_fileibodyggy.py\", line 15, in tf__train_function\n",
      "    retval_ = ag__.converted_call(ag__.ld(step_function), (ag__.ld(self), ag__.ld(iterator)), None, fscope)\n",
      "ValueError: in user code:\n",
      "\n",
      "    File \"E:\\anaconda3\\envs\\segmentation\\lib\\site-packages\\keras\\src\\engine\\training.py\", line 1338, in train_function  *\n",
      "        return step_function(self, iterator)\n",
      "    File \"E:\\anaconda3\\envs\\segmentation\\lib\\site-packages\\keras\\src\\engine\\training.py\", line 1322, in step_function  **\n",
      "        outputs = model.distribute_strategy.run(run_step, args=(data,))\n",
      "    File \"E:\\anaconda3\\envs\\segmentation\\lib\\site-packages\\keras\\src\\engine\\training.py\", line 1303, in run_step  **\n",
      "        outputs = model.train_step(data)\n",
      "    File \"E:\\anaconda3\\envs\\segmentation\\lib\\site-packages\\keras\\src\\engine\\training.py\", line 1080, in train_step\n",
      "        y_pred = self(x, training=True)\n",
      "    File \"E:\\anaconda3\\envs\\segmentation\\lib\\site-packages\\keras\\src\\utils\\traceback_utils.py\", line 70, in error_handler\n",
      "        raise e.with_traceback(filtered_tb) from None\n",
      "    File \"E:\\anaconda3\\envs\\segmentation\\lib\\site-packages\\keras\\src\\engine\\input_spec.py\", line 298, in assert_input_compatibility\n",
      "        raise ValueError(\n",
      "\n",
      "    ValueError: Input 0 of layer \"sequential_4\" is incompatible with the layer: expected shape=(None, 10), found shape=(None, 5)\n",
      "\n",
      "\n",
      "--------------------------------------------------------------------------------\n",
      "1 fits failed with the following error:\n",
      "Traceback (most recent call last):\n",
      "  File \"E:\\anaconda3\\envs\\segmentation\\lib\\site-packages\\sklearn\\model_selection\\_validation.py\", line 729, in _fit_and_score\n",
      "    estimator.fit(X_train, y_train, **fit_params)\n",
      "  File \"E:\\anaconda3\\envs\\segmentation\\lib\\site-packages\\sklearn\\base.py\", line 1152, in wrapper\n",
      "    return fit_method(estimator, *args, **kwargs)\n",
      "  File \"E:\\anaconda3\\envs\\segmentation\\lib\\site-packages\\sklearn\\pipeline.py\", line 427, in fit\n",
      "    self._final_estimator.fit(Xt, y, **fit_params_last_step)\n",
      "  File \"C:\\Users\\marcb\\AppData\\Local\\Temp\\ipykernel_24688\\2277059315.py\", line 30, in fit\n",
      "  File \"E:\\anaconda3\\envs\\segmentation\\lib\\site-packages\\keras\\src\\utils\\traceback_utils.py\", line 70, in error_handler\n",
      "    raise e.with_traceback(filtered_tb) from None\n",
      "  File \"C:\\Users\\marcb\\AppData\\Local\\Temp\\__autograph_generated_fileq5no0svl.py\", line 15, in tf__train_function\n",
      "    retval_ = ag__.converted_call(ag__.ld(step_function), (ag__.ld(self), ag__.ld(iterator)), None, fscope)\n",
      "ValueError: in user code:\n",
      "\n",
      "    File \"E:\\anaconda3\\envs\\segmentation\\lib\\site-packages\\keras\\src\\engine\\training.py\", line 1338, in train_function  *\n",
      "        return step_function(self, iterator)\n",
      "    File \"E:\\anaconda3\\envs\\segmentation\\lib\\site-packages\\keras\\src\\engine\\training.py\", line 1322, in step_function  **\n",
      "        outputs = model.distribute_strategy.run(run_step, args=(data,))\n",
      "    File \"E:\\anaconda3\\envs\\segmentation\\lib\\site-packages\\keras\\src\\engine\\training.py\", line 1303, in run_step  **\n",
      "        outputs = model.train_step(data)\n",
      "    File \"E:\\anaconda3\\envs\\segmentation\\lib\\site-packages\\keras\\src\\engine\\training.py\", line 1080, in train_step\n",
      "        y_pred = self(x, training=True)\n",
      "    File \"E:\\anaconda3\\envs\\segmentation\\lib\\site-packages\\keras\\src\\utils\\traceback_utils.py\", line 70, in error_handler\n",
      "        raise e.with_traceback(filtered_tb) from None\n",
      "    File \"E:\\anaconda3\\envs\\segmentation\\lib\\site-packages\\keras\\src\\engine\\input_spec.py\", line 298, in assert_input_compatibility\n",
      "        raise ValueError(\n",
      "\n",
      "    ValueError: Input 0 of layer \"sequential_6\" is incompatible with the layer: expected shape=(None, 10), found shape=(None, 15)\n",
      "\n",
      "\n",
      "--------------------------------------------------------------------------------\n",
      "1 fits failed with the following error:\n",
      "Traceback (most recent call last):\n",
      "  File \"E:\\anaconda3\\envs\\segmentation\\lib\\site-packages\\sklearn\\model_selection\\_validation.py\", line 729, in _fit_and_score\n",
      "    estimator.fit(X_train, y_train, **fit_params)\n",
      "  File \"E:\\anaconda3\\envs\\segmentation\\lib\\site-packages\\sklearn\\base.py\", line 1152, in wrapper\n",
      "    return fit_method(estimator, *args, **kwargs)\n",
      "  File \"E:\\anaconda3\\envs\\segmentation\\lib\\site-packages\\sklearn\\pipeline.py\", line 427, in fit\n",
      "    self._final_estimator.fit(Xt, y, **fit_params_last_step)\n",
      "  File \"C:\\Users\\marcb\\AppData\\Local\\Temp\\ipykernel_24688\\2277059315.py\", line 30, in fit\n",
      "  File \"E:\\anaconda3\\envs\\segmentation\\lib\\site-packages\\keras\\src\\utils\\traceback_utils.py\", line 70, in error_handler\n",
      "    raise e.with_traceback(filtered_tb) from None\n",
      "  File \"C:\\Users\\marcb\\AppData\\Local\\Temp\\__autograph_generated_filezpu79s1e.py\", line 15, in tf__train_function\n",
      "    retval_ = ag__.converted_call(ag__.ld(step_function), (ag__.ld(self), ag__.ld(iterator)), None, fscope)\n",
      "ValueError: in user code:\n",
      "\n",
      "    File \"E:\\anaconda3\\envs\\segmentation\\lib\\site-packages\\keras\\src\\engine\\training.py\", line 1338, in train_function  *\n",
      "        return step_function(self, iterator)\n",
      "    File \"E:\\anaconda3\\envs\\segmentation\\lib\\site-packages\\keras\\src\\engine\\training.py\", line 1322, in step_function  **\n",
      "        outputs = model.distribute_strategy.run(run_step, args=(data,))\n",
      "    File \"E:\\anaconda3\\envs\\segmentation\\lib\\site-packages\\keras\\src\\engine\\training.py\", line 1303, in run_step  **\n",
      "        outputs = model.train_step(data)\n",
      "    File \"E:\\anaconda3\\envs\\segmentation\\lib\\site-packages\\keras\\src\\engine\\training.py\", line 1080, in train_step\n",
      "        y_pred = self(x, training=True)\n",
      "    File \"E:\\anaconda3\\envs\\segmentation\\lib\\site-packages\\keras\\src\\utils\\traceback_utils.py\", line 70, in error_handler\n",
      "        raise e.with_traceback(filtered_tb) from None\n",
      "    File \"E:\\anaconda3\\envs\\segmentation\\lib\\site-packages\\keras\\src\\engine\\input_spec.py\", line 298, in assert_input_compatibility\n",
      "        raise ValueError(\n",
      "\n",
      "    ValueError: Input 0 of layer \"sequential_4\" is incompatible with the layer: expected shape=(None, 10), found shape=(None, 15)\n",
      "\n",
      "\n",
      "--------------------------------------------------------------------------------\n",
      "1 fits failed with the following error:\n",
      "Traceback (most recent call last):\n",
      "  File \"E:\\anaconda3\\envs\\segmentation\\lib\\site-packages\\sklearn\\model_selection\\_validation.py\", line 729, in _fit_and_score\n",
      "    estimator.fit(X_train, y_train, **fit_params)\n",
      "  File \"E:\\anaconda3\\envs\\segmentation\\lib\\site-packages\\sklearn\\base.py\", line 1152, in wrapper\n",
      "    return fit_method(estimator, *args, **kwargs)\n",
      "  File \"E:\\anaconda3\\envs\\segmentation\\lib\\site-packages\\sklearn\\pipeline.py\", line 427, in fit\n",
      "    self._final_estimator.fit(Xt, y, **fit_params_last_step)\n",
      "  File \"C:\\Users\\marcb\\AppData\\Local\\Temp\\ipykernel_24688\\2277059315.py\", line 30, in fit\n",
      "  File \"E:\\anaconda3\\envs\\segmentation\\lib\\site-packages\\keras\\src\\utils\\traceback_utils.py\", line 70, in error_handler\n",
      "    raise e.with_traceback(filtered_tb) from None\n",
      "  File \"C:\\Users\\marcb\\AppData\\Local\\Temp\\__autograph_generated_filepjids2ym.py\", line 15, in tf__train_function\n",
      "    retval_ = ag__.converted_call(ag__.ld(step_function), (ag__.ld(self), ag__.ld(iterator)), None, fscope)\n",
      "ValueError: in user code:\n",
      "\n",
      "    File \"E:\\anaconda3\\envs\\segmentation\\lib\\site-packages\\keras\\src\\engine\\training.py\", line 1338, in train_function  *\n",
      "        return step_function(self, iterator)\n",
      "    File \"E:\\anaconda3\\envs\\segmentation\\lib\\site-packages\\keras\\src\\engine\\training.py\", line 1322, in step_function  **\n",
      "        outputs = model.distribute_strategy.run(run_step, args=(data,))\n",
      "    File \"E:\\anaconda3\\envs\\segmentation\\lib\\site-packages\\keras\\src\\engine\\training.py\", line 1303, in run_step  **\n",
      "        outputs = model.train_step(data)\n",
      "    File \"E:\\anaconda3\\envs\\segmentation\\lib\\site-packages\\keras\\src\\engine\\training.py\", line 1080, in train_step\n",
      "        y_pred = self(x, training=True)\n",
      "    File \"E:\\anaconda3\\envs\\segmentation\\lib\\site-packages\\keras\\src\\utils\\traceback_utils.py\", line 70, in error_handler\n",
      "        raise e.with_traceback(filtered_tb) from None\n",
      "    File \"E:\\anaconda3\\envs\\segmentation\\lib\\site-packages\\keras\\src\\engine\\input_spec.py\", line 298, in assert_input_compatibility\n",
      "        raise ValueError(\n",
      "\n",
      "    ValueError: Input 0 of layer \"sequential_5\" is incompatible with the layer: expected shape=(None, 10), found shape=(None, 15)\n",
      "\n",
      "\n",
      "  warnings.warn(some_fits_failed_message, FitFailedWarning)\n",
      "E:\\anaconda3\\envs\\segmentation\\lib\\site-packages\\sklearn\\model_selection\\_search.py:979: UserWarning: One or more of the test scores are non-finite: [       nan 0.64482387        nan        nan 0.60958135        nan\n",
      "        nan 0.6514584         nan        nan 0.62699364        nan]\n",
      "  warnings.warn(\n"
     ]
    },
    {
     "name": "stdout",
     "output_type": "stream",
     "text": [
      "Fitting 3 folds for each of 18 candidates, totalling 54 fits\n",
      "Fitting 3 folds for each of 9 candidates, totalling 27 fits\n",
      "Fitting 3 folds for each of 54 candidates, totalling 162 fits\n"
     ]
    },
    {
     "name": "stderr",
     "output_type": "stream",
     "text": [
      "E:\\anaconda3\\envs\\segmentation\\lib\\site-packages\\sklearn\\feature_selection\\_univariate_selection.py:112: UserWarning: Features [78 91] are constant.\n",
      "  warnings.warn(\"Features %s are constant.\" % constant_features_idx, UserWarning)\n",
      "E:\\anaconda3\\envs\\segmentation\\lib\\site-packages\\sklearn\\feature_selection\\_univariate_selection.py:113: RuntimeWarning: invalid value encountered in divide\n",
      "  f = msb / msw\n"
     ]
    },
    {
     "name": "stdout",
     "output_type": "stream",
     "text": [
      "38/38 [==============================] - 0s 743us/step\n"
     ]
    }
   ],
   "source": [
    "import pandas as pd\n",
    "import numpy as np\n",
    "import matplotlib.pyplot as plt\n",
    "from sklearn.model_selection import train_test_split, GridSearchCV\n",
    "from sklearn.preprocessing import LabelEncoder, StandardScaler\n",
    "from sklearn.linear_model import LogisticRegression\n",
    "from sklearn.ensemble import RandomForestClassifier, GradientBoostingClassifier\n",
    "from xgboost import XGBClassifier\n",
    "from sklearn.svm import SVC\n",
    "from sklearn.neighbors import KNeighborsClassifier\n",
    "from sklearn.metrics import accuracy_score, classification_report\n",
    "from tensorflow.keras.models import Sequential\n",
    "from tensorflow.keras.layers import Dense\n",
    "from sklearn.base import BaseEstimator, ClassifierMixin\n",
    "from sklearn.decomposition import PCA\n",
    "from sklearn.feature_selection import SelectKBest, f_classif\n",
    "from sklearn.pipeline import Pipeline\n",
    "\n",
    "# Custom KerasClassifier for deep learning\n",
    "class KerasClassifier(BaseEstimator, ClassifierMixin):\n",
    "    def __init__(self, build_fn=None, epochs=1, batch_size=32, verbose=1):\n",
    "        self.build_fn = build_fn\n",
    "        self.epochs = epochs\n",
    "        self.batch_size = batch_size\n",
    "        self.verbose = verbose\n",
    "        self.model_ = None\n",
    "\n",
    "    def fit(self, X, y):\n",
    "        self.model_ = self.build_fn()\n",
    "        self.model_.fit(X, y, epochs=self.epochs, batch_size=self.batch_size, verbose=self.verbose)\n",
    "        return self\n",
    "\n",
    "    def predict(self, X):\n",
    "        y_pred = self.model_.predict(X)\n",
    "        return (y_pred > 0.5).astype(int)\n",
    "\n",
    "    def score(self, X, y):\n",
    "        _, accuracy = self.model_.evaluate(X, y, verbose=0)\n",
    "        return accuracy\n",
    "\n",
    "# Step 1: Load the dataset\n",
    "df = pd.read_csv(\"ufc-master.csv\")\n",
    "\n",
    "# Step 2: Handle missing values\n",
    "numeric_columns = df.select_dtypes(include=[np.number]).columns\n",
    "df[numeric_columns] = df[numeric_columns].fillna(df[numeric_columns].mean())\n",
    "categorical_columns = df.select_dtypes(include=['object']).columns\n",
    "df[categorical_columns] = df[categorical_columns].fillna('Unknown')\n",
    "\n",
    "# Step 3: Remove fighter names\n",
    "df = df.drop(columns=['RedFighter', 'BlueFighter'])\n",
    "\n",
    "# Step 4: Encode categorical variables\n",
    "label_enc = LabelEncoder()\n",
    "for col in categorical_columns:\n",
    "    if col in df.columns:\n",
    "        df[col] = label_enc.fit_transform(df[col])\n",
    "\n",
    "# Step 5: Feature Scaling\n",
    "scaler = StandardScaler()\n",
    "X = df.drop('Winner', axis=1)\n",
    "y = df['Winner']\n",
    "X_scaled = scaler.fit_transform(X)\n",
    "\n",
    "# Step 6: Split data into training and testing sets\n",
    "X_train, X_test, y_train, y_test = train_test_split(X_scaled, y, test_size=0.2, random_state=42)\n",
    "\n",
    "# Step 7: Define Models\n",
    "def create_neural_network_model(input_dim):\n",
    "    model = Sequential()\n",
    "    model.add(Dense(64, input_dim=input_dim, activation='relu'))\n",
    "    model.add(Dense(32, activation='relu'))\n",
    "    model.add(Dense(1, activation='sigmoid'))\n",
    "    model.compile(optimizer='adam', loss='binary_crossentropy', metrics=['accuracy'])\n",
    "    return model\n",
    "\n",
    "models = {\n",
    "    'LogisticRegression': LogisticRegression(),\n",
    "    'RandomForest': RandomForestClassifier(),\n",
    "    'XGBoost': XGBClassifier(),\n",
    "    'NeuralNetwork': KerasClassifier(build_fn=lambda: create_neural_network_model(10), epochs=50, batch_size=32, verbose=0),\n",
    "    'SVM': SVC(),\n",
    "    'KNN': KNeighborsClassifier(),\n",
    "    'GradientBoosting': GradientBoostingClassifier()\n",
    "}\n",
    "\n",
    "# Step 8: Define parameter grids for models\n",
    "param_grids = {\n",
    "    'LogisticRegression': {\n",
    "        'reduce_dim__n_components': [5, 10, 15],\n",
    "        'classifier__C': [0.1, 1.0, 10.0],\n",
    "        'classifier__solver': ['liblinear', 'lbfgs']\n",
    "    },\n",
    "    'RandomForest': {\n",
    "        'reduce_dim__k': [10, 20, 30],\n",
    "        'classifier__n_estimators': [100, 200],\n",
    "        'classifier__max_depth': [None, 10, 20],\n",
    "        'classifier__min_samples_split': [2, 5]\n",
    "    },\n",
    "    'XGBoost': {\n",
    "        'reduce_dim__k': [10, 20, 30],\n",
    "        'classifier__n_estimators': [50, 100],\n",
    "        'classifier__learning_rate': [0.01, 0.1, 0.2],\n",
    "        'classifier__max_depth': [3, 6, 10]\n",
    "    },\n",
    "    'NeuralNetwork': {\n",
    "        'reduce_dim__n_components': [5, 10, 15],\n",
    "        'classifier__epochs': [20, 50],\n",
    "        'classifier__batch_size': [16, 32]\n",
    "    },\n",
    "    'SVM': {\n",
    "        'reduce_dim__n_components': [5, 10, 15],\n",
    "        'classifier__C': [0.1, 1.0, 10.0],\n",
    "        'classifier__kernel': ['linear', 'rbf']\n",
    "    },\n",
    "    'KNN': {\n",
    "        'reduce_dim__n_components': [5, 10, 15],\n",
    "        'classifier__n_neighbors': [3, 5, 7]\n",
    "    },\n",
    "    'GradientBoosting': {\n",
    "        'reduce_dim__k': [10, 20, 30],\n",
    "        'classifier__n_estimators': [50, 100],\n",
    "        'classifier__learning_rate': [0.01, 0.1, 0.2],\n",
    "        'classifier__max_depth': [3, 5, 7]\n",
    "    }\n",
    "}\n",
    "\n",
    "# Step 9: Create pipelines\n",
    "pipelines = {\n",
    "    'LogisticRegression': Pipeline([('reduce_dim', PCA()), ('classifier', models['LogisticRegression'])]),\n",
    "    'RandomForest': Pipeline([('reduce_dim', SelectKBest(score_func=f_classif)), ('classifier', models['RandomForest'])]),\n",
    "    'XGBoost': Pipeline([('reduce_dim', SelectKBest(score_func=f_classif)), ('classifier', models['XGBoost'])]),\n",
    "    'NeuralNetwork': Pipeline([('reduce_dim', PCA()), ('classifier', models['NeuralNetwork'])]),\n",
    "    'SVM': Pipeline([('reduce_dim', PCA()), ('classifier', models['SVM'])]),\n",
    "    'KNN': Pipeline([('reduce_dim', PCA()), ('classifier', models['KNN'])]),\n",
    "    'GradientBoosting': Pipeline([('reduce_dim', SelectKBest(score_func=f_classif)), ('classifier', models['GradientBoosting'])])\n",
    "}\n",
    "\n",
    "# Step 10: Perform GridSearch\n",
    "best_models = {}\n",
    "for model_name in pipelines:\n",
    "    grid = GridSearchCV(estimator=pipelines[model_name], param_grid=param_grids[model_name], cv=3, n_jobs=-1, verbose=1)\n",
    "    grid.fit(X_train, y_train)\n",
    "    best_models[model_name] = grid.best_estimator_\n",
    "\n",
    "# Step 11: Evaluate best models\n",
    "model_performance = {}\n",
    "for model_name, model in best_models.items():\n",
    "    y_pred = model.predict(X_test)\n",
    "    if model_name == 'NeuralNetwork':\n",
    "        y_pred = (y_pred > 0.5).astype(int)\n",
    "    accuracy = accuracy_score(y_test, y_pred)\n",
    "    model_performance[model_name] = accuracy\n",
    "\n",
    "# Step 12: Visualize Predictions and Feature Importance\n",
    "top_3_models = sorted(model_performance, key=model_performance.get, reverse=True)[:3]\n",
    "\n",
    "# Fighter data for prediction\n",
    "fighter_1 = {\n",
    "    # Your fighter data here\n",
    "}\n",
    "\n",
    "\n"
   ]
  },
  {
   "cell_type": "code",
   "execution_count": 61,
   "id": "7c39303a-8172-450e-a54e-0f8b212fbe91",
   "metadata": {},
   "outputs": [
    {
     "ename": "ValueError",
     "evalue": "The feature names should match those that were passed during fit.\nFeature names seen at fit time, yet now missing:\n- Country\n- Date\n- Finish\n- FinishDetails\n- FinishRoundTime\n- ...\n",
     "output_type": "error",
     "traceback": [
      "\u001b[1;31m---------------------------------------------------------------------------\u001b[0m",
      "\u001b[1;31mValueError\u001b[0m                                Traceback (most recent call last)",
      "\u001b[1;32m~\\AppData\\Local\\Temp\\ipykernel_24688\\4047903706.py\u001b[0m in \u001b[0;36m<module>\u001b[1;34m\u001b[0m\n\u001b[0;32m    130\u001b[0m \u001b[1;33m\u001b[0m\u001b[0m\n\u001b[0;32m    131\u001b[0m \u001b[1;31m# Scale the numerical columns using the fitted scaler\u001b[0m\u001b[1;33m\u001b[0m\u001b[1;33m\u001b[0m\u001b[1;33m\u001b[0m\u001b[0m\n\u001b[1;32m--> 132\u001b[1;33m \u001b[0mfighter_comparison_scaled\u001b[0m \u001b[1;33m=\u001b[0m \u001b[0mscaler\u001b[0m\u001b[1;33m.\u001b[0m\u001b[0mtransform\u001b[0m\u001b[1;33m(\u001b[0m\u001b[0mfighter_comparison_df\u001b[0m\u001b[1;33m)\u001b[0m\u001b[1;33m\u001b[0m\u001b[1;33m\u001b[0m\u001b[0m\n\u001b[0m\u001b[0;32m    133\u001b[0m \u001b[1;33m\u001b[0m\u001b[0m\n\u001b[0;32m    134\u001b[0m \u001b[1;31m# Step 3: Use the top 3 models to predict the outcome\u001b[0m\u001b[1;33m\u001b[0m\u001b[1;33m\u001b[0m\u001b[1;33m\u001b[0m\u001b[0m\n",
      "\u001b[1;32mE:\\anaconda3\\envs\\segmentation\\lib\\site-packages\\sklearn\\utils\\_set_output.py\u001b[0m in \u001b[0;36mwrapped\u001b[1;34m(self, X, *args, **kwargs)\u001b[0m\n\u001b[0;32m    155\u001b[0m     \u001b[1;33m@\u001b[0m\u001b[0mwraps\u001b[0m\u001b[1;33m(\u001b[0m\u001b[0mf\u001b[0m\u001b[1;33m)\u001b[0m\u001b[1;33m\u001b[0m\u001b[1;33m\u001b[0m\u001b[0m\n\u001b[0;32m    156\u001b[0m     \u001b[1;32mdef\u001b[0m \u001b[0mwrapped\u001b[0m\u001b[1;33m(\u001b[0m\u001b[0mself\u001b[0m\u001b[1;33m,\u001b[0m \u001b[0mX\u001b[0m\u001b[1;33m,\u001b[0m \u001b[1;33m*\u001b[0m\u001b[0margs\u001b[0m\u001b[1;33m,\u001b[0m \u001b[1;33m**\u001b[0m\u001b[0mkwargs\u001b[0m\u001b[1;33m)\u001b[0m\u001b[1;33m:\u001b[0m\u001b[1;33m\u001b[0m\u001b[1;33m\u001b[0m\u001b[0m\n\u001b[1;32m--> 157\u001b[1;33m         \u001b[0mdata_to_wrap\u001b[0m \u001b[1;33m=\u001b[0m \u001b[0mf\u001b[0m\u001b[1;33m(\u001b[0m\u001b[0mself\u001b[0m\u001b[1;33m,\u001b[0m \u001b[0mX\u001b[0m\u001b[1;33m,\u001b[0m \u001b[1;33m*\u001b[0m\u001b[0margs\u001b[0m\u001b[1;33m,\u001b[0m \u001b[1;33m**\u001b[0m\u001b[0mkwargs\u001b[0m\u001b[1;33m)\u001b[0m\u001b[1;33m\u001b[0m\u001b[1;33m\u001b[0m\u001b[0m\n\u001b[0m\u001b[0;32m    158\u001b[0m         \u001b[1;32mif\u001b[0m \u001b[0misinstance\u001b[0m\u001b[1;33m(\u001b[0m\u001b[0mdata_to_wrap\u001b[0m\u001b[1;33m,\u001b[0m \u001b[0mtuple\u001b[0m\u001b[1;33m)\u001b[0m\u001b[1;33m:\u001b[0m\u001b[1;33m\u001b[0m\u001b[1;33m\u001b[0m\u001b[0m\n\u001b[0;32m    159\u001b[0m             \u001b[1;31m# only wrap the first output for cross decomposition\u001b[0m\u001b[1;33m\u001b[0m\u001b[1;33m\u001b[0m\u001b[1;33m\u001b[0m\u001b[0m\n",
      "\u001b[1;32mE:\\anaconda3\\envs\\segmentation\\lib\\site-packages\\sklearn\\preprocessing\\_data.py\u001b[0m in \u001b[0;36mtransform\u001b[1;34m(self, X, copy)\u001b[0m\n\u001b[0;32m   1004\u001b[0m \u001b[1;33m\u001b[0m\u001b[0m\n\u001b[0;32m   1005\u001b[0m         \u001b[0mcopy\u001b[0m \u001b[1;33m=\u001b[0m \u001b[0mcopy\u001b[0m \u001b[1;32mif\u001b[0m \u001b[0mcopy\u001b[0m \u001b[1;32mis\u001b[0m \u001b[1;32mnot\u001b[0m \u001b[1;32mNone\u001b[0m \u001b[1;32melse\u001b[0m \u001b[0mself\u001b[0m\u001b[1;33m.\u001b[0m\u001b[0mcopy\u001b[0m\u001b[1;33m\u001b[0m\u001b[1;33m\u001b[0m\u001b[0m\n\u001b[1;32m-> 1006\u001b[1;33m         X = self._validate_data(\n\u001b[0m\u001b[0;32m   1007\u001b[0m             \u001b[0mX\u001b[0m\u001b[1;33m,\u001b[0m\u001b[1;33m\u001b[0m\u001b[1;33m\u001b[0m\u001b[0m\n\u001b[0;32m   1008\u001b[0m             \u001b[0mreset\u001b[0m\u001b[1;33m=\u001b[0m\u001b[1;32mFalse\u001b[0m\u001b[1;33m,\u001b[0m\u001b[1;33m\u001b[0m\u001b[1;33m\u001b[0m\u001b[0m\n",
      "\u001b[1;32mE:\\anaconda3\\envs\\segmentation\\lib\\site-packages\\sklearn\\base.py\u001b[0m in \u001b[0;36m_validate_data\u001b[1;34m(self, X, y, reset, validate_separately, cast_to_ndarray, **check_params)\u001b[0m\n\u001b[0;32m    578\u001b[0m             \u001b[0mvalidated\u001b[0m\u001b[1;33m.\u001b[0m\u001b[1;33m\u001b[0m\u001b[1;33m\u001b[0m\u001b[0m\n\u001b[0;32m    579\u001b[0m         \"\"\"\n\u001b[1;32m--> 580\u001b[1;33m         \u001b[0mself\u001b[0m\u001b[1;33m.\u001b[0m\u001b[0m_check_feature_names\u001b[0m\u001b[1;33m(\u001b[0m\u001b[0mX\u001b[0m\u001b[1;33m,\u001b[0m \u001b[0mreset\u001b[0m\u001b[1;33m=\u001b[0m\u001b[0mreset\u001b[0m\u001b[1;33m)\u001b[0m\u001b[1;33m\u001b[0m\u001b[1;33m\u001b[0m\u001b[0m\n\u001b[0m\u001b[0;32m    581\u001b[0m \u001b[1;33m\u001b[0m\u001b[0m\n\u001b[0;32m    582\u001b[0m         \u001b[1;32mif\u001b[0m \u001b[0my\u001b[0m \u001b[1;32mis\u001b[0m \u001b[1;32mNone\u001b[0m \u001b[1;32mand\u001b[0m \u001b[0mself\u001b[0m\u001b[1;33m.\u001b[0m\u001b[0m_get_tags\u001b[0m\u001b[1;33m(\u001b[0m\u001b[1;33m)\u001b[0m\u001b[1;33m[\u001b[0m\u001b[1;34m\"requires_y\"\u001b[0m\u001b[1;33m]\u001b[0m\u001b[1;33m:\u001b[0m\u001b[1;33m\u001b[0m\u001b[1;33m\u001b[0m\u001b[0m\n",
      "\u001b[1;32mE:\\anaconda3\\envs\\segmentation\\lib\\site-packages\\sklearn\\base.py\u001b[0m in \u001b[0;36m_check_feature_names\u001b[1;34m(self, X, reset)\u001b[0m\n\u001b[0;32m    505\u001b[0m                 )\n\u001b[0;32m    506\u001b[0m \u001b[1;33m\u001b[0m\u001b[0m\n\u001b[1;32m--> 507\u001b[1;33m             \u001b[1;32mraise\u001b[0m \u001b[0mValueError\u001b[0m\u001b[1;33m(\u001b[0m\u001b[0mmessage\u001b[0m\u001b[1;33m)\u001b[0m\u001b[1;33m\u001b[0m\u001b[1;33m\u001b[0m\u001b[0m\n\u001b[0m\u001b[0;32m    508\u001b[0m \u001b[1;33m\u001b[0m\u001b[0m\n\u001b[0;32m    509\u001b[0m     def _validate_data(\n",
      "\u001b[1;31mValueError\u001b[0m: The feature names should match those that were passed during fit.\nFeature names seen at fit time, yet now missing:\n- Country\n- Date\n- Finish\n- FinishDetails\n- FinishRoundTime\n- ...\n"
     ]
    }
   ],
   "source": [
    "# Step 12: Fighter data for prediction\n",
    "fighter_1 = {\n",
    "    'RedOdds': -150,\n",
    "    'BlueOdds': 120,\n",
    "    'RedExpectedValue': 0.6,\n",
    "    'BlueExpectedValue': 0.4,\n",
    "    'Date': '2024-10-26',\n",
    "    'Location': 'Abu Dhabi',\n",
    "    'Country': 'Spain',\n",
    "    'TitleBout': True,\n",
    "    'WeightClass': 'Featherweight',\n",
    "    'Gender': 'MALE',\n",
    "    'NumberOfRounds': 5,\n",
    "    'BlueCurrentLoseStreak': 0,\n",
    "    'BlueCurrentWinStreak': 1,\n",
    "    'BlueDraws': 0,\n",
    "    'BlueAvgSigStrLanded': 7.16,\n",
    "    'BlueAvgSigStrPct': 49.0,\n",
    "    'BlueAvgSubAtt': 0.4,\n",
    "    'BlueAvgTDLanded': 0.5,\n",
    "    'BlueAvgTDPct': 83.0,\n",
    "    'BlueLongestWinStreak': 14,\n",
    "    'BlueLosses': 7,\n",
    "    'BlueTotalRoundsFought': 113,\n",
    "    'BlueTotalTitleBouts': 11,\n",
    "    'BlueWinsByDecisionMajority': 0,\n",
    "    'BlueWinsByDecisionSplit': 0,\n",
    "    'BlueWinsByDecisionUnanimous': 10,\n",
    "    'BlueWinsByKO': 11,\n",
    "    'BlueWinsBySubmission': 2,\n",
    "    'BlueWinsByTKODoctorStoppage': 1,\n",
    "    'BlueWins': 24,\n",
    "    'BlueStance': 'Orthodox',\n",
    "    'BlueHeightCms': 180,\n",
    "    'BlueReachCms': 175,\n",
    "    'BlueWeightLbs': 145,\n",
    "    'RedCurrentLoseStreak': 0,\n",
    "    'RedCurrentWinStreak': 5,\n",
    "    'RedDraws': 0,\n",
    "    'RedAvgSigStrLanded': 4.40,\n",
    "    'RedAvgSigStrPct': 46.0,\n",
    "    'RedAvgSubAtt': 1.28,\n",
    "    'RedAvgTDLanded': 1.92,\n",
    "    'RedAvgTDPct': 56.0,\n",
    "    'RedLongestWinStreak': 5,\n",
    "    'RedLosses': 0,\n",
    "    'RedTotalRoundsFought': 25,\n",
    "    'RedTotalTitleBouts': 1,\n",
    "    'RedWinsByDecisionMajority': 2,\n",
    "    'RedWinsByDecisionSplit': 1,\n",
    "    'RedWinsByDecisionUnanimous': 2,\n",
    "    'RedWinsByKO': 5,\n",
    "    'RedWinsBySubmission': 8,\n",
    "    'RedWinsByTKODoctorStoppage': 0,\n",
    "    'RedWins': 15,\n",
    "    'RedStance': 'Orthodox',\n",
    "    'RedHeightCms': 170,\n",
    "    'RedReachCms': 175,\n",
    "    'RedWeightLbs': 145,\n",
    "    'RedAge': 27,\n",
    "    'BlueAge': 32,\n",
    "    'LoseStreakDif': 0,\n",
    "    'WinStreakDif': 4,\n",
    "    'LongestWinStreakDif': -9,\n",
    "    'WinDif': -9,\n",
    "    'LossDif': 7,\n",
    "    'TotalRoundDif': -88,\n",
    "    'TotalTitleBoutDif': -10,\n",
    "    'KODif': 6,\n",
    "    'SubDif': 6,\n",
    "    'HeightDif': -5,\n",
    "    'ReachDif': 0,\n",
    "    'AgeDif': -5,\n",
    "    'SigStrDif': -2.76,\n",
    "    'AvgSubAttDif': 0.88,\n",
    "    'AvgTDDif': 1.42,\n",
    "    'EmptyArena': False,\n",
    "    'BMatchWCRank': 1,\n",
    "    'RMatchWCRank': 1,\n",
    "    'RWFlyweightRank': 0,\n",
    "    'RWFeatherweightRank': 1,\n",
    "    'RWStrawweightRank': 0,\n",
    "    'RWBantamweightRank': 0,\n",
    "    'RHeavyweightRank': 0,\n",
    "    'RLightHeavyweightRank': 0,\n",
    "    'RMiddleweightRank': 3,\n",
    "    'RWelterweightRank': 0,\n",
    "    'RLightweightRank': 0,\n",
    "    'RFeatherweightRank': 1,\n",
    "    'RBantamweightRank': 0,\n",
    "    'RFlyweightRank': 0,\n",
    "    'RPFPRank': 1,\n",
    "    'BWFlyweightRank': 0,\n",
    "    'BWFeatherweightRank': 0,\n",
    "    'BWStrawweightRank': 0,\n",
    "    'BWBantamweightRank': 0,\n",
    "    'BHeavyweightRank': 0,\n",
    "    'BLightHeavyweightRank': 0,\n",
    "    'BMiddleweightRank': 0,\n",
    "    'BWelterweightRank': 0,\n",
    "    'BLightweightRank': 0,\n",
    "    'BFeatherweightRank': 0,\n",
    "    'BBantamweightRank': 0,\n",
    "    'BFlyweightRank': 0,\n",
    "    'BPFPRank': 2,\n",
    "    'BetterRank': 0,\n",
    "    'Finish': 'KO',\n",
    "    'FinishDetails': 'Punches',\n",
    "    'FinishRound': 2,\n",
    "    'FinishRoundTime': '3:32',\n",
    "    'TotalFightTimeSecs': 600,\n",
    "    'RedDecOdds': 150,\n",
    "    'BlueDecOdds': -150,\n",
    "    'RSubOdds': 300,\n",
    "    'BSubOdds': -100,\n",
    "    'RKOOdds': 120,\n",
    "    'BKOOdds': -150\n",
    "}\n",
    "\n",
    "# Remove or convert non-numeric columns before scaling\n",
    "fighter_comparison_df = fighter_comparison_df.drop(columns=['Date', 'Location', 'Country', 'Finish', 'FinishDetails', 'FinishRoundTime'])\n",
    "\n",
    "# Ensure all remaining categorical columns are label-encoded\n",
    "for col in categorical_columns:\n",
    "    if col in fighter_comparison_df.columns:\n",
    "        unseen_categories = [item for item in fighter_comparison_df[col].unique() if item not in label_enc.classes_]\n",
    "        if unseen_categories:\n",
    "            label_enc.classes_ = np.append(label_enc.classes_, unseen_categories)\n",
    "        fighter_comparison_df[col] = label_enc.transform(fighter_comparison_df[col])\n",
    "\n",
    "# Scale the numerical columns using the fitted scaler\n",
    "fighter_comparison_scaled = scaler.transform(fighter_comparison_df)\n",
    "\n",
    "# Step 3: Use the top 3 models to predict the outcome\n",
    "predictions = []\n",
    "model_names = []\n",
    "\n",
    "for model_name in top_3_models:\n",
    "    model = best_models[model_name]\n",
    "    prediction = model.predict(fighter_comparison_scaled)[0]\n",
    "    predictions.append(prediction)\n",
    "    model_names.append(model_name)\n",
    "\n",
    "# Plot predictions\n",
    "import matplotlib.pyplot as plt\n",
    "\n",
    "plt.figure(figsize=(10, 5))\n",
    "plt.bar(model_names, predictions, color=['blue' if p == 0 else 'red' for p in predictions])\n",
    "plt.xlabel('Models')\n",
    "plt.ylabel('Prediction (0: Blue Win, 1: Red Win)')\n",
    "plt.title('Predictions for the fight')\n",
    "plt.show()\n"
   ]
  },
  {
   "cell_type": "code",
   "execution_count": null,
   "id": "c11076b5-bb75-41f3-bbcd-f12e28823bb9",
   "metadata": {},
   "outputs": [],
   "source": []
  },
  {
   "cell_type": "code",
   "execution_count": null,
   "id": "7d8d27f4-f4a7-4477-a492-dee6f80f7d7a",
   "metadata": {},
   "outputs": [],
   "source": []
  },
  {
   "cell_type": "code",
   "execution_count": null,
   "id": "6601e246-ebf1-4b74-af67-5a8a60a4259a",
   "metadata": {},
   "outputs": [],
   "source": []
  },
  {
   "cell_type": "code",
   "execution_count": null,
   "id": "bbd0cb4e-729e-45af-b989-8bbfde85c56c",
   "metadata": {},
   "outputs": [],
   "source": []
  },
  {
   "cell_type": "code",
   "execution_count": null,
   "id": "feb53a9b-2e6a-47ae-b58f-421378a714b8",
   "metadata": {},
   "outputs": [],
   "source": []
  },
  {
   "cell_type": "code",
   "execution_count": null,
   "id": "f1d6b11f-d38a-4d02-9baa-f20abbe3cf60",
   "metadata": {},
   "outputs": [],
   "source": []
  },
  {
   "cell_type": "code",
   "execution_count": null,
   "id": "b9886902-19d4-4f45-8526-9324173893d2",
   "metadata": {},
   "outputs": [],
   "source": []
  },
  {
   "cell_type": "code",
   "execution_count": null,
   "id": "eda51398-2b56-4ac7-8484-4c6a5641a8b3",
   "metadata": {},
   "outputs": [],
   "source": []
  },
  {
   "cell_type": "code",
   "execution_count": 62,
   "id": "e72f35e6-95b3-4648-b60f-41e1d1393a9b",
   "metadata": {
    "scrolled": true
   },
   "outputs": [
    {
     "name": "stdout",
     "output_type": "stream",
     "text": [
      "\n",
      "Running GridSearch for LogisticRegression...\n",
      "Fitting 3 folds for each of 18 candidates, totalling 54 fits\n",
      "Best parameters for LogisticRegression: {'classifier__C': 0.1, 'classifier__solver': 'lbfgs', 'reduce_dim__n_components': 10}\n",
      "\n",
      "Running GridSearch for RandomForest...\n",
      "Fitting 3 folds for each of 36 candidates, totalling 108 fits\n"
     ]
    },
    {
     "name": "stderr",
     "output_type": "stream",
     "text": [
      "E:\\anaconda3\\envs\\segmentation\\lib\\site-packages\\sklearn\\feature_selection\\_univariate_selection.py:112: UserWarning: Features [78 91] are constant.\n",
      "  warnings.warn(\"Features %s are constant.\" % constant_features_idx, UserWarning)\n",
      "E:\\anaconda3\\envs\\segmentation\\lib\\site-packages\\sklearn\\feature_selection\\_univariate_selection.py:113: RuntimeWarning: invalid value encountered in divide\n",
      "  f = msb / msw\n"
     ]
    },
    {
     "name": "stdout",
     "output_type": "stream",
     "text": [
      "Best parameters for RandomForest: {'classifier__max_depth': 10, 'classifier__min_samples_split': 5, 'classifier__n_estimators': 200, 'reduce_dim__k': 20}\n",
      "\n",
      "Running GridSearch for XGBoost...\n",
      "Fitting 3 folds for each of 54 candidates, totalling 162 fits\n"
     ]
    },
    {
     "name": "stderr",
     "output_type": "stream",
     "text": [
      "E:\\anaconda3\\envs\\segmentation\\lib\\site-packages\\sklearn\\feature_selection\\_univariate_selection.py:112: UserWarning: Features [78 91] are constant.\n",
      "  warnings.warn(\"Features %s are constant.\" % constant_features_idx, UserWarning)\n",
      "E:\\anaconda3\\envs\\segmentation\\lib\\site-packages\\sklearn\\feature_selection\\_univariate_selection.py:113: RuntimeWarning: invalid value encountered in divide\n",
      "  f = msb / msw\n"
     ]
    },
    {
     "name": "stdout",
     "output_type": "stream",
     "text": [
      "Best parameters for XGBoost: {'classifier__learning_rate': 0.1, 'classifier__max_depth': 3, 'classifier__n_estimators': 50, 'reduce_dim__k': 20}\n",
      "\n",
      "Running GridSearch for NeuralNetwork...\n",
      "Fitting 3 folds for each of 12 candidates, totalling 36 fits\n"
     ]
    },
    {
     "name": "stderr",
     "output_type": "stream",
     "text": [
      "E:\\anaconda3\\envs\\segmentation\\lib\\site-packages\\sklearn\\model_selection\\_validation.py:425: FitFailedWarning: \n",
      "24 fits failed out of a total of 36.\n",
      "The score on these train-test partitions for these parameters will be set to nan.\n",
      "If these failures are not expected, you can try to debug them by setting error_score='raise'.\n",
      "\n",
      "Below are more details about the failures:\n",
      "--------------------------------------------------------------------------------\n",
      "1 fits failed with the following error:\n",
      "Traceback (most recent call last):\n",
      "  File \"E:\\anaconda3\\envs\\segmentation\\lib\\site-packages\\sklearn\\model_selection\\_validation.py\", line 729, in _fit_and_score\n",
      "    estimator.fit(X_train, y_train, **fit_params)\n",
      "  File \"E:\\anaconda3\\envs\\segmentation\\lib\\site-packages\\sklearn\\base.py\", line 1152, in wrapper\n",
      "    return fit_method(estimator, *args, **kwargs)\n",
      "  File \"E:\\anaconda3\\envs\\segmentation\\lib\\site-packages\\sklearn\\pipeline.py\", line 427, in fit\n",
      "    self._final_estimator.fit(Xt, y, **fit_params_last_step)\n",
      "  File \"C:\\Users\\marcb\\AppData\\Local\\Temp\\ipykernel_24688\\3521222499.py\", line 27, in fit\n",
      "  File \"E:\\anaconda3\\envs\\segmentation\\lib\\site-packages\\keras\\src\\utils\\traceback_utils.py\", line 70, in error_handler\n",
      "    raise e.with_traceback(filtered_tb) from None\n",
      "  File \"C:\\Users\\marcb\\AppData\\Local\\Temp\\__autograph_generated_fileglr5i53b.py\", line 15, in tf__train_function\n",
      "    retval_ = ag__.converted_call(ag__.ld(step_function), (ag__.ld(self), ag__.ld(iterator)), None, fscope)\n",
      "ValueError: in user code:\n",
      "\n",
      "    File \"E:\\anaconda3\\envs\\segmentation\\lib\\site-packages\\keras\\src\\engine\\training.py\", line 1338, in train_function  *\n",
      "        return step_function(self, iterator)\n",
      "    File \"E:\\anaconda3\\envs\\segmentation\\lib\\site-packages\\keras\\src\\engine\\training.py\", line 1322, in step_function  **\n",
      "        outputs = model.distribute_strategy.run(run_step, args=(data,))\n",
      "    File \"E:\\anaconda3\\envs\\segmentation\\lib\\site-packages\\keras\\src\\engine\\training.py\", line 1303, in run_step  **\n",
      "        outputs = model.train_step(data)\n",
      "    File \"E:\\anaconda3\\envs\\segmentation\\lib\\site-packages\\keras\\src\\engine\\training.py\", line 1080, in train_step\n",
      "        y_pred = self(x, training=True)\n",
      "    File \"E:\\anaconda3\\envs\\segmentation\\lib\\site-packages\\keras\\src\\utils\\traceback_utils.py\", line 70, in error_handler\n",
      "        raise e.with_traceback(filtered_tb) from None\n",
      "    File \"E:\\anaconda3\\envs\\segmentation\\lib\\site-packages\\keras\\src\\engine\\input_spec.py\", line 298, in assert_input_compatibility\n",
      "        raise ValueError(\n",
      "\n",
      "    ValueError: Input 0 of layer \"sequential_5\" is incompatible with the layer: expected shape=(None, 10), found shape=(None, 5)\n",
      "\n",
      "\n",
      "--------------------------------------------------------------------------------\n",
      "1 fits failed with the following error:\n",
      "Traceback (most recent call last):\n",
      "  File \"E:\\anaconda3\\envs\\segmentation\\lib\\site-packages\\sklearn\\model_selection\\_validation.py\", line 729, in _fit_and_score\n",
      "    estimator.fit(X_train, y_train, **fit_params)\n",
      "  File \"E:\\anaconda3\\envs\\segmentation\\lib\\site-packages\\sklearn\\base.py\", line 1152, in wrapper\n",
      "    return fit_method(estimator, *args, **kwargs)\n",
      "  File \"E:\\anaconda3\\envs\\segmentation\\lib\\site-packages\\sklearn\\pipeline.py\", line 427, in fit\n",
      "    self._final_estimator.fit(Xt, y, **fit_params_last_step)\n",
      "  File \"C:\\Users\\marcb\\AppData\\Local\\Temp\\ipykernel_24688\\3521222499.py\", line 27, in fit\n",
      "  File \"E:\\anaconda3\\envs\\segmentation\\lib\\site-packages\\keras\\src\\utils\\traceback_utils.py\", line 70, in error_handler\n",
      "    raise e.with_traceback(filtered_tb) from None\n",
      "  File \"C:\\Users\\marcb\\AppData\\Local\\Temp\\__autograph_generated_filezpu79s1e.py\", line 15, in tf__train_function\n",
      "    retval_ = ag__.converted_call(ag__.ld(step_function), (ag__.ld(self), ag__.ld(iterator)), None, fscope)\n",
      "ValueError: in user code:\n",
      "\n",
      "    File \"E:\\anaconda3\\envs\\segmentation\\lib\\site-packages\\keras\\src\\engine\\training.py\", line 1338, in train_function  *\n",
      "        return step_function(self, iterator)\n",
      "    File \"E:\\anaconda3\\envs\\segmentation\\lib\\site-packages\\keras\\src\\engine\\training.py\", line 1322, in step_function  **\n",
      "        outputs = model.distribute_strategy.run(run_step, args=(data,))\n",
      "    File \"E:\\anaconda3\\envs\\segmentation\\lib\\site-packages\\keras\\src\\engine\\training.py\", line 1303, in run_step  **\n",
      "        outputs = model.train_step(data)\n",
      "    File \"E:\\anaconda3\\envs\\segmentation\\lib\\site-packages\\keras\\src\\engine\\training.py\", line 1080, in train_step\n",
      "        y_pred = self(x, training=True)\n",
      "    File \"E:\\anaconda3\\envs\\segmentation\\lib\\site-packages\\keras\\src\\utils\\traceback_utils.py\", line 70, in error_handler\n",
      "        raise e.with_traceback(filtered_tb) from None\n",
      "    File \"E:\\anaconda3\\envs\\segmentation\\lib\\site-packages\\keras\\src\\engine\\input_spec.py\", line 298, in assert_input_compatibility\n",
      "        raise ValueError(\n",
      "\n",
      "    ValueError: Input 0 of layer \"sequential_5\" is incompatible with the layer: expected shape=(None, 10), found shape=(None, 5)\n",
      "\n",
      "\n",
      "--------------------------------------------------------------------------------\n",
      "1 fits failed with the following error:\n",
      "Traceback (most recent call last):\n",
      "  File \"E:\\anaconda3\\envs\\segmentation\\lib\\site-packages\\sklearn\\model_selection\\_validation.py\", line 729, in _fit_and_score\n",
      "    estimator.fit(X_train, y_train, **fit_params)\n",
      "  File \"E:\\anaconda3\\envs\\segmentation\\lib\\site-packages\\sklearn\\base.py\", line 1152, in wrapper\n",
      "    return fit_method(estimator, *args, **kwargs)\n",
      "  File \"E:\\anaconda3\\envs\\segmentation\\lib\\site-packages\\sklearn\\pipeline.py\", line 427, in fit\n",
      "    self._final_estimator.fit(Xt, y, **fit_params_last_step)\n",
      "  File \"C:\\Users\\marcb\\AppData\\Local\\Temp\\ipykernel_24688\\3521222499.py\", line 27, in fit\n",
      "  File \"E:\\anaconda3\\envs\\segmentation\\lib\\site-packages\\keras\\src\\utils\\traceback_utils.py\", line 70, in error_handler\n",
      "    raise e.with_traceback(filtered_tb) from None\n",
      "  File \"C:\\Users\\marcb\\AppData\\Local\\Temp\\__autograph_generated_filexbnzblmp.py\", line 15, in tf__train_function\n",
      "    retval_ = ag__.converted_call(ag__.ld(step_function), (ag__.ld(self), ag__.ld(iterator)), None, fscope)\n",
      "ValueError: in user code:\n",
      "\n",
      "    File \"E:\\anaconda3\\envs\\segmentation\\lib\\site-packages\\keras\\src\\engine\\training.py\", line 1338, in train_function  *\n",
      "        return step_function(self, iterator)\n",
      "    File \"E:\\anaconda3\\envs\\segmentation\\lib\\site-packages\\keras\\src\\engine\\training.py\", line 1322, in step_function  **\n",
      "        outputs = model.distribute_strategy.run(run_step, args=(data,))\n",
      "    File \"E:\\anaconda3\\envs\\segmentation\\lib\\site-packages\\keras\\src\\engine\\training.py\", line 1303, in run_step  **\n",
      "        outputs = model.train_step(data)\n",
      "    File \"E:\\anaconda3\\envs\\segmentation\\lib\\site-packages\\keras\\src\\engine\\training.py\", line 1080, in train_step\n",
      "        y_pred = self(x, training=True)\n",
      "    File \"E:\\anaconda3\\envs\\segmentation\\lib\\site-packages\\keras\\src\\utils\\traceback_utils.py\", line 70, in error_handler\n",
      "        raise e.with_traceback(filtered_tb) from None\n",
      "    File \"E:\\anaconda3\\envs\\segmentation\\lib\\site-packages\\keras\\src\\engine\\input_spec.py\", line 298, in assert_input_compatibility\n",
      "        raise ValueError(\n",
      "\n",
      "    ValueError: Input 0 of layer \"sequential\" is incompatible with the layer: expected shape=(None, 10), found shape=(16, 5)\n",
      "\n",
      "\n",
      "--------------------------------------------------------------------------------\n",
      "1 fits failed with the following error:\n",
      "Traceback (most recent call last):\n",
      "  File \"E:\\anaconda3\\envs\\segmentation\\lib\\site-packages\\sklearn\\model_selection\\_validation.py\", line 729, in _fit_and_score\n",
      "    estimator.fit(X_train, y_train, **fit_params)\n",
      "  File \"E:\\anaconda3\\envs\\segmentation\\lib\\site-packages\\sklearn\\base.py\", line 1152, in wrapper\n",
      "    return fit_method(estimator, *args, **kwargs)\n",
      "  File \"E:\\anaconda3\\envs\\segmentation\\lib\\site-packages\\sklearn\\pipeline.py\", line 427, in fit\n",
      "    self._final_estimator.fit(Xt, y, **fit_params_last_step)\n",
      "  File \"C:\\Users\\marcb\\AppData\\Local\\Temp\\ipykernel_24688\\3521222499.py\", line 27, in fit\n",
      "  File \"E:\\anaconda3\\envs\\segmentation\\lib\\site-packages\\keras\\src\\utils\\traceback_utils.py\", line 70, in error_handler\n",
      "    raise e.with_traceback(filtered_tb) from None\n",
      "  File \"C:\\Users\\marcb\\AppData\\Local\\Temp\\__autograph_generated_filepjids2ym.py\", line 15, in tf__train_function\n",
      "    retval_ = ag__.converted_call(ag__.ld(step_function), (ag__.ld(self), ag__.ld(iterator)), None, fscope)\n",
      "ValueError: in user code:\n",
      "\n",
      "    File \"E:\\anaconda3\\envs\\segmentation\\lib\\site-packages\\keras\\src\\engine\\training.py\", line 1338, in train_function  *\n",
      "        return step_function(self, iterator)\n",
      "    File \"E:\\anaconda3\\envs\\segmentation\\lib\\site-packages\\keras\\src\\engine\\training.py\", line 1322, in step_function  **\n",
      "        outputs = model.distribute_strategy.run(run_step, args=(data,))\n",
      "    File \"E:\\anaconda3\\envs\\segmentation\\lib\\site-packages\\keras\\src\\engine\\training.py\", line 1303, in run_step  **\n",
      "        outputs = model.train_step(data)\n",
      "    File \"E:\\anaconda3\\envs\\segmentation\\lib\\site-packages\\keras\\src\\engine\\training.py\", line 1080, in train_step\n",
      "        y_pred = self(x, training=True)\n",
      "    File \"E:\\anaconda3\\envs\\segmentation\\lib\\site-packages\\keras\\src\\utils\\traceback_utils.py\", line 70, in error_handler\n",
      "        raise e.with_traceback(filtered_tb) from None\n",
      "    File \"E:\\anaconda3\\envs\\segmentation\\lib\\site-packages\\keras\\src\\engine\\input_spec.py\", line 298, in assert_input_compatibility\n",
      "        raise ValueError(\n",
      "\n",
      "    ValueError: Input 0 of layer \"sequential_6\" is incompatible with the layer: expected shape=(None, 10), found shape=(None, 15)\n",
      "\n",
      "\n",
      "--------------------------------------------------------------------------------\n",
      "1 fits failed with the following error:\n",
      "Traceback (most recent call last):\n",
      "  File \"E:\\anaconda3\\envs\\segmentation\\lib\\site-packages\\sklearn\\model_selection\\_validation.py\", line 729, in _fit_and_score\n",
      "    estimator.fit(X_train, y_train, **fit_params)\n",
      "  File \"E:\\anaconda3\\envs\\segmentation\\lib\\site-packages\\sklearn\\base.py\", line 1152, in wrapper\n",
      "    return fit_method(estimator, *args, **kwargs)\n",
      "  File \"E:\\anaconda3\\envs\\segmentation\\lib\\site-packages\\sklearn\\pipeline.py\", line 427, in fit\n",
      "    self._final_estimator.fit(Xt, y, **fit_params_last_step)\n",
      "  File \"C:\\Users\\marcb\\AppData\\Local\\Temp\\ipykernel_24688\\3521222499.py\", line 27, in fit\n",
      "  File \"E:\\anaconda3\\envs\\segmentation\\lib\\site-packages\\keras\\src\\utils\\traceback_utils.py\", line 70, in error_handler\n",
      "    raise e.with_traceback(filtered_tb) from None\n",
      "  File \"C:\\Users\\marcb\\AppData\\Local\\Temp\\__autograph_generated_file3at0n400.py\", line 15, in tf__train_function\n",
      "    retval_ = ag__.converted_call(ag__.ld(step_function), (ag__.ld(self), ag__.ld(iterator)), None, fscope)\n",
      "ValueError: in user code:\n",
      "\n",
      "    File \"E:\\anaconda3\\envs\\segmentation\\lib\\site-packages\\keras\\src\\engine\\training.py\", line 1338, in train_function  *\n",
      "        return step_function(self, iterator)\n",
      "    File \"E:\\anaconda3\\envs\\segmentation\\lib\\site-packages\\keras\\src\\engine\\training.py\", line 1322, in step_function  **\n",
      "        outputs = model.distribute_strategy.run(run_step, args=(data,))\n",
      "    File \"E:\\anaconda3\\envs\\segmentation\\lib\\site-packages\\keras\\src\\engine\\training.py\", line 1303, in run_step  **\n",
      "        outputs = model.train_step(data)\n",
      "    File \"E:\\anaconda3\\envs\\segmentation\\lib\\site-packages\\keras\\src\\engine\\training.py\", line 1080, in train_step\n",
      "        y_pred = self(x, training=True)\n",
      "    File \"E:\\anaconda3\\envs\\segmentation\\lib\\site-packages\\keras\\src\\utils\\traceback_utils.py\", line 70, in error_handler\n",
      "        raise e.with_traceback(filtered_tb) from None\n",
      "    File \"E:\\anaconda3\\envs\\segmentation\\lib\\site-packages\\keras\\src\\engine\\input_spec.py\", line 298, in assert_input_compatibility\n",
      "        raise ValueError(\n",
      "\n",
      "    ValueError: Input 0 of layer \"sequential_4\" is incompatible with the layer: expected shape=(None, 10), found shape=(None, 15)\n",
      "\n",
      "\n",
      "--------------------------------------------------------------------------------\n",
      "1 fits failed with the following error:\n",
      "Traceback (most recent call last):\n",
      "  File \"E:\\anaconda3\\envs\\segmentation\\lib\\site-packages\\sklearn\\model_selection\\_validation.py\", line 729, in _fit_and_score\n",
      "    estimator.fit(X_train, y_train, **fit_params)\n",
      "  File \"E:\\anaconda3\\envs\\segmentation\\lib\\site-packages\\sklearn\\base.py\", line 1152, in wrapper\n",
      "    return fit_method(estimator, *args, **kwargs)\n",
      "  File \"E:\\anaconda3\\envs\\segmentation\\lib\\site-packages\\sklearn\\pipeline.py\", line 427, in fit\n",
      "    self._final_estimator.fit(Xt, y, **fit_params_last_step)\n",
      "  File \"C:\\Users\\marcb\\AppData\\Local\\Temp\\ipykernel_24688\\3521222499.py\", line 27, in fit\n",
      "  File \"E:\\anaconda3\\envs\\segmentation\\lib\\site-packages\\keras\\src\\utils\\traceback_utils.py\", line 70, in error_handler\n",
      "    raise e.with_traceback(filtered_tb) from None\n",
      "  File \"C:\\Users\\marcb\\AppData\\Local\\Temp\\__autograph_generated_file4_9d3n8b.py\", line 15, in tf__train_function\n",
      "    retval_ = ag__.converted_call(ag__.ld(step_function), (ag__.ld(self), ag__.ld(iterator)), None, fscope)\n",
      "ValueError: in user code:\n",
      "\n",
      "    File \"E:\\anaconda3\\envs\\segmentation\\lib\\site-packages\\keras\\src\\engine\\training.py\", line 1338, in train_function  *\n",
      "        return step_function(self, iterator)\n",
      "    File \"E:\\anaconda3\\envs\\segmentation\\lib\\site-packages\\keras\\src\\engine\\training.py\", line 1322, in step_function  **\n",
      "        outputs = model.distribute_strategy.run(run_step, args=(data,))\n",
      "    File \"E:\\anaconda3\\envs\\segmentation\\lib\\site-packages\\keras\\src\\engine\\training.py\", line 1303, in run_step  **\n",
      "        outputs = model.train_step(data)\n",
      "    File \"E:\\anaconda3\\envs\\segmentation\\lib\\site-packages\\keras\\src\\engine\\training.py\", line 1080, in train_step\n",
      "        y_pred = self(x, training=True)\n",
      "    File \"E:\\anaconda3\\envs\\segmentation\\lib\\site-packages\\keras\\src\\utils\\traceback_utils.py\", line 70, in error_handler\n",
      "        raise e.with_traceback(filtered_tb) from None\n",
      "    File \"E:\\anaconda3\\envs\\segmentation\\lib\\site-packages\\keras\\src\\engine\\input_spec.py\", line 298, in assert_input_compatibility\n",
      "        raise ValueError(\n",
      "\n",
      "    ValueError: Input 0 of layer \"sequential\" is incompatible with the layer: expected shape=(None, 10), found shape=(16, 15)\n",
      "\n",
      "\n",
      "--------------------------------------------------------------------------------\n",
      "1 fits failed with the following error:\n",
      "Traceback (most recent call last):\n",
      "  File \"E:\\anaconda3\\envs\\segmentation\\lib\\site-packages\\sklearn\\model_selection\\_validation.py\", line 729, in _fit_and_score\n",
      "    estimator.fit(X_train, y_train, **fit_params)\n",
      "  File \"E:\\anaconda3\\envs\\segmentation\\lib\\site-packages\\sklearn\\base.py\", line 1152, in wrapper\n",
      "    return fit_method(estimator, *args, **kwargs)\n",
      "  File \"E:\\anaconda3\\envs\\segmentation\\lib\\site-packages\\sklearn\\pipeline.py\", line 427, in fit\n",
      "    self._final_estimator.fit(Xt, y, **fit_params_last_step)\n",
      "  File \"C:\\Users\\marcb\\AppData\\Local\\Temp\\ipykernel_24688\\3521222499.py\", line 27, in fit\n",
      "  File \"E:\\anaconda3\\envs\\segmentation\\lib\\site-packages\\keras\\src\\utils\\traceback_utils.py\", line 70, in error_handler\n",
      "    raise e.with_traceback(filtered_tb) from None\n",
      "  File \"C:\\Users\\marcb\\AppData\\Local\\Temp\\__autograph_generated_filenqsvt53_.py\", line 15, in tf__train_function\n",
      "    retval_ = ag__.converted_call(ag__.ld(step_function), (ag__.ld(self), ag__.ld(iterator)), None, fscope)\n",
      "ValueError: in user code:\n",
      "\n",
      "    File \"E:\\anaconda3\\envs\\segmentation\\lib\\site-packages\\keras\\src\\engine\\training.py\", line 1338, in train_function  *\n",
      "        return step_function(self, iterator)\n",
      "    File \"E:\\anaconda3\\envs\\segmentation\\lib\\site-packages\\keras\\src\\engine\\training.py\", line 1322, in step_function  **\n",
      "        outputs = model.distribute_strategy.run(run_step, args=(data,))\n",
      "    File \"E:\\anaconda3\\envs\\segmentation\\lib\\site-packages\\keras\\src\\engine\\training.py\", line 1303, in run_step  **\n",
      "        outputs = model.train_step(data)\n",
      "    File \"E:\\anaconda3\\envs\\segmentation\\lib\\site-packages\\keras\\src\\engine\\training.py\", line 1080, in train_step\n",
      "        y_pred = self(x, training=True)\n",
      "    File \"E:\\anaconda3\\envs\\segmentation\\lib\\site-packages\\keras\\src\\utils\\traceback_utils.py\", line 70, in error_handler\n",
      "        raise e.with_traceback(filtered_tb) from None\n",
      "    File \"E:\\anaconda3\\envs\\segmentation\\lib\\site-packages\\keras\\src\\engine\\input_spec.py\", line 298, in assert_input_compatibility\n",
      "        raise ValueError(\n",
      "\n",
      "    ValueError: Input 0 of layer \"sequential_5\" is incompatible with the layer: expected shape=(None, 10), found shape=(None, 5)\n",
      "\n",
      "\n",
      "--------------------------------------------------------------------------------\n",
      "1 fits failed with the following error:\n",
      "Traceback (most recent call last):\n",
      "  File \"E:\\anaconda3\\envs\\segmentation\\lib\\site-packages\\sklearn\\model_selection\\_validation.py\", line 729, in _fit_and_score\n",
      "    estimator.fit(X_train, y_train, **fit_params)\n",
      "  File \"E:\\anaconda3\\envs\\segmentation\\lib\\site-packages\\sklearn\\base.py\", line 1152, in wrapper\n",
      "    return fit_method(estimator, *args, **kwargs)\n",
      "  File \"E:\\anaconda3\\envs\\segmentation\\lib\\site-packages\\sklearn\\pipeline.py\", line 427, in fit\n",
      "    self._final_estimator.fit(Xt, y, **fit_params_last_step)\n",
      "  File \"C:\\Users\\marcb\\AppData\\Local\\Temp\\ipykernel_24688\\3521222499.py\", line 27, in fit\n",
      "  File \"E:\\anaconda3\\envs\\segmentation\\lib\\site-packages\\keras\\src\\utils\\traceback_utils.py\", line 70, in error_handler\n",
      "    raise e.with_traceback(filtered_tb) from None\n",
      "  File \"C:\\Users\\marcb\\AppData\\Local\\Temp\\__autograph_generated_fileagyowcpt.py\", line 15, in tf__train_function\n",
      "    retval_ = ag__.converted_call(ag__.ld(step_function), (ag__.ld(self), ag__.ld(iterator)), None, fscope)\n",
      "ValueError: in user code:\n",
      "\n",
      "    File \"E:\\anaconda3\\envs\\segmentation\\lib\\site-packages\\keras\\src\\engine\\training.py\", line 1338, in train_function  *\n",
      "        return step_function(self, iterator)\n",
      "    File \"E:\\anaconda3\\envs\\segmentation\\lib\\site-packages\\keras\\src\\engine\\training.py\", line 1322, in step_function  **\n",
      "        outputs = model.distribute_strategy.run(run_step, args=(data,))\n",
      "    File \"E:\\anaconda3\\envs\\segmentation\\lib\\site-packages\\keras\\src\\engine\\training.py\", line 1303, in run_step  **\n",
      "        outputs = model.train_step(data)\n",
      "    File \"E:\\anaconda3\\envs\\segmentation\\lib\\site-packages\\keras\\src\\engine\\training.py\", line 1080, in train_step\n",
      "        y_pred = self(x, training=True)\n",
      "    File \"E:\\anaconda3\\envs\\segmentation\\lib\\site-packages\\keras\\src\\utils\\traceback_utils.py\", line 70, in error_handler\n",
      "        raise e.with_traceback(filtered_tb) from None\n",
      "    File \"E:\\anaconda3\\envs\\segmentation\\lib\\site-packages\\keras\\src\\engine\\input_spec.py\", line 298, in assert_input_compatibility\n",
      "        raise ValueError(\n",
      "\n",
      "    ValueError: Input 0 of layer \"sequential_4\" is incompatible with the layer: expected shape=(None, 10), found shape=(None, 5)\n",
      "\n",
      "\n",
      "--------------------------------------------------------------------------------\n",
      "1 fits failed with the following error:\n",
      "Traceback (most recent call last):\n",
      "  File \"E:\\anaconda3\\envs\\segmentation\\lib\\site-packages\\sklearn\\model_selection\\_validation.py\", line 729, in _fit_and_score\n",
      "    estimator.fit(X_train, y_train, **fit_params)\n",
      "  File \"E:\\anaconda3\\envs\\segmentation\\lib\\site-packages\\sklearn\\base.py\", line 1152, in wrapper\n",
      "    return fit_method(estimator, *args, **kwargs)\n",
      "  File \"E:\\anaconda3\\envs\\segmentation\\lib\\site-packages\\sklearn\\pipeline.py\", line 427, in fit\n",
      "    self._final_estimator.fit(Xt, y, **fit_params_last_step)\n",
      "  File \"C:\\Users\\marcb\\AppData\\Local\\Temp\\ipykernel_24688\\3521222499.py\", line 27, in fit\n",
      "  File \"E:\\anaconda3\\envs\\segmentation\\lib\\site-packages\\keras\\src\\utils\\traceback_utils.py\", line 70, in error_handler\n",
      "    raise e.with_traceback(filtered_tb) from None\n",
      "  File \"C:\\Users\\marcb\\AppData\\Local\\Temp\\__autograph_generated_filekti7ha7p.py\", line 15, in tf__train_function\n",
      "    retval_ = ag__.converted_call(ag__.ld(step_function), (ag__.ld(self), ag__.ld(iterator)), None, fscope)\n",
      "ValueError: in user code:\n",
      "\n",
      "    File \"E:\\anaconda3\\envs\\segmentation\\lib\\site-packages\\keras\\src\\engine\\training.py\", line 1338, in train_function  *\n",
      "        return step_function(self, iterator)\n",
      "    File \"E:\\anaconda3\\envs\\segmentation\\lib\\site-packages\\keras\\src\\engine\\training.py\", line 1322, in step_function  **\n",
      "        outputs = model.distribute_strategy.run(run_step, args=(data,))\n",
      "    File \"E:\\anaconda3\\envs\\segmentation\\lib\\site-packages\\keras\\src\\engine\\training.py\", line 1303, in run_step  **\n",
      "        outputs = model.train_step(data)\n",
      "    File \"E:\\anaconda3\\envs\\segmentation\\lib\\site-packages\\keras\\src\\engine\\training.py\", line 1080, in train_step\n",
      "        y_pred = self(x, training=True)\n",
      "    File \"E:\\anaconda3\\envs\\segmentation\\lib\\site-packages\\keras\\src\\utils\\traceback_utils.py\", line 70, in error_handler\n",
      "        raise e.with_traceback(filtered_tb) from None\n",
      "    File \"E:\\anaconda3\\envs\\segmentation\\lib\\site-packages\\keras\\src\\engine\\input_spec.py\", line 298, in assert_input_compatibility\n",
      "        raise ValueError(\n",
      "\n",
      "    ValueError: Input 0 of layer \"sequential\" is incompatible with the layer: expected shape=(None, 10), found shape=(16, 5)\n",
      "\n",
      "\n",
      "--------------------------------------------------------------------------------\n",
      "1 fits failed with the following error:\n",
      "Traceback (most recent call last):\n",
      "  File \"E:\\anaconda3\\envs\\segmentation\\lib\\site-packages\\sklearn\\model_selection\\_validation.py\", line 729, in _fit_and_score\n",
      "    estimator.fit(X_train, y_train, **fit_params)\n",
      "  File \"E:\\anaconda3\\envs\\segmentation\\lib\\site-packages\\sklearn\\base.py\", line 1152, in wrapper\n",
      "    return fit_method(estimator, *args, **kwargs)\n",
      "  File \"E:\\anaconda3\\envs\\segmentation\\lib\\site-packages\\sklearn\\pipeline.py\", line 427, in fit\n",
      "    self._final_estimator.fit(Xt, y, **fit_params_last_step)\n",
      "  File \"C:\\Users\\marcb\\AppData\\Local\\Temp\\ipykernel_24688\\3521222499.py\", line 27, in fit\n",
      "  File \"E:\\anaconda3\\envs\\segmentation\\lib\\site-packages\\keras\\src\\utils\\traceback_utils.py\", line 70, in error_handler\n",
      "    raise e.with_traceback(filtered_tb) from None\n",
      "  File \"C:\\Users\\marcb\\AppData\\Local\\Temp\\__autograph_generated_fileibodyggy.py\", line 15, in tf__train_function\n",
      "    retval_ = ag__.converted_call(ag__.ld(step_function), (ag__.ld(self), ag__.ld(iterator)), None, fscope)\n",
      "ValueError: in user code:\n",
      "\n",
      "    File \"E:\\anaconda3\\envs\\segmentation\\lib\\site-packages\\keras\\src\\engine\\training.py\", line 1338, in train_function  *\n",
      "        return step_function(self, iterator)\n",
      "    File \"E:\\anaconda3\\envs\\segmentation\\lib\\site-packages\\keras\\src\\engine\\training.py\", line 1322, in step_function  **\n",
      "        outputs = model.distribute_strategy.run(run_step, args=(data,))\n",
      "    File \"E:\\anaconda3\\envs\\segmentation\\lib\\site-packages\\keras\\src\\engine\\training.py\", line 1303, in run_step  **\n",
      "        outputs = model.train_step(data)\n",
      "    File \"E:\\anaconda3\\envs\\segmentation\\lib\\site-packages\\keras\\src\\engine\\training.py\", line 1080, in train_step\n",
      "        y_pred = self(x, training=True)\n",
      "    File \"E:\\anaconda3\\envs\\segmentation\\lib\\site-packages\\keras\\src\\utils\\traceback_utils.py\", line 70, in error_handler\n",
      "        raise e.with_traceback(filtered_tb) from None\n",
      "    File \"E:\\anaconda3\\envs\\segmentation\\lib\\site-packages\\keras\\src\\engine\\input_spec.py\", line 298, in assert_input_compatibility\n",
      "        raise ValueError(\n",
      "\n",
      "    ValueError: Input 0 of layer \"sequential_5\" is incompatible with the layer: expected shape=(None, 10), found shape=(None, 15)\n",
      "\n",
      "\n",
      "--------------------------------------------------------------------------------\n",
      "1 fits failed with the following error:\n",
      "Traceback (most recent call last):\n",
      "  File \"E:\\anaconda3\\envs\\segmentation\\lib\\site-packages\\sklearn\\model_selection\\_validation.py\", line 729, in _fit_and_score\n",
      "    estimator.fit(X_train, y_train, **fit_params)\n",
      "  File \"E:\\anaconda3\\envs\\segmentation\\lib\\site-packages\\sklearn\\base.py\", line 1152, in wrapper\n",
      "    return fit_method(estimator, *args, **kwargs)\n",
      "  File \"E:\\anaconda3\\envs\\segmentation\\lib\\site-packages\\sklearn\\pipeline.py\", line 427, in fit\n",
      "    self._final_estimator.fit(Xt, y, **fit_params_last_step)\n",
      "  File \"C:\\Users\\marcb\\AppData\\Local\\Temp\\ipykernel_24688\\3521222499.py\", line 27, in fit\n",
      "  File \"E:\\anaconda3\\envs\\segmentation\\lib\\site-packages\\keras\\src\\utils\\traceback_utils.py\", line 70, in error_handler\n",
      "    raise e.with_traceback(filtered_tb) from None\n",
      "  File \"C:\\Users\\marcb\\AppData\\Local\\Temp\\__autograph_generated_file2t1qo1jp.py\", line 15, in tf__train_function\n",
      "    retval_ = ag__.converted_call(ag__.ld(step_function), (ag__.ld(self), ag__.ld(iterator)), None, fscope)\n",
      "ValueError: in user code:\n",
      "\n",
      "    File \"E:\\anaconda3\\envs\\segmentation\\lib\\site-packages\\keras\\src\\engine\\training.py\", line 1338, in train_function  *\n",
      "        return step_function(self, iterator)\n",
      "    File \"E:\\anaconda3\\envs\\segmentation\\lib\\site-packages\\keras\\src\\engine\\training.py\", line 1322, in step_function  **\n",
      "        outputs = model.distribute_strategy.run(run_step, args=(data,))\n",
      "    File \"E:\\anaconda3\\envs\\segmentation\\lib\\site-packages\\keras\\src\\engine\\training.py\", line 1303, in run_step  **\n",
      "        outputs = model.train_step(data)\n",
      "    File \"E:\\anaconda3\\envs\\segmentation\\lib\\site-packages\\keras\\src\\engine\\training.py\", line 1080, in train_step\n",
      "        y_pred = self(x, training=True)\n",
      "    File \"E:\\anaconda3\\envs\\segmentation\\lib\\site-packages\\keras\\src\\utils\\traceback_utils.py\", line 70, in error_handler\n",
      "        raise e.with_traceback(filtered_tb) from None\n",
      "    File \"E:\\anaconda3\\envs\\segmentation\\lib\\site-packages\\keras\\src\\engine\\input_spec.py\", line 298, in assert_input_compatibility\n",
      "        raise ValueError(\n",
      "\n",
      "    ValueError: Input 0 of layer \"sequential_5\" is incompatible with the layer: expected shape=(None, 10), found shape=(None, 15)\n",
      "\n",
      "\n",
      "--------------------------------------------------------------------------------\n",
      "1 fits failed with the following error:\n",
      "Traceback (most recent call last):\n",
      "  File \"E:\\anaconda3\\envs\\segmentation\\lib\\site-packages\\sklearn\\model_selection\\_validation.py\", line 729, in _fit_and_score\n",
      "    estimator.fit(X_train, y_train, **fit_params)\n",
      "  File \"E:\\anaconda3\\envs\\segmentation\\lib\\site-packages\\sklearn\\base.py\", line 1152, in wrapper\n",
      "    return fit_method(estimator, *args, **kwargs)\n",
      "  File \"E:\\anaconda3\\envs\\segmentation\\lib\\site-packages\\sklearn\\pipeline.py\", line 427, in fit\n",
      "    self._final_estimator.fit(Xt, y, **fit_params_last_step)\n",
      "  File \"C:\\Users\\marcb\\AppData\\Local\\Temp\\ipykernel_24688\\3521222499.py\", line 27, in fit\n",
      "  File \"E:\\anaconda3\\envs\\segmentation\\lib\\site-packages\\keras\\src\\utils\\traceback_utils.py\", line 70, in error_handler\n",
      "    raise e.with_traceback(filtered_tb) from None\n",
      "  File \"C:\\Users\\marcb\\AppData\\Local\\Temp\\__autograph_generated_fileq3oub6wn.py\", line 15, in tf__train_function\n",
      "    retval_ = ag__.converted_call(ag__.ld(step_function), (ag__.ld(self), ag__.ld(iterator)), None, fscope)\n",
      "ValueError: in user code:\n",
      "\n",
      "    File \"E:\\anaconda3\\envs\\segmentation\\lib\\site-packages\\keras\\src\\engine\\training.py\", line 1338, in train_function  *\n",
      "        return step_function(self, iterator)\n",
      "    File \"E:\\anaconda3\\envs\\segmentation\\lib\\site-packages\\keras\\src\\engine\\training.py\", line 1322, in step_function  **\n",
      "        outputs = model.distribute_strategy.run(run_step, args=(data,))\n",
      "    File \"E:\\anaconda3\\envs\\segmentation\\lib\\site-packages\\keras\\src\\engine\\training.py\", line 1303, in run_step  **\n",
      "        outputs = model.train_step(data)\n",
      "    File \"E:\\anaconda3\\envs\\segmentation\\lib\\site-packages\\keras\\src\\engine\\training.py\", line 1080, in train_step\n",
      "        y_pred = self(x, training=True)\n",
      "    File \"E:\\anaconda3\\envs\\segmentation\\lib\\site-packages\\keras\\src\\utils\\traceback_utils.py\", line 70, in error_handler\n",
      "        raise e.with_traceback(filtered_tb) from None\n",
      "    File \"E:\\anaconda3\\envs\\segmentation\\lib\\site-packages\\keras\\src\\engine\\input_spec.py\", line 298, in assert_input_compatibility\n",
      "        raise ValueError(\n",
      "\n",
      "    ValueError: Input 0 of layer \"sequential_5\" is incompatible with the layer: expected shape=(None, 10), found shape=(16, 15)\n",
      "\n",
      "\n",
      "--------------------------------------------------------------------------------\n",
      "1 fits failed with the following error:\n",
      "Traceback (most recent call last):\n",
      "  File \"E:\\anaconda3\\envs\\segmentation\\lib\\site-packages\\sklearn\\model_selection\\_validation.py\", line 729, in _fit_and_score\n",
      "    estimator.fit(X_train, y_train, **fit_params)\n",
      "  File \"E:\\anaconda3\\envs\\segmentation\\lib\\site-packages\\sklearn\\base.py\", line 1152, in wrapper\n",
      "    return fit_method(estimator, *args, **kwargs)\n",
      "  File \"E:\\anaconda3\\envs\\segmentation\\lib\\site-packages\\sklearn\\pipeline.py\", line 427, in fit\n",
      "    self._final_estimator.fit(Xt, y, **fit_params_last_step)\n",
      "  File \"C:\\Users\\marcb\\AppData\\Local\\Temp\\ipykernel_24688\\3521222499.py\", line 27, in fit\n",
      "  File \"E:\\anaconda3\\envs\\segmentation\\lib\\site-packages\\keras\\src\\utils\\traceback_utils.py\", line 70, in error_handler\n",
      "    raise e.with_traceback(filtered_tb) from None\n",
      "  File \"C:\\Users\\marcb\\AppData\\Local\\Temp\\__autograph_generated_file7txwl163.py\", line 15, in tf__train_function\n",
      "    retval_ = ag__.converted_call(ag__.ld(step_function), (ag__.ld(self), ag__.ld(iterator)), None, fscope)\n",
      "ValueError: in user code:\n",
      "\n",
      "    File \"E:\\anaconda3\\envs\\segmentation\\lib\\site-packages\\keras\\src\\engine\\training.py\", line 1338, in train_function  *\n",
      "        return step_function(self, iterator)\n",
      "    File \"E:\\anaconda3\\envs\\segmentation\\lib\\site-packages\\keras\\src\\engine\\training.py\", line 1322, in step_function  **\n",
      "        outputs = model.distribute_strategy.run(run_step, args=(data,))\n",
      "    File \"E:\\anaconda3\\envs\\segmentation\\lib\\site-packages\\keras\\src\\engine\\training.py\", line 1303, in run_step  **\n",
      "        outputs = model.train_step(data)\n",
      "    File \"E:\\anaconda3\\envs\\segmentation\\lib\\site-packages\\keras\\src\\engine\\training.py\", line 1080, in train_step\n",
      "        y_pred = self(x, training=True)\n",
      "    File \"E:\\anaconda3\\envs\\segmentation\\lib\\site-packages\\keras\\src\\utils\\traceback_utils.py\", line 70, in error_handler\n",
      "        raise e.with_traceback(filtered_tb) from None\n",
      "    File \"E:\\anaconda3\\envs\\segmentation\\lib\\site-packages\\keras\\src\\engine\\input_spec.py\", line 298, in assert_input_compatibility\n",
      "        raise ValueError(\n",
      "\n",
      "    ValueError: Input 0 of layer \"sequential_5\" is incompatible with the layer: expected shape=(None, 10), found shape=(None, 5)\n",
      "\n",
      "\n",
      "--------------------------------------------------------------------------------\n",
      "1 fits failed with the following error:\n",
      "Traceback (most recent call last):\n",
      "  File \"E:\\anaconda3\\envs\\segmentation\\lib\\site-packages\\sklearn\\model_selection\\_validation.py\", line 729, in _fit_and_score\n",
      "    estimator.fit(X_train, y_train, **fit_params)\n",
      "  File \"E:\\anaconda3\\envs\\segmentation\\lib\\site-packages\\sklearn\\base.py\", line 1152, in wrapper\n",
      "    return fit_method(estimator, *args, **kwargs)\n",
      "  File \"E:\\anaconda3\\envs\\segmentation\\lib\\site-packages\\sklearn\\pipeline.py\", line 427, in fit\n",
      "    self._final_estimator.fit(Xt, y, **fit_params_last_step)\n",
      "  File \"C:\\Users\\marcb\\AppData\\Local\\Temp\\ipykernel_24688\\3521222499.py\", line 27, in fit\n",
      "  File \"E:\\anaconda3\\envs\\segmentation\\lib\\site-packages\\keras\\src\\utils\\traceback_utils.py\", line 70, in error_handler\n",
      "    raise e.with_traceback(filtered_tb) from None\n",
      "  File \"C:\\Users\\marcb\\AppData\\Local\\Temp\\__autograph_generated_fileq_dwuwll.py\", line 15, in tf__train_function\n",
      "    retval_ = ag__.converted_call(ag__.ld(step_function), (ag__.ld(self), ag__.ld(iterator)), None, fscope)\n",
      "ValueError: in user code:\n",
      "\n",
      "    File \"E:\\anaconda3\\envs\\segmentation\\lib\\site-packages\\keras\\src\\engine\\training.py\", line 1338, in train_function  *\n",
      "        return step_function(self, iterator)\n",
      "    File \"E:\\anaconda3\\envs\\segmentation\\lib\\site-packages\\keras\\src\\engine\\training.py\", line 1322, in step_function  **\n",
      "        outputs = model.distribute_strategy.run(run_step, args=(data,))\n",
      "    File \"E:\\anaconda3\\envs\\segmentation\\lib\\site-packages\\keras\\src\\engine\\training.py\", line 1303, in run_step  **\n",
      "        outputs = model.train_step(data)\n",
      "    File \"E:\\anaconda3\\envs\\segmentation\\lib\\site-packages\\keras\\src\\engine\\training.py\", line 1080, in train_step\n",
      "        y_pred = self(x, training=True)\n",
      "    File \"E:\\anaconda3\\envs\\segmentation\\lib\\site-packages\\keras\\src\\utils\\traceback_utils.py\", line 70, in error_handler\n",
      "        raise e.with_traceback(filtered_tb) from None\n",
      "    File \"E:\\anaconda3\\envs\\segmentation\\lib\\site-packages\\keras\\src\\engine\\input_spec.py\", line 298, in assert_input_compatibility\n",
      "        raise ValueError(\n",
      "\n",
      "    ValueError: Input 0 of layer \"sequential_5\" is incompatible with the layer: expected shape=(None, 10), found shape=(None, 5)\n",
      "\n",
      "\n",
      "--------------------------------------------------------------------------------\n",
      "1 fits failed with the following error:\n",
      "Traceback (most recent call last):\n",
      "  File \"E:\\anaconda3\\envs\\segmentation\\lib\\site-packages\\sklearn\\model_selection\\_validation.py\", line 729, in _fit_and_score\n",
      "    estimator.fit(X_train, y_train, **fit_params)\n",
      "  File \"E:\\anaconda3\\envs\\segmentation\\lib\\site-packages\\sklearn\\base.py\", line 1152, in wrapper\n",
      "    return fit_method(estimator, *args, **kwargs)\n",
      "  File \"E:\\anaconda3\\envs\\segmentation\\lib\\site-packages\\sklearn\\pipeline.py\", line 427, in fit\n",
      "    self._final_estimator.fit(Xt, y, **fit_params_last_step)\n",
      "  File \"C:\\Users\\marcb\\AppData\\Local\\Temp\\ipykernel_24688\\3521222499.py\", line 27, in fit\n",
      "  File \"E:\\anaconda3\\envs\\segmentation\\lib\\site-packages\\keras\\src\\utils\\traceback_utils.py\", line 70, in error_handler\n",
      "    raise e.with_traceback(filtered_tb) from None\n",
      "  File \"C:\\Users\\marcb\\AppData\\Local\\Temp\\__autograph_generated_filepjids2ym.py\", line 15, in tf__train_function\n",
      "    retval_ = ag__.converted_call(ag__.ld(step_function), (ag__.ld(self), ag__.ld(iterator)), None, fscope)\n",
      "ValueError: in user code:\n",
      "\n",
      "    File \"E:\\anaconda3\\envs\\segmentation\\lib\\site-packages\\keras\\src\\engine\\training.py\", line 1338, in train_function  *\n",
      "        return step_function(self, iterator)\n",
      "    File \"E:\\anaconda3\\envs\\segmentation\\lib\\site-packages\\keras\\src\\engine\\training.py\", line 1322, in step_function  **\n",
      "        outputs = model.distribute_strategy.run(run_step, args=(data,))\n",
      "    File \"E:\\anaconda3\\envs\\segmentation\\lib\\site-packages\\keras\\src\\engine\\training.py\", line 1303, in run_step  **\n",
      "        outputs = model.train_step(data)\n",
      "    File \"E:\\anaconda3\\envs\\segmentation\\lib\\site-packages\\keras\\src\\engine\\training.py\", line 1080, in train_step\n",
      "        y_pred = self(x, training=True)\n",
      "    File \"E:\\anaconda3\\envs\\segmentation\\lib\\site-packages\\keras\\src\\utils\\traceback_utils.py\", line 70, in error_handler\n",
      "        raise e.with_traceback(filtered_tb) from None\n",
      "    File \"E:\\anaconda3\\envs\\segmentation\\lib\\site-packages\\keras\\src\\engine\\input_spec.py\", line 298, in assert_input_compatibility\n",
      "        raise ValueError(\n",
      "\n",
      "    ValueError: Input 0 of layer \"sequential_7\" is incompatible with the layer: expected shape=(None, 10), found shape=(None, 5)\n",
      "\n",
      "\n",
      "--------------------------------------------------------------------------------\n",
      "1 fits failed with the following error:\n",
      "Traceback (most recent call last):\n",
      "  File \"E:\\anaconda3\\envs\\segmentation\\lib\\site-packages\\sklearn\\model_selection\\_validation.py\", line 729, in _fit_and_score\n",
      "    estimator.fit(X_train, y_train, **fit_params)\n",
      "  File \"E:\\anaconda3\\envs\\segmentation\\lib\\site-packages\\sklearn\\base.py\", line 1152, in wrapper\n",
      "    return fit_method(estimator, *args, **kwargs)\n",
      "  File \"E:\\anaconda3\\envs\\segmentation\\lib\\site-packages\\sklearn\\pipeline.py\", line 427, in fit\n",
      "    self._final_estimator.fit(Xt, y, **fit_params_last_step)\n",
      "  File \"C:\\Users\\marcb\\AppData\\Local\\Temp\\ipykernel_24688\\3521222499.py\", line 27, in fit\n",
      "  File \"E:\\anaconda3\\envs\\segmentation\\lib\\site-packages\\keras\\src\\utils\\traceback_utils.py\", line 70, in error_handler\n",
      "    raise e.with_traceback(filtered_tb) from None\n",
      "  File \"C:\\Users\\marcb\\AppData\\Local\\Temp\\__autograph_generated_fileq_dwuwll.py\", line 15, in tf__train_function\n",
      "    retval_ = ag__.converted_call(ag__.ld(step_function), (ag__.ld(self), ag__.ld(iterator)), None, fscope)\n",
      "ValueError: in user code:\n",
      "\n",
      "    File \"E:\\anaconda3\\envs\\segmentation\\lib\\site-packages\\keras\\src\\engine\\training.py\", line 1338, in train_function  *\n",
      "        return step_function(self, iterator)\n",
      "    File \"E:\\anaconda3\\envs\\segmentation\\lib\\site-packages\\keras\\src\\engine\\training.py\", line 1322, in step_function  **\n",
      "        outputs = model.distribute_strategy.run(run_step, args=(data,))\n",
      "    File \"E:\\anaconda3\\envs\\segmentation\\lib\\site-packages\\keras\\src\\engine\\training.py\", line 1303, in run_step  **\n",
      "        outputs = model.train_step(data)\n",
      "    File \"E:\\anaconda3\\envs\\segmentation\\lib\\site-packages\\keras\\src\\engine\\training.py\", line 1080, in train_step\n",
      "        y_pred = self(x, training=True)\n",
      "    File \"E:\\anaconda3\\envs\\segmentation\\lib\\site-packages\\keras\\src\\utils\\traceback_utils.py\", line 70, in error_handler\n",
      "        raise e.with_traceback(filtered_tb) from None\n",
      "    File \"E:\\anaconda3\\envs\\segmentation\\lib\\site-packages\\keras\\src\\engine\\input_spec.py\", line 298, in assert_input_compatibility\n",
      "        raise ValueError(\n",
      "\n",
      "    ValueError: Input 0 of layer \"sequential_6\" is incompatible with the layer: expected shape=(None, 10), found shape=(None, 15)\n",
      "\n",
      "\n",
      "--------------------------------------------------------------------------------\n",
      "1 fits failed with the following error:\n",
      "Traceback (most recent call last):\n",
      "  File \"E:\\anaconda3\\envs\\segmentation\\lib\\site-packages\\sklearn\\model_selection\\_validation.py\", line 729, in _fit_and_score\n",
      "    estimator.fit(X_train, y_train, **fit_params)\n",
      "  File \"E:\\anaconda3\\envs\\segmentation\\lib\\site-packages\\sklearn\\base.py\", line 1152, in wrapper\n",
      "    return fit_method(estimator, *args, **kwargs)\n",
      "  File \"E:\\anaconda3\\envs\\segmentation\\lib\\site-packages\\sklearn\\pipeline.py\", line 427, in fit\n",
      "    self._final_estimator.fit(Xt, y, **fit_params_last_step)\n",
      "  File \"C:\\Users\\marcb\\AppData\\Local\\Temp\\ipykernel_24688\\3521222499.py\", line 27, in fit\n",
      "  File \"E:\\anaconda3\\envs\\segmentation\\lib\\site-packages\\keras\\src\\utils\\traceback_utils.py\", line 70, in error_handler\n",
      "    raise e.with_traceback(filtered_tb) from None\n",
      "  File \"C:\\Users\\marcb\\AppData\\Local\\Temp\\__autograph_generated_filenqsvt53_.py\", line 15, in tf__train_function\n",
      "    retval_ = ag__.converted_call(ag__.ld(step_function), (ag__.ld(self), ag__.ld(iterator)), None, fscope)\n",
      "ValueError: in user code:\n",
      "\n",
      "    File \"E:\\anaconda3\\envs\\segmentation\\lib\\site-packages\\keras\\src\\engine\\training.py\", line 1338, in train_function  *\n",
      "        return step_function(self, iterator)\n",
      "    File \"E:\\anaconda3\\envs\\segmentation\\lib\\site-packages\\keras\\src\\engine\\training.py\", line 1322, in step_function  **\n",
      "        outputs = model.distribute_strategy.run(run_step, args=(data,))\n",
      "    File \"E:\\anaconda3\\envs\\segmentation\\lib\\site-packages\\keras\\src\\engine\\training.py\", line 1303, in run_step  **\n",
      "        outputs = model.train_step(data)\n",
      "    File \"E:\\anaconda3\\envs\\segmentation\\lib\\site-packages\\keras\\src\\engine\\training.py\", line 1080, in train_step\n",
      "        y_pred = self(x, training=True)\n",
      "    File \"E:\\anaconda3\\envs\\segmentation\\lib\\site-packages\\keras\\src\\utils\\traceback_utils.py\", line 70, in error_handler\n",
      "        raise e.with_traceback(filtered_tb) from None\n",
      "    File \"E:\\anaconda3\\envs\\segmentation\\lib\\site-packages\\keras\\src\\engine\\input_spec.py\", line 298, in assert_input_compatibility\n",
      "        raise ValueError(\n",
      "\n",
      "    ValueError: Input 0 of layer \"sequential_6\" is incompatible with the layer: expected shape=(None, 10), found shape=(None, 15)\n",
      "\n",
      "\n",
      "--------------------------------------------------------------------------------\n",
      "1 fits failed with the following error:\n",
      "Traceback (most recent call last):\n",
      "  File \"E:\\anaconda3\\envs\\segmentation\\lib\\site-packages\\sklearn\\model_selection\\_validation.py\", line 729, in _fit_and_score\n",
      "    estimator.fit(X_train, y_train, **fit_params)\n",
      "  File \"E:\\anaconda3\\envs\\segmentation\\lib\\site-packages\\sklearn\\base.py\", line 1152, in wrapper\n",
      "    return fit_method(estimator, *args, **kwargs)\n",
      "  File \"E:\\anaconda3\\envs\\segmentation\\lib\\site-packages\\sklearn\\pipeline.py\", line 427, in fit\n",
      "    self._final_estimator.fit(Xt, y, **fit_params_last_step)\n",
      "  File \"C:\\Users\\marcb\\AppData\\Local\\Temp\\ipykernel_24688\\3521222499.py\", line 27, in fit\n",
      "  File \"E:\\anaconda3\\envs\\segmentation\\lib\\site-packages\\keras\\src\\utils\\traceback_utils.py\", line 70, in error_handler\n",
      "    raise e.with_traceback(filtered_tb) from None\n",
      "  File \"C:\\Users\\marcb\\AppData\\Local\\Temp\\__autograph_generated_file2t1qo1jp.py\", line 15, in tf__train_function\n",
      "    retval_ = ag__.converted_call(ag__.ld(step_function), (ag__.ld(self), ag__.ld(iterator)), None, fscope)\n",
      "ValueError: in user code:\n",
      "\n",
      "    File \"E:\\anaconda3\\envs\\segmentation\\lib\\site-packages\\keras\\src\\engine\\training.py\", line 1338, in train_function  *\n",
      "        return step_function(self, iterator)\n",
      "    File \"E:\\anaconda3\\envs\\segmentation\\lib\\site-packages\\keras\\src\\engine\\training.py\", line 1322, in step_function  **\n",
      "        outputs = model.distribute_strategy.run(run_step, args=(data,))\n",
      "    File \"E:\\anaconda3\\envs\\segmentation\\lib\\site-packages\\keras\\src\\engine\\training.py\", line 1303, in run_step  **\n",
      "        outputs = model.train_step(data)\n",
      "    File \"E:\\anaconda3\\envs\\segmentation\\lib\\site-packages\\keras\\src\\engine\\training.py\", line 1080, in train_step\n",
      "        y_pred = self(x, training=True)\n",
      "    File \"E:\\anaconda3\\envs\\segmentation\\lib\\site-packages\\keras\\src\\utils\\traceback_utils.py\", line 70, in error_handler\n",
      "        raise e.with_traceback(filtered_tb) from None\n",
      "    File \"E:\\anaconda3\\envs\\segmentation\\lib\\site-packages\\keras\\src\\engine\\input_spec.py\", line 298, in assert_input_compatibility\n",
      "        raise ValueError(\n",
      "\n",
      "    ValueError: Input 0 of layer \"sequential_6\" is incompatible with the layer: expected shape=(None, 10), found shape=(None, 15)\n",
      "\n",
      "\n",
      "--------------------------------------------------------------------------------\n",
      "1 fits failed with the following error:\n",
      "Traceback (most recent call last):\n",
      "  File \"E:\\anaconda3\\envs\\segmentation\\lib\\site-packages\\sklearn\\model_selection\\_validation.py\", line 729, in _fit_and_score\n",
      "    estimator.fit(X_train, y_train, **fit_params)\n",
      "  File \"E:\\anaconda3\\envs\\segmentation\\lib\\site-packages\\sklearn\\base.py\", line 1152, in wrapper\n",
      "    return fit_method(estimator, *args, **kwargs)\n",
      "  File \"E:\\anaconda3\\envs\\segmentation\\lib\\site-packages\\sklearn\\pipeline.py\", line 427, in fit\n",
      "    self._final_estimator.fit(Xt, y, **fit_params_last_step)\n",
      "  File \"C:\\Users\\marcb\\AppData\\Local\\Temp\\ipykernel_24688\\3521222499.py\", line 27, in fit\n",
      "  File \"E:\\anaconda3\\envs\\segmentation\\lib\\site-packages\\keras\\src\\utils\\traceback_utils.py\", line 70, in error_handler\n",
      "    raise e.with_traceback(filtered_tb) from None\n",
      "  File \"C:\\Users\\marcb\\AppData\\Local\\Temp\\__autograph_generated_fileglr5i53b.py\", line 15, in tf__train_function\n",
      "    retval_ = ag__.converted_call(ag__.ld(step_function), (ag__.ld(self), ag__.ld(iterator)), None, fscope)\n",
      "ValueError: in user code:\n",
      "\n",
      "    File \"E:\\anaconda3\\envs\\segmentation\\lib\\site-packages\\keras\\src\\engine\\training.py\", line 1338, in train_function  *\n",
      "        return step_function(self, iterator)\n",
      "    File \"E:\\anaconda3\\envs\\segmentation\\lib\\site-packages\\keras\\src\\engine\\training.py\", line 1322, in step_function  **\n",
      "        outputs = model.distribute_strategy.run(run_step, args=(data,))\n",
      "    File \"E:\\anaconda3\\envs\\segmentation\\lib\\site-packages\\keras\\src\\engine\\training.py\", line 1303, in run_step  **\n",
      "        outputs = model.train_step(data)\n",
      "    File \"E:\\anaconda3\\envs\\segmentation\\lib\\site-packages\\keras\\src\\engine\\training.py\", line 1080, in train_step\n",
      "        y_pred = self(x, training=True)\n",
      "    File \"E:\\anaconda3\\envs\\segmentation\\lib\\site-packages\\keras\\src\\utils\\traceback_utils.py\", line 70, in error_handler\n",
      "        raise e.with_traceback(filtered_tb) from None\n",
      "    File \"E:\\anaconda3\\envs\\segmentation\\lib\\site-packages\\keras\\src\\engine\\input_spec.py\", line 298, in assert_input_compatibility\n",
      "        raise ValueError(\n",
      "\n",
      "    ValueError: Input 0 of layer \"sequential_6\" is incompatible with the layer: expected shape=(None, 10), found shape=(None, 5)\n",
      "\n",
      "\n",
      "--------------------------------------------------------------------------------\n",
      "1 fits failed with the following error:\n",
      "Traceback (most recent call last):\n",
      "  File \"E:\\anaconda3\\envs\\segmentation\\lib\\site-packages\\sklearn\\model_selection\\_validation.py\", line 729, in _fit_and_score\n",
      "    estimator.fit(X_train, y_train, **fit_params)\n",
      "  File \"E:\\anaconda3\\envs\\segmentation\\lib\\site-packages\\sklearn\\base.py\", line 1152, in wrapper\n",
      "    return fit_method(estimator, *args, **kwargs)\n",
      "  File \"E:\\anaconda3\\envs\\segmentation\\lib\\site-packages\\sklearn\\pipeline.py\", line 427, in fit\n",
      "    self._final_estimator.fit(Xt, y, **fit_params_last_step)\n",
      "  File \"C:\\Users\\marcb\\AppData\\Local\\Temp\\ipykernel_24688\\3521222499.py\", line 27, in fit\n",
      "  File \"E:\\anaconda3\\envs\\segmentation\\lib\\site-packages\\keras\\src\\utils\\traceback_utils.py\", line 70, in error_handler\n",
      "    raise e.with_traceback(filtered_tb) from None\n",
      "  File \"C:\\Users\\marcb\\AppData\\Local\\Temp\\__autograph_generated_file3at0n400.py\", line 15, in tf__train_function\n",
      "    retval_ = ag__.converted_call(ag__.ld(step_function), (ag__.ld(self), ag__.ld(iterator)), None, fscope)\n",
      "ValueError: in user code:\n",
      "\n",
      "    File \"E:\\anaconda3\\envs\\segmentation\\lib\\site-packages\\keras\\src\\engine\\training.py\", line 1338, in train_function  *\n",
      "        return step_function(self, iterator)\n",
      "    File \"E:\\anaconda3\\envs\\segmentation\\lib\\site-packages\\keras\\src\\engine\\training.py\", line 1322, in step_function  **\n",
      "        outputs = model.distribute_strategy.run(run_step, args=(data,))\n",
      "    File \"E:\\anaconda3\\envs\\segmentation\\lib\\site-packages\\keras\\src\\engine\\training.py\", line 1303, in run_step  **\n",
      "        outputs = model.train_step(data)\n",
      "    File \"E:\\anaconda3\\envs\\segmentation\\lib\\site-packages\\keras\\src\\engine\\training.py\", line 1080, in train_step\n",
      "        y_pred = self(x, training=True)\n",
      "    File \"E:\\anaconda3\\envs\\segmentation\\lib\\site-packages\\keras\\src\\utils\\traceback_utils.py\", line 70, in error_handler\n",
      "        raise e.with_traceback(filtered_tb) from None\n",
      "    File \"E:\\anaconda3\\envs\\segmentation\\lib\\site-packages\\keras\\src\\engine\\input_spec.py\", line 298, in assert_input_compatibility\n",
      "        raise ValueError(\n",
      "\n",
      "    ValueError: Input 0 of layer \"sequential_5\" is incompatible with the layer: expected shape=(None, 10), found shape=(None, 5)\n",
      "\n",
      "\n",
      "--------------------------------------------------------------------------------\n",
      "1 fits failed with the following error:\n",
      "Traceback (most recent call last):\n",
      "  File \"E:\\anaconda3\\envs\\segmentation\\lib\\site-packages\\sklearn\\model_selection\\_validation.py\", line 729, in _fit_and_score\n",
      "    estimator.fit(X_train, y_train, **fit_params)\n",
      "  File \"E:\\anaconda3\\envs\\segmentation\\lib\\site-packages\\sklearn\\base.py\", line 1152, in wrapper\n",
      "    return fit_method(estimator, *args, **kwargs)\n",
      "  File \"E:\\anaconda3\\envs\\segmentation\\lib\\site-packages\\sklearn\\pipeline.py\", line 427, in fit\n",
      "    self._final_estimator.fit(Xt, y, **fit_params_last_step)\n",
      "  File \"C:\\Users\\marcb\\AppData\\Local\\Temp\\ipykernel_24688\\3521222499.py\", line 27, in fit\n",
      "  File \"E:\\anaconda3\\envs\\segmentation\\lib\\site-packages\\keras\\src\\utils\\traceback_utils.py\", line 70, in error_handler\n",
      "    raise e.with_traceback(filtered_tb) from None\n",
      "  File \"C:\\Users\\marcb\\AppData\\Local\\Temp\\__autograph_generated_file7txwl163.py\", line 15, in tf__train_function\n",
      "    retval_ = ag__.converted_call(ag__.ld(step_function), (ag__.ld(self), ag__.ld(iterator)), None, fscope)\n",
      "ValueError: in user code:\n",
      "\n",
      "    File \"E:\\anaconda3\\envs\\segmentation\\lib\\site-packages\\keras\\src\\engine\\training.py\", line 1338, in train_function  *\n",
      "        return step_function(self, iterator)\n",
      "    File \"E:\\anaconda3\\envs\\segmentation\\lib\\site-packages\\keras\\src\\engine\\training.py\", line 1322, in step_function  **\n",
      "        outputs = model.distribute_strategy.run(run_step, args=(data,))\n",
      "    File \"E:\\anaconda3\\envs\\segmentation\\lib\\site-packages\\keras\\src\\engine\\training.py\", line 1303, in run_step  **\n",
      "        outputs = model.train_step(data)\n",
      "    File \"E:\\anaconda3\\envs\\segmentation\\lib\\site-packages\\keras\\src\\engine\\training.py\", line 1080, in train_step\n",
      "        y_pred = self(x, training=True)\n",
      "    File \"E:\\anaconda3\\envs\\segmentation\\lib\\site-packages\\keras\\src\\utils\\traceback_utils.py\", line 70, in error_handler\n",
      "        raise e.with_traceback(filtered_tb) from None\n",
      "    File \"E:\\anaconda3\\envs\\segmentation\\lib\\site-packages\\keras\\src\\engine\\input_spec.py\", line 298, in assert_input_compatibility\n",
      "        raise ValueError(\n",
      "\n",
      "    ValueError: Input 0 of layer \"sequential_6\" is incompatible with the layer: expected shape=(None, 10), found shape=(None, 5)\n",
      "\n",
      "\n",
      "--------------------------------------------------------------------------------\n",
      "1 fits failed with the following error:\n",
      "Traceback (most recent call last):\n",
      "  File \"E:\\anaconda3\\envs\\segmentation\\lib\\site-packages\\sklearn\\model_selection\\_validation.py\", line 729, in _fit_and_score\n",
      "    estimator.fit(X_train, y_train, **fit_params)\n",
      "  File \"E:\\anaconda3\\envs\\segmentation\\lib\\site-packages\\sklearn\\base.py\", line 1152, in wrapper\n",
      "    return fit_method(estimator, *args, **kwargs)\n",
      "  File \"E:\\anaconda3\\envs\\segmentation\\lib\\site-packages\\sklearn\\pipeline.py\", line 427, in fit\n",
      "    self._final_estimator.fit(Xt, y, **fit_params_last_step)\n",
      "  File \"C:\\Users\\marcb\\AppData\\Local\\Temp\\ipykernel_24688\\3521222499.py\", line 27, in fit\n",
      "  File \"E:\\anaconda3\\envs\\segmentation\\lib\\site-packages\\keras\\src\\utils\\traceback_utils.py\", line 70, in error_handler\n",
      "    raise e.with_traceback(filtered_tb) from None\n",
      "  File \"C:\\Users\\marcb\\AppData\\Local\\Temp\\__autograph_generated_file2t1qo1jp.py\", line 15, in tf__train_function\n",
      "    retval_ = ag__.converted_call(ag__.ld(step_function), (ag__.ld(self), ag__.ld(iterator)), None, fscope)\n",
      "ValueError: in user code:\n",
      "\n",
      "    File \"E:\\anaconda3\\envs\\segmentation\\lib\\site-packages\\keras\\src\\engine\\training.py\", line 1338, in train_function  *\n",
      "        return step_function(self, iterator)\n",
      "    File \"E:\\anaconda3\\envs\\segmentation\\lib\\site-packages\\keras\\src\\engine\\training.py\", line 1322, in step_function  **\n",
      "        outputs = model.distribute_strategy.run(run_step, args=(data,))\n",
      "    File \"E:\\anaconda3\\envs\\segmentation\\lib\\site-packages\\keras\\src\\engine\\training.py\", line 1303, in run_step  **\n",
      "        outputs = model.train_step(data)\n",
      "    File \"E:\\anaconda3\\envs\\segmentation\\lib\\site-packages\\keras\\src\\engine\\training.py\", line 1080, in train_step\n",
      "        y_pred = self(x, training=True)\n",
      "    File \"E:\\anaconda3\\envs\\segmentation\\lib\\site-packages\\keras\\src\\utils\\traceback_utils.py\", line 70, in error_handler\n",
      "        raise e.with_traceback(filtered_tb) from None\n",
      "    File \"E:\\anaconda3\\envs\\segmentation\\lib\\site-packages\\keras\\src\\engine\\input_spec.py\", line 298, in assert_input_compatibility\n",
      "        raise ValueError(\n",
      "\n",
      "    ValueError: Input 0 of layer \"sequential_7\" is incompatible with the layer: expected shape=(None, 10), found shape=(None, 15)\n",
      "\n",
      "\n",
      "--------------------------------------------------------------------------------\n",
      "1 fits failed with the following error:\n",
      "Traceback (most recent call last):\n",
      "  File \"E:\\anaconda3\\envs\\segmentation\\lib\\site-packages\\sklearn\\model_selection\\_validation.py\", line 729, in _fit_and_score\n",
      "    estimator.fit(X_train, y_train, **fit_params)\n",
      "  File \"E:\\anaconda3\\envs\\segmentation\\lib\\site-packages\\sklearn\\base.py\", line 1152, in wrapper\n",
      "    return fit_method(estimator, *args, **kwargs)\n",
      "  File \"E:\\anaconda3\\envs\\segmentation\\lib\\site-packages\\sklearn\\pipeline.py\", line 427, in fit\n",
      "    self._final_estimator.fit(Xt, y, **fit_params_last_step)\n",
      "  File \"C:\\Users\\marcb\\AppData\\Local\\Temp\\ipykernel_24688\\3521222499.py\", line 27, in fit\n",
      "  File \"E:\\anaconda3\\envs\\segmentation\\lib\\site-packages\\keras\\src\\utils\\traceback_utils.py\", line 70, in error_handler\n",
      "    raise e.with_traceback(filtered_tb) from None\n",
      "  File \"C:\\Users\\marcb\\AppData\\Local\\Temp\\__autograph_generated_fileglr5i53b.py\", line 15, in tf__train_function\n",
      "    retval_ = ag__.converted_call(ag__.ld(step_function), (ag__.ld(self), ag__.ld(iterator)), None, fscope)\n",
      "ValueError: in user code:\n",
      "\n",
      "    File \"E:\\anaconda3\\envs\\segmentation\\lib\\site-packages\\keras\\src\\engine\\training.py\", line 1338, in train_function  *\n",
      "        return step_function(self, iterator)\n",
      "    File \"E:\\anaconda3\\envs\\segmentation\\lib\\site-packages\\keras\\src\\engine\\training.py\", line 1322, in step_function  **\n",
      "        outputs = model.distribute_strategy.run(run_step, args=(data,))\n",
      "    File \"E:\\anaconda3\\envs\\segmentation\\lib\\site-packages\\keras\\src\\engine\\training.py\", line 1303, in run_step  **\n",
      "        outputs = model.train_step(data)\n",
      "    File \"E:\\anaconda3\\envs\\segmentation\\lib\\site-packages\\keras\\src\\engine\\training.py\", line 1080, in train_step\n",
      "        y_pred = self(x, training=True)\n",
      "    File \"E:\\anaconda3\\envs\\segmentation\\lib\\site-packages\\keras\\src\\utils\\traceback_utils.py\", line 70, in error_handler\n",
      "        raise e.with_traceback(filtered_tb) from None\n",
      "    File \"E:\\anaconda3\\envs\\segmentation\\lib\\site-packages\\keras\\src\\engine\\input_spec.py\", line 298, in assert_input_compatibility\n",
      "        raise ValueError(\n",
      "\n",
      "    ValueError: Input 0 of layer \"sequential_7\" is incompatible with the layer: expected shape=(None, 10), found shape=(None, 15)\n",
      "\n",
      "\n",
      "--------------------------------------------------------------------------------\n",
      "1 fits failed with the following error:\n",
      "Traceback (most recent call last):\n",
      "  File \"E:\\anaconda3\\envs\\segmentation\\lib\\site-packages\\sklearn\\model_selection\\_validation.py\", line 729, in _fit_and_score\n",
      "    estimator.fit(X_train, y_train, **fit_params)\n",
      "  File \"E:\\anaconda3\\envs\\segmentation\\lib\\site-packages\\sklearn\\base.py\", line 1152, in wrapper\n",
      "    return fit_method(estimator, *args, **kwargs)\n",
      "  File \"E:\\anaconda3\\envs\\segmentation\\lib\\site-packages\\sklearn\\pipeline.py\", line 427, in fit\n",
      "    self._final_estimator.fit(Xt, y, **fit_params_last_step)\n",
      "  File \"C:\\Users\\marcb\\AppData\\Local\\Temp\\ipykernel_24688\\3521222499.py\", line 27, in fit\n",
      "  File \"E:\\anaconda3\\envs\\segmentation\\lib\\site-packages\\keras\\src\\utils\\traceback_utils.py\", line 70, in error_handler\n",
      "    raise e.with_traceback(filtered_tb) from None\n",
      "  File \"C:\\Users\\marcb\\AppData\\Local\\Temp\\__autograph_generated_file3at0n400.py\", line 15, in tf__train_function\n",
      "    retval_ = ag__.converted_call(ag__.ld(step_function), (ag__.ld(self), ag__.ld(iterator)), None, fscope)\n",
      "ValueError: in user code:\n",
      "\n",
      "    File \"E:\\anaconda3\\envs\\segmentation\\lib\\site-packages\\keras\\src\\engine\\training.py\", line 1338, in train_function  *\n",
      "        return step_function(self, iterator)\n",
      "    File \"E:\\anaconda3\\envs\\segmentation\\lib\\site-packages\\keras\\src\\engine\\training.py\", line 1322, in step_function  **\n",
      "        outputs = model.distribute_strategy.run(run_step, args=(data,))\n",
      "    File \"E:\\anaconda3\\envs\\segmentation\\lib\\site-packages\\keras\\src\\engine\\training.py\", line 1303, in run_step  **\n",
      "        outputs = model.train_step(data)\n",
      "    File \"E:\\anaconda3\\envs\\segmentation\\lib\\site-packages\\keras\\src\\engine\\training.py\", line 1080, in train_step\n",
      "        y_pred = self(x, training=True)\n",
      "    File \"E:\\anaconda3\\envs\\segmentation\\lib\\site-packages\\keras\\src\\utils\\traceback_utils.py\", line 70, in error_handler\n",
      "        raise e.with_traceback(filtered_tb) from None\n",
      "    File \"E:\\anaconda3\\envs\\segmentation\\lib\\site-packages\\keras\\src\\engine\\input_spec.py\", line 298, in assert_input_compatibility\n",
      "        raise ValueError(\n",
      "\n",
      "    ValueError: Input 0 of layer \"sequential_6\" is incompatible with the layer: expected shape=(None, 10), found shape=(None, 15)\n",
      "\n",
      "\n",
      "  warnings.warn(some_fits_failed_message, FitFailedWarning)\n",
      "E:\\anaconda3\\envs\\segmentation\\lib\\site-packages\\sklearn\\model_selection\\_search.py:979: UserWarning: One or more of the test scores are non-finite: [       nan 0.63632329        nan        nan 0.6143471         nan\n",
      "        nan 0.65187389        nan        nan 0.62533744        nan]\n",
      "  warnings.warn(\n"
     ]
    },
    {
     "name": "stdout",
     "output_type": "stream",
     "text": [
      "Best parameters for NeuralNetwork: {'classifier__batch_size': 32, 'classifier__epochs': 20, 'reduce_dim__n_components': 10}\n",
      "\n",
      "Evaluating best LogisticRegression model...\n",
      "Accuracy for LogisticRegression: 0.6600331674958541\n",
      "Classification Report for LogisticRegression:\n",
      "              precision    recall  f1-score   support\n",
      "\n",
      "           0       0.63      0.49      0.55       514\n",
      "           1       0.67      0.79      0.73       692\n",
      "\n",
      "    accuracy                           0.66      1206\n",
      "   macro avg       0.65      0.64      0.64      1206\n",
      "weighted avg       0.66      0.66      0.65      1206\n",
      "\n",
      "\n",
      "Evaluating best RandomForest model...\n",
      "Accuracy for RandomForest: 0.6625207296849088\n",
      "Classification Report for RandomForest:\n",
      "              precision    recall  f1-score   support\n",
      "\n",
      "           0       0.65      0.46      0.54       514\n",
      "           1       0.67      0.81      0.73       692\n",
      "\n",
      "    accuracy                           0.66      1206\n",
      "   macro avg       0.66      0.64      0.64      1206\n",
      "weighted avg       0.66      0.66      0.65      1206\n",
      "\n",
      "\n",
      "Evaluating best XGBoost model...\n",
      "Accuracy for XGBoost: 0.6567164179104478\n",
      "Classification Report for XGBoost:\n",
      "              precision    recall  f1-score   support\n",
      "\n",
      "           0       0.64      0.45      0.53       514\n",
      "           1       0.67      0.81      0.73       692\n",
      "\n",
      "    accuracy                           0.66      1206\n",
      "   macro avg       0.65      0.63      0.63      1206\n",
      "weighted avg       0.65      0.66      0.64      1206\n",
      "\n",
      "\n",
      "Evaluating best NeuralNetwork model...\n",
      "38/38 [==============================] - 0s 760us/step\n",
      "Accuracy for NeuralNetwork: 0.642620232172471\n",
      "Classification Report for NeuralNetwork:\n",
      "              precision    recall  f1-score   support\n",
      "\n",
      "           0       0.58      0.57      0.57       514\n",
      "           1       0.68      0.70      0.69       692\n",
      "\n",
      "    accuracy                           0.64      1206\n",
      "   macro avg       0.63      0.63      0.63      1206\n",
      "weighted avg       0.64      0.64      0.64      1206\n",
      "\n",
      "\n",
      "Top 3 models based on accuracy: ['RandomForest', 'LogisticRegression', 'XGBoost', 'NeuralNetwork']\n",
      "\n",
      "Prediction using RandomForest: 0\n",
      "\n",
      "Prediction using LogisticRegression: 1\n",
      "\n",
      "Prediction using XGBoost: 1\n",
      "1/1 [==============================] - 0s 18ms/step\n",
      "\n",
      "Prediction using NeuralNetwork: [1]\n"
     ]
    }
   ],
   "source": [
    "import pandas as pd\n",
    "import numpy as np\n",
    "from sklearn.model_selection import train_test_split, GridSearchCV\n",
    "from sklearn.preprocessing import LabelEncoder, StandardScaler\n",
    "from sklearn.linear_model import LogisticRegression\n",
    "from sklearn.ensemble import RandomForestClassifier\n",
    "from xgboost import XGBClassifier\n",
    "from sklearn.metrics import accuracy_score, classification_report\n",
    "from tensorflow.keras.models import Sequential\n",
    "from tensorflow.keras.layers import Dense\n",
    "from sklearn.base import BaseEstimator, ClassifierMixin\n",
    "from sklearn.decomposition import PCA\n",
    "from sklearn.feature_selection import SelectKBest, f_classif\n",
    "from sklearn.pipeline import Pipeline\n",
    "\n",
    "# Custom KerasClassifier for deep learning\n",
    "class KerasClassifier(BaseEstimator, ClassifierMixin):\n",
    "    def __init__(self, build_fn=None, epochs=1, batch_size=32, verbose=1):\n",
    "        self.build_fn = build_fn\n",
    "        self.epochs = epochs\n",
    "        self.batch_size = batch_size\n",
    "        self.verbose = verbose\n",
    "        self.model_ = None\n",
    "\n",
    "    def fit(self, X, y):\n",
    "        self.model_ = self.build_fn()\n",
    "        self.model_.fit(X, y, epochs=self.epochs, batch_size=self.batch_size, verbose=self.verbose)\n",
    "        return self\n",
    "\n",
    "    def predict(self, X):\n",
    "        y_pred = self.model_.predict(X)\n",
    "        return (y_pred > 0.5).astype(int)\n",
    "\n",
    "    def score(self, X, y):\n",
    "        _, accuracy = self.model_.evaluate(X, y, verbose=0)\n",
    "        return accuracy\n",
    "\n",
    "# Step 1: Load the dataset\n",
    "df = pd.read_csv(\"ufc-master.csv\")  # Replace with correct path to your CSV file\n",
    "\n",
    "# Step 2: Handle missing values\n",
    "numeric_columns = df.select_dtypes(include=[np.number]).columns\n",
    "df[numeric_columns] = df[numeric_columns].fillna(df[numeric_columns].mean())\n",
    "categorical_columns = df.select_dtypes(include=['object']).columns\n",
    "df[categorical_columns] = df[categorical_columns].fillna('Unknown')\n",
    "\n",
    "# Step 3: Remove fighter names (since names do not contribute)\n",
    "df = df.drop(columns=['RedFighter', 'BlueFighter'])\n",
    "\n",
    "# Step 4: Encode categorical variables using LabelEncoder\n",
    "label_enc = LabelEncoder()\n",
    "for col in categorical_columns:\n",
    "    if col in df.columns:  # Apply only if the column exists\n",
    "        df[col] = label_enc.fit_transform(df[col])\n",
    "\n",
    "# Step 5: Feature Scaling using StandardScaler\n",
    "scaler = StandardScaler()\n",
    "X = df.drop('Winner', axis=1)  # Features, excluding the target column 'Winner'\n",
    "y = df['Winner']  # Target variable\n",
    "X_scaled = scaler.fit_transform(X)\n",
    "\n",
    "# Step 6: Split the data into training and testing sets\n",
    "X_train, X_test, y_train, y_test = train_test_split(X_scaled, y, test_size=0.2, random_state=42)\n",
    "\n",
    "# Step 7: Define Machine Learning Models to compare in GridSearch\n",
    "def create_neural_network_model(input_dim):\n",
    "    model = Sequential()\n",
    "    model.add(Dense(64, input_dim=input_dim, activation='relu'))\n",
    "    model.add(Dense(32, activation='relu'))\n",
    "    model.add(Dense(1, activation='sigmoid'))  # Binary classification\n",
    "    model.compile(optimizer='adam', loss='binary_crossentropy', metrics=['accuracy'])\n",
    "    return model\n",
    "\n",
    "models = {\n",
    "    'LogisticRegression': LogisticRegression(),\n",
    "    'RandomForest': RandomForestClassifier(),\n",
    "    'XGBoost': XGBClassifier(),\n",
    "    'NeuralNetwork': KerasClassifier(build_fn=create_neural_network_model, epochs=50, batch_size=32, verbose=0)\n",
    "}\n",
    "\n",
    "# Step 8: Define parameter grids for models and feature reduction techniques (PCA/SelectKBest)\n",
    "param_grids = {\n",
    "    'LogisticRegression': {\n",
    "        'reduce_dim__n_components': [5, 10, 15],  # PCA components\n",
    "        'classifier__C': [0.1, 1.0, 10.0],\n",
    "        'classifier__solver': ['liblinear', 'lbfgs']\n",
    "    },\n",
    "    'RandomForest': {\n",
    "        'reduce_dim__k': [10, 20, 30],  # SelectKBest features\n",
    "        'classifier__n_estimators': [100, 200],\n",
    "        'classifier__max_depth': [None, 10, 20],\n",
    "        'classifier__min_samples_split': [2, 5]\n",
    "    },\n",
    "    'XGBoost': {\n",
    "        'reduce_dim__k': [10, 20, 30],  # SelectKBest features\n",
    "        'classifier__n_estimators': [50, 100],\n",
    "        'classifier__learning_rate': [0.01, 0.1, 0.2],\n",
    "        'classifier__max_depth': [3, 6, 10]\n",
    "    },\n",
    "    'NeuralNetwork': {\n",
    "        'reduce_dim__n_components': [5, 10, 15],  # PCA components\n",
    "        'classifier__epochs': [20, 50],\n",
    "        'classifier__batch_size': [16, 32]\n",
    "    }\n",
    "}\n",
    "\n",
    "# Step 9: Create pipelines combining feature reduction and classification\n",
    "pipelines = {\n",
    "    'LogisticRegression': Pipeline([('reduce_dim', PCA()), ('classifier', models['LogisticRegression'])]),\n",
    "    'RandomForest': Pipeline([('reduce_dim', SelectKBest(score_func=f_classif)), ('classifier', models['RandomForest'])]),\n",
    "    'XGBoost': Pipeline([('reduce_dim', SelectKBest(score_func=f_classif)), ('classifier', models['XGBoost'])]),\n",
    "    'NeuralNetwork': Pipeline([('reduce_dim', PCA()), ('classifier', KerasClassifier(build_fn=lambda: create_neural_network_model(10), epochs=50, batch_size=32, verbose=0))])\n",
    "}\n",
    "\n",
    "# Step 10: Perform GridSearch for each model and feature reduction technique\n",
    "best_models = {}\n",
    "for model_name in pipelines:\n",
    "    print(f\"\\nRunning GridSearch for {model_name}...\")\n",
    "    grid = GridSearchCV(estimator=pipelines[model_name], param_grid=param_grids[model_name], cv=3, n_jobs=-1, verbose=1)\n",
    "    grid.fit(X_train, y_train)\n",
    "    best_models[model_name] = grid.best_estimator_\n",
    "    print(f\"Best parameters for {model_name}: {grid.best_params_}\")\n",
    "\n",
    "# Step 11: Evaluate the best models and select the top 3 based on accuracy\n",
    "model_performance = {}\n",
    "for model_name, model in best_models.items():\n",
    "    print(f\"\\nEvaluating best {model_name} model...\")\n",
    "    y_pred = model.predict(X_test)\n",
    "    if model_name == 'NeuralNetwork':\n",
    "        y_pred = (y_pred > 0.5).astype(int)  # Convert probabilities to binary predictions for neural network\n",
    "    accuracy = accuracy_score(y_test, y_pred)\n",
    "    print(f\"Accuracy for {model_name}: {accuracy}\")\n",
    "    print(f\"Classification Report for {model_name}:\\n{classification_report(y_test, y_pred)}\")\n",
    "    model_performance[model_name] = accuracy\n",
    "\n",
    "\n",
    "# Sort models by accuracy and pick the top 3\n",
    "top_3_models = sorted(model_performance, key=model_performance.get, reverse=True)[:4]\n",
    "print(f\"\\nTop 3 models based on accuracy: {top_3_models}\")\n",
    "\n",
    "\n",
    "# Step 12: Fighter data for prediction\n",
    "fighter_1 = {\n",
    "    'RedOdds': -150,\n",
    "    'BlueOdds': 120,\n",
    "    'RedExpectedValue': 0.6,\n",
    "    'BlueExpectedValue': 0.4,\n",
    "    'Date': '2024-10-26',\n",
    "    'Location': 'Abu Dhabi',\n",
    "    'Country': 'Spain',\n",
    "    'TitleBout': True,\n",
    "    'WeightClass': 'Featherweight',\n",
    "    'Gender': 'MALE',\n",
    "    'NumberOfRounds': 5,\n",
    "    'BlueCurrentLoseStreak': 0,\n",
    "    'BlueCurrentWinStreak': 1,\n",
    "    'BlueDraws': 0,\n",
    "    'BlueAvgSigStrLanded': 7.16,\n",
    "    'BlueAvgSigStrPct': 49.0,\n",
    "    'BlueAvgSubAtt': 0.4,\n",
    "    'BlueAvgTDLanded': 0.5,\n",
    "    'BlueAvgTDPct': 83.0,\n",
    "    'BlueLongestWinStreak': 14,\n",
    "    'BlueLosses': 7,\n",
    "    'BlueTotalRoundsFought': 113,\n",
    "    'BlueTotalTitleBouts': 11,\n",
    "    'BlueWinsByDecisionMajority': 0,\n",
    "    'BlueWinsByDecisionSplit': 0,\n",
    "    'BlueWinsByDecisionUnanimous': 10,\n",
    "    'BlueWinsByKO': 11,\n",
    "    'BlueWinsBySubmission': 2,\n",
    "    'BlueWinsByTKODoctorStoppage': 1,\n",
    "    'BlueWins': 24,\n",
    "    'BlueStance': 'Orthodox',\n",
    "    'BlueHeightCms': 180,\n",
    "    'BlueReachCms': 175,\n",
    "    'BlueWeightLbs': 145,\n",
    "    'RedCurrentLoseStreak': 0,\n",
    "    'RedCurrentWinStreak': 5,\n",
    "    'RedDraws': 0,\n",
    "    'RedAvgSigStrLanded': 4.40,\n",
    "    'RedAvgSigStrPct': 46.0,\n",
    "    'RedAvgSubAtt': 1.28,\n",
    "    'RedAvgTDLanded': 1.92,\n",
    "    'RedAvgTDPct': 56.0,\n",
    "    'RedLongestWinStreak': 5,\n",
    "    'RedLosses': 0,\n",
    "    'RedTotalRoundsFought': 25,\n",
    "    'RedTotalTitleBouts': 1,\n",
    "    'RedWinsByDecisionMajority': 2,\n",
    "    'RedWinsByDecisionSplit': 1,\n",
    "    'RedWinsByDecisionUnanimous': 2,\n",
    "    'RedWinsByKO': 5,\n",
    "    'RedWinsBySubmission': 8,\n",
    "    'RedWinsByTKODoctorStoppage': 0,\n",
    "    'RedWins': 15,\n",
    "    'RedStance': 'Orthodox',\n",
    "    'RedHeightCms': 170,\n",
    "    'RedReachCms': 175,\n",
    "    'RedWeightLbs': 145,\n",
    "    'RedAge': 27,\n",
    "    'BlueAge': 32,\n",
    "    'LoseStreakDif': 0,\n",
    "    'WinStreakDif': 4,\n",
    "    'LongestWinStreakDif': -9,\n",
    "    'WinDif': -9,\n",
    "    'LossDif': 7,\n",
    "    'TotalRoundDif': -88,\n",
    "    'TotalTitleBoutDif': -10,\n",
    "    'KODif': 6,\n",
    "    'SubDif': 6,\n",
    "    'HeightDif': -5,\n",
    "    'ReachDif': 0,\n",
    "    'AgeDif': -5,\n",
    "    'SigStrDif': -2.76,\n",
    "    'AvgSubAttDif': 0.88,\n",
    "    'AvgTDDif': 1.42,\n",
    "    'EmptyArena': False,\n",
    "    'BMatchWCRank': 1,\n",
    "    'RMatchWCRank': 1,\n",
    "    'RWFlyweightRank': 0,\n",
    "    'RWFeatherweightRank': 1,\n",
    "    'RWStrawweightRank': 0,\n",
    "    'RWBantamweightRank': 0,\n",
    "    'RHeavyweightRank': 0,\n",
    "    'RLightHeavyweightRank': 0,\n",
    "    'RMiddleweightRank': 3,\n",
    "    'RWelterweightRank': 0,\n",
    "    'RLightweightRank': 0,\n",
    "    'RFeatherweightRank': 1,\n",
    "    'RBantamweightRank': 0,\n",
    "    'RFlyweightRank': 0,\n",
    "    'RPFPRank': 1,\n",
    "    'BWFlyweightRank': 0,\n",
    "    'BWFeatherweightRank': 0,\n",
    "    'BWStrawweightRank': 0,\n",
    "    'BWBantamweightRank': 0,\n",
    "    'BHeavyweightRank': 0,\n",
    "    'BLightHeavyweightRank': 0,\n",
    "    'BMiddleweightRank': 0,\n",
    "    'BWelterweightRank': 0,\n",
    "    'BLightweightRank': 0,\n",
    "    'BFeatherweightRank': 0,\n",
    "    'BBantamweightRank': 0,\n",
    "    'BFlyweightRank': 0,\n",
    "    'BPFPRank': 2,\n",
    "    'BetterRank': 0,\n",
    "    'Finish': 'KO',\n",
    "    'FinishDetails': 'Punches',\n",
    "    'FinishRound': 2,\n",
    "    'FinishRoundTime': '3:32',\n",
    "    'TotalFightTimeSecs': 600,\n",
    "    'RedDecOdds': 150,\n",
    "    'BlueDecOdds': -150,\n",
    "    'RSubOdds': 300,\n",
    "    'BSubOdds': -100,\n",
    "    'RKOOdds': 120,\n",
    "    'BKOOdds': -150\n",
    "}\n",
    "\n",
    "# Convert fighter_1 data to DataFrame\n",
    "fighter_comparison_df = pd.DataFrame([fighter_1])\n",
    "\n",
    "# Step 2: Preprocess and scale the features\n",
    "# Ensure that all categorical columns are processed correctly (handle missing categories if necessary)\n",
    "for col in categorical_columns:\n",
    "    if col in fighter_comparison_df.columns:\n",
    "        unseen_categories = [item for item in fighter_comparison_df[col].unique() if item not in label_enc.classes_]\n",
    "        if unseen_categories:\n",
    "            label_enc.classes_ = np.append(label_enc.classes_, unseen_categories)\n",
    "        fighter_comparison_df[col] = label_enc.transform(fighter_comparison_df[col])\n",
    "\n",
    "# Scale the numerical columns\n",
    "fighter_comparison_scaled = scaler.transform(fighter_comparison_df)\n",
    "\n",
    "# Step 3: Use the top 3 models to predict the outcome\n",
    "for model_name in top_3_models:\n",
    "    model = best_models[model_name]\n",
    "    prediction = model.predict(fighter_comparison_scaled)\n",
    "    print(f\"\\nPrediction using {model_name}: {prediction[0]}\")"
   ]
  },
  {
   "cell_type": "code",
   "execution_count": null,
   "id": "049a62d8-1e51-4d19-a06c-c005372ecab4",
   "metadata": {},
   "outputs": [],
   "source": []
  },
  {
   "cell_type": "code",
   "execution_count": null,
   "id": "fb3fe80c-b992-4e8d-8bb6-0d1bd213b705",
   "metadata": {},
   "outputs": [],
   "source": []
  },
  {
   "cell_type": "code",
   "execution_count": null,
   "id": "4679417d-67db-49e2-81f9-b4c27253bb32",
   "metadata": {},
   "outputs": [],
   "source": []
  }
 ],
 "metadata": {
  "kernelspec": {
   "display_name": "Python 3 (ipykernel)",
   "language": "python",
   "name": "python3"
  },
  "language_info": {
   "codemirror_mode": {
    "name": "ipython",
    "version": 3
   },
   "file_extension": ".py",
   "mimetype": "text/x-python",
   "name": "python",
   "nbconvert_exporter": "python",
   "pygments_lexer": "ipython3",
   "version": "3.8.19"
  }
 },
 "nbformat": 4,
 "nbformat_minor": 5
}
